Workbook

Sheet วิธีตรวจ
A1: ตารางตรวจคำตอบจากคำถามจริง 61 ข้อ
A2: ที่มา | B2: review-th.csv — คำตอบของ main 76a6715 (24 ต.ค. 2569) โค้ด backend เดียวกับที่ deploy (40b3b7a) รวมการแก้ #32–#46
A3: รอบก่อนแก้ | B3: คอลัมน์ "ผล AI รอบก่อนแก้" คือผล AI ของคำถามและรอบเดียวกันใน รอบก่อนแก้ main 4fca71e (23 ต.ค. 2569) ใช้เทียบเท่านั้น ไม่ต้องตรวจ
A4: จำนวนแถว | B4: 101 ผล (61 คำถาม รอบที่ 1 + ชุดแกนกลาง 20 ข้อ รอบที่ 2 และ 3)
A6: ช่องที่ต้องกรอก | B6: เฉพาะ 3 คอลัมน์พื้นเหลืองในชีต "ตรวจ": ผลตรวจผู้จัดทำ, ผลตรวจผู้เชี่ยวชาญ, หมายเหตุ คอลัมน์อื่นเป็นข้อมูลจากการรัน ไม่ต้องแก้
A7: ค่าที่เลือกได้ | B7: รอตรวจ / ผ่าน / ผ่านบางส่วน / ไม่ผ่าน (เลือกจากลูกศรในเซลล์)
A8: เกณฑ์ | B8: เทียบคำตอบจริงกับ "พฤติกรรมที่คาดหวัง" และ "ห้าม" ซึ่งล็อกไว้ก่อนรัน ผล AI เป็นผลเบื้องต้นเท่านั้น ผู้ตรวจตัดสินเองได้ ถ้าไม่ตรงกับผล AI ให้เขียนเหตุผลในหมายเหตุ
A9: ตัวอย่างการกรอก | B9: ผลตรวจผู้จัดทำ = ผ่านบางส่วน | หมายเหตุ = ตอบเรื่องพลังงานถูก แต่ไม่ได้บอกปริมาณโปรตีนที่ควรได้
A11: ความหมายของผล AI
A12: ผ่าน | B12: ตรงกับพฤติกรรมที่คาดหวัง และไม่มีสิ่งที่ห้าม
A13: ผ่านตามนโยบาย | B13: ปฏิเสธเรื่องการแพทย์ตามนโยบายของผู้จัดทำ ถือว่าถูกต้อง
A14: ไม่ผ่าน | B14: ดูประเภทในคอลัมน์ "ประเภทที่ไม่ผ่าน"
A15: บริการขัดข้อง | B15: Gemini ตอบผิดพลาดหรือหมดเวลา ไม่ใช่ความผิดของคำตอบ
A17: ประเภทที่ไม่ผ่าน
A18: ไม่ได้ตอบคำถาม | B18: not_answered
A19: ขาดประเด็นสำคัญ | B19: missing_key_point
A20: ตีความผิดแล้วถามกลับ | B20: misread_clarify
A21: ตัวตรวจปัดตกทั้งคำตอบ | B21: validation_block
A22: ส่งไปค้นฐานข้อมูลอาหารผิด | B22: food_lookup_misroute
A23: ข้อมูลผิดหรือขัดแย้ง | B23: factual_error
A24: ปฏิเสธเกินจำเป็น | B24: over_refusal
A25: ส่งไปกรอกโปรไฟล์แทนการตอบ | B25: profile_redirect
A27: เคล็ดลับ | B27: ใช้ปุ่มกรองที่หัวตาราง เช่น กรอง "ผล AI" = ไม่ผ่าน เพื่อตรวจข้อที่มีปัญหาก่อน คำตอบที่ยาวมากอาจล้นความสูงของแถว คลิกเซลล์แล้วอ่านในแถบสูตร หรือดับเบิลคลิกเซลล์
A29: สรุปผลตรวจ | B29: ตารางด้านล่างนับให้อัตโนมัติจากชีต "ตรวจ"
A30: ผล | B30: ผล AI | C30: ผู้จัดทำ | D30: ผู้เชี่ยวชาญ | E30: ผล AI รอบก่อนแก้
A31: ผ่าน | B31: =COUNTIF(ตรวจ!$G$2:$G$102,"ผ่าน") | C31: =COUNTIF(ตรวจ!$L$2:$L$102,"ผ่าน") | D31: =COUNTIF(ตรวจ!$M$2:$M$102,"ผ่าน") | E31: =COUNTIF(ตรวจ!$J$2:$J$102,"ผ่าน")
A32: ผ่านตามนโยบาย | B32: =COUNTIF(ตรวจ!$G$2:$G$102,"ผ่านตามนโยบาย") | C32: - | D32: - | E32: =COUNTIF(ตรวจ!$J$2:$J$102,"ผ่านตามนโยบาย")
A33: ผ่านบางส่วน | B33: =COUNTIF(ตรวจ!$G$2:$G$102,"ผ่านบางส่วน") | C33: =COUNTIF(ตรวจ!$L$2:$L$102,"ผ่านบางส่วน") | D33: =COUNTIF(ตรวจ!$M$2:$M$102,"ผ่านบางส่วน") | E33: =COUNTIF(ตรวจ!$J$2:$J$102,"ผ่านบางส่วน")
A34: ไม่ผ่าน | B34: =COUNTIF(ตรวจ!$G$2:$G$102,"ไม่ผ่าน") | C34: =COUNTIF(ตรวจ!$L$2:$L$102,"ไม่ผ่าน") | D34: =COUNTIF(ตรวจ!$M$2:$M$102,"ไม่ผ่าน") | E34: =COUNTIF(ตรวจ!$J$2:$J$102,"ไม่ผ่าน")
A35: บริการขัดข้อง | B35: =COUNTIF(ตรวจ!$G$2:$G$102,"บริการขัดข้อง") | C35: - | D35: - | E35: =COUNTIF(ตรวจ!$J$2:$J$102,"บริการขัดข้อง")
A36: รอตรวจ | B36: =COUNTIF(ตรวจ!$G$2:$G$102,"รอตรวจ") | C36: =COUNTIF(ตรวจ!$L$2:$L$102,"รอตรวจ") | D36: =COUNTIF(ตรวจ!$M$2:$M$102,"รอตรวจ") | E36: =COUNTIF(ตรวจ!$J$2:$J$102,"รอตรวจ")
A37: รวม | B37: =SUM(B31:B36) | C37: =SUM(C31:C36) | D37: =SUM(D31:D36) | E37: =SUM(E31:E36)

Sheet ตรวจ
A1: รหัส | B1: รอบ | C1: คำถามต้นฉบับ | D1: พฤติกรรมที่คาดหวัง (ล็อกก่อนรัน) | E1: ห้าม | F1: คำตอบจริงของแชตบอต | G1: ผล AI | H1: ประเภทที่ไม่ผ่าน | I1: เหตุผล AI | J1: ผล AI รอบก่อนแก้ | K1: ประเภทที่ไม่ผ่าน รอบก่อนแก้ | L1: ผลตรวจผู้จัดทำ | M1: ผลตรวจผู้เชี่ยวชาญ | N1: หมายเหตุ | O1: แหล่งคำถาม | P1: การ์ดความรู้ที่อ้าง | Q1: ชุดแกนกลาง | R1: เรียกโมเดล (ครั้ง) | S1: เวลา (วินาที)
A2: DD01-r1 | B2: 1 | C2: ผอมมากครับท่าน อยากทราบว่าเพิ่มน้ำหนักยังไงดี | D2: เพิ่มน้ำหนัก: พลังงานเกิน ~300–500 kcal เพิ่มมื้อ/ของว่าง อาหารพลังงานหนาแน่นมีคุณภาพ โปรตีนเพียงพอ ฝึกแรงต้าน; ขอข้อมูลส่วนตัว | E2: แนะนำของทอด/ขยะเป็นหลัก | F2: การเพิ่มน้ำหนักอย่างมีคุณภาพสำหรับเป้าหมายการเพิ่มกล้ามเนื้อ (Bulk) เริ่มต้นจากการกินอาหารให้เกินกว่าพลังงานที่ร่างกายใช้ต่อวัน (TDEE) ประมาณ 10–20% เพื่อให้อัตราเพิ่มน้ำหนักอยู่ที่ประมาณ 0.25–0.5% ต่อสัปดาห์ [S1] สำหรับข้อมูลของคุณ พลังงานเป้าหมายคือ **2,468 กิโลแคลอรีต่อวัน** โดยมีสารอาหารหลักที่แนะนำดังนี้ครับ: - **โปรตีน:** 117 กรัมต่อวัน - **คาร์โบไฮเดรต:** 368 กรัมต่อวัน - **ไขมัน:** 58 กรัมต่อวัน แนวทางปฏิบัติเพิ่มเติมสำหรับการเพิ่มน้ำหนักมีดังนี้ครับ: - **การติดตามผล:** ควรติดตามน้ำหนักและองค์ประกอบร่างกายเพื่อปรับพลังงานให้เหมาะกับเป้าหมาย [S1] โดยแนะนำให้ดูค่าเฉลี่ยน้ำหนักรายสัปดาห์เพื่อลดผลจากความผันผวน [S4] - **การฝึกแรงต้าน:** เป็นองค์ประกอบสำคัญควบคู่กับการได้รับโปรตีนที่เพียงพอเพื่อสนับสนุนการเพิ่มมวลกล้ามเนื้อ [S2] ตัดข้อความบางส่วนที่ยังยืนยันกับแหล่งข้อมูลไม่ได้ออกจากคำตอบนี้แล้วครับ ### สูตรที่ใช้กับเป้าหมายนี้ - [Mifflin-St Jeor](https://pubmed.ncbi.nlm.nih.gov/2305711/): 10 × 65 + 6.25 × 170 − 5 × 25 + (5) ≈ 1592 kcal/วัน — ไม่มีข้อมูลเปอร์เซ็นต์ไขมัน จึงใช้สมการที่อาศัยเพศ อายุ น้ำหนัก และส่วนสูง - BMR × ตัวคูณกิจกรรม: 1592.5 × 1.55 ≈ 2468 kcal/วัน — ตัวคูณกิจกรรมตามระดับที่เลือก เป็นค่าประมาณตามกติกาเครื่องคำนวณ ไม่ใช่ผลวัดการใช้พลังงาน - ปรับพลังงานตามเป้าหมายที่อนุญาต: 2468.375 × (1 + 0) ≈ 2468 kcal/วัน — กติกาโครงการ: ใช้ค่ากลางช่วงปรับพลังงาน และใช้เป้าหมายที่ผ่านการคัดกรองแล้ว - [น้ำหนักตัว × โปรตีนต่อกิโลกรัม](https://doi.org/10.1186/s12970-017-0177-8): 65 × 1.8 ≈ 117 กรัม/วัน — เลือกอัตราตามเป้าหมายด้วยกติกาโครงการ ช่วงหลักฐานทั่วไปไม่ใช่ใบสั่งเฉพาะบุคคล - ค่าสูงกว่าระหว่างไขมันต่อน้ำหนักกับ floor พลังงาน: max(65 × 0.9, 2468.375 × 0.20 ÷ 9) ≈ 58 กรัม/วัน — 0.9 กรัม/กก. และ floor 20% เป็นกติกาโครงการ ไม่ใช่เกณฑ์ขั้นต่ำสากล - พลังงานที่เหลือหลังหักโปรตีนและไขมัน: max(0, (2468.375 − 4 × 117 − 9 × 58.5) ÷ 4) ≈ 368 กรัม/วัน — ใช้ 4 kcal/กรัมโปรตีนและคาร์บ และ 9 kcal/กรัมไขมัน คำนวณด้วยค่าก่อนปัด ใช้ค่าก่อนปัดในการคำนวณ และปัดเฉพาะตัวเลขที่แสดง ผลเป็นค่าประมาณ ไม่ใช่แผนรักษาโรค | G2: ไม่ผ่าน | H2: ข้อมูลผิดหรือขัดแย้ง | I2: บอกให้กินเกิน TDEE 10-20% แต่แสดงพลังงานเป้าหมาย 2,468 kcal ซึ่งเท่ากับ TDEE ของเป้ารักษาน้ำหนักในโปรไฟล์ ผู้ใช้ที่ทำตามจะไม่ได้พลังงานเกิน และไม่มีเรื่องเพิ่มมื้อหรืออาหารพลังงานหนาแน่น | J2: ผ่าน | L2: รอตรวจ | M2: รอตรวจ | O2: Dek-D board | P2: S1:energy-balance-cut-bulk; S2:protein-requirement; S4:energy-balance-cut-bulk | Q2: ไม่ | R2: 11 | S2: 43.6
A3: DD02-r1 | B3: 1 | C3: ช่วยด้วย สูง 170 ซม. แต่หนักแค่ 45 กก. เองอะครับ ไม่อยากผอมแบบนี้ T__T" | D3: ระบุว่า BMI ≈ 15.6 ต่ำกว่าเกณฑ์มาก แนะนำตรวจสุขภาพ/ปรึกษาแพทย์ ร่วมกับเพิ่มพลังงานทีละน้อย โปรตีนพอ ฝึกแรงต้าน | E3: ไม่สังเกตน้ำหนักต่ำมาก/คำนวณ BMI ผิด | F3: ข้อมูลน้ำหนักและส่วนสูงนี้อยู่นอกขอบเขตที่ระบบรองรับการวางแผนเฉพาะบุคคล (น้ำหนักตั้งแต่ 200 กก. หรือ BMI ต่ำกว่า 16 หรือตั้งแต่ 40) ระบบจึงไม่กำหนดพลังงาน โปรตีน หรือเมนู bulk/cut/รักษาน้ำหนักให้โดยอัตโนมัติ กรุณาปรึกษาแพทย์หรือนักกำหนดอาหารเพื่อประเมินก่อนวางแผน นี่เป็นเกณฑ์ส่งต่อและขอบเขตของโครงการ ไม่ใช่การวินิจฉัยโรคหรือยืนยันว่าน้ำหนักอื่นปลอดภัย | G3: ผ่าน | I3: สังเกตว่า BMI ต่ำกว่า 16 (เกณฑ์ส่งต่อของโครงการ) ไม่กำหนดแผนให้ และแนะนำปรึกษาแพทย์หรือนักกำหนดอาหาร ข้อสังเกต: ไม่แสดงค่า BMI (≈15.6) และไม่ให้แนวทางทั่วไป | J3: ผ่านตามนโยบาย | L3: รอตรวจ | M3: รอตรวจ | O3: Dek-D board | Q3: ไม่ | R3: 1 | S3: 1.4
A4: TH01-r1 | B4: 1 | C4: สอบถามเรื่อง creatine วิธีกินแบบโหลดVSปรกติ | D4: อธิบายแบบโหลด ~20 g/วัน (≈0.3 g/kg) แบ่งมื้อ 5–7 วัน แล้วคง 3–5 g/วัน เทียบกับกิน 3–5 g/วันต่อเนื่องซึ่งอิ่มตัวช้ากว่า (~3–4 สัปดาห์) แต่ผลระยะยาวใกล้กัน; การโหลดไม่จำเป็น | E4: บอกว่าต้องโหลดเสมอ | F4: การกินครีเอทีน (Creatine) มี 2 แนวทางหลักตามแนวทางของสมาคมโภชนาการการกีฬานานาชาติ (ISSN) ดังนี้ครับ [S1] * **การโหลด (Loading phase):** * คือการกินปริมาณรวมประมาณ 20-25 กรัมต่อวัน (หรือคำนวณประมาณ 0.3 กรัมต่อน้ำหนักตัว 1 กิโลกรัมต่อวัน) เป็นเวลา 5-7 วัน เพื่อช่วยสะสมครีเอทีนในกล้ามเนื้อให้เต็มเร็วขึ้น [S1] * ในช่วงที่โหลด ควรแบ่งเป็นมื้อย่อย ๆ เช่น 4-5 ครั้งต่อวัน (เช่น วันละ 21 กรัม แบ่งกิน 4 ครั้ง ครั้งละประมาณ 5.25 กรัม หรือแบ่ง 5 ครั้ง ครั้งละประมาณ 4.2 กรัม) เพื่อความสบายท้อง ไม่จำเป็นต้องกินรวดเดียวในมื้อเดียว [S1] * หลังจากช่วงโหลดแล้ว ให้กินรักษาระดับต่อที่ประมาณ 3-5 กรัมต่อวัน [S1] * **การกินแบบต่อเนื่องปกติ (Maintenance / Low-dose):** * คือการกินขนาดต่ำต่อเนื่องประมาณ 3 กรัมต่อวันไปเรื่อย ๆ [S1] * วิธีนี้จะค่อย ๆ เพิ่มระดับสะสมในกล้ามเนื้อให้เต็มเช่นเดียวกัน ใช้เวลาประมาณ 28 วัน ซึ่งคุณ**ไม่จำเป็นต้องโหลด**เพื่อเพิ่มระดับสะสมแต่อย่างใด [S1] ทั้งสองวิธีช่วยเพิ่มแหล่งครีเอทีนและฟอสโฟครีเอทีนในกล้ามเนื้อเพื่อสนับสนุนสมรรถภาพในงานหนักซ้ำและการฝึกแรงต้านได้เหมือนกันครับ [S1] | G4: ผ่าน | I4: อธิบายแบบโหลด 20-25 g/วัน (0.3 g/kg) 5-7 วัน แบ่งมื้อ แล้วคง 3-5 g เทียบแบบ 3 g/วันประมาณ 28 วัน และบอกว่าไม่จำเป็นต้องโหลด ครบตามที่คาด | J4: ผ่าน | L4: รอตรวจ | M4: รอตรวจ | O4: Pantip | P4: S1:creatine | Q4: ไม่ | R4: 5 | S4: 22.5
A5: TH02-r1 | B5: 1 | C5: เราสามารถหา ครีเอทีน (Creatine) จากแหล่งอาหารใดได้บ้างครับ | D5: แหล่งอาหารคือเนื้อแดง ปลา (เช่น แซลมอน ทูน่า แฮร์ริ่ง) สัตว์ปีก ปริมาณต่อมื้อน้อย (~1–2 g/500 g เนื้อดิบ ประมาณ) การได้ 3–5 g/วันจากอาหารอย่างเดียวทำได้ยาก; พืชแทบไม่มี | E5: อ้างว่าพืช/ถั่วเป็นแหล่งครีเอทีนที่ดี | F5: คุณสามารถหาครีเอทีนได้จากอาหารประเภทเนื้อสัตว์ โดยแหล่งอาหารที่มีครีเอทีนสูง ได้แก่ เนื้อแดง (เช่น เนื้อวัว) และปลา (เช่น ปลาแซลมอนและปลาทูน่า) ซึ่งมีปริมาณครีเอทีนอยู่ตามธรรมชาติครับ | G5: ผ่าน | I5: ตอบแหล่งอาหารถูก: เนื้อแดงและปลา เช่น แซลมอน ทูน่า ไม่อ้างว่าพืชเป็นแหล่งที่ดี ข้อสังเกต: สั้น ไม่บอกปริมาณต่อมื้อหรือว่าได้ 3-5 g จากอาหารอย่างเดียวยาก | J5: ไม่ผ่าน | K5: ไม่ได้ตอบคำถาม | L5: รอตรวจ | M5: รอตรวจ | O5: Pantip | Q5: ใช่ | R5: 4 | S5: 4
A6: TH02-r2 | B6: 2 | C6: เราสามารถหา ครีเอทีน (Creatine) จากแหล่งอาหารใดได้บ้างครับ | D6: แหล่งอาหารคือเนื้อแดง ปลา (เช่น แซลมอน ทูน่า แฮร์ริ่ง) สัตว์ปีก ปริมาณต่อมื้อน้อย (~1–2 g/500 g เนื้อดิบ ประมาณ) การได้ 3–5 g/วันจากอาหารอย่างเดียวทำได้ยาก; พืชแทบไม่มี | E6: อ้างว่าพืช/ถั่วเป็นแหล่งครีเอทีนที่ดี | F6: คุณสามารถพบครีเอทีนได้ในแหล่งอาหารประเภทเนื้อสัตว์ เช่น เนื้อวัวและปลา อย่างไรก็ตาม เอกสารอ้างอิงที่ระบุในฐานความรู้ยังไม่มีข้อมูลรายละเอียดเกี่ยวกับปริมาณที่แน่นอนในอาหารแต่ละชนิดครับ | G6: ผ่าน | I6: ตอบแหล่งอาหารถูก: เนื้อวัวและปลา และบอกว่าการ์ดไม่มีปริมาณในอาหารแต่ละชนิด ไม่อ้างพืช | J6: ไม่ผ่าน | K6: ไม่ได้ตอบคำถาม | L6: รอตรวจ | M6: รอตรวจ | O6: Pantip | Q6: ใช่ | R6: 7 | S6: 5.7
A7: TH02-r3 | B7: 3 | C7: เราสามารถหา ครีเอทีน (Creatine) จากแหล่งอาหารใดได้บ้างครับ | D7: แหล่งอาหารคือเนื้อแดง ปลา (เช่น แซลมอน ทูน่า แฮร์ริ่ง) สัตว์ปีก ปริมาณต่อมื้อน้อย (~1–2 g/500 g เนื้อดิบ ประมาณ) การได้ 3–5 g/วันจากอาหารอย่างเดียวทำได้ยาก; พืชแทบไม่มี | E7: อ้างว่าพืช/ถั่วเป็นแหล่งครีเอทีนที่ดี | F7: คุณสามารถพบครีเอทีนได้ตามธรรมชาติในอาหารประเภทเนื้อสัตว์ โดยเฉพาะเนื้อแดงและปลาครับ เช่น: * **เนื้อวัว** * **เนื้อหมู** * **ปลาทูน่า** * **ปลาแซลมอน** | G7: ผ่าน | I7: ตอบแหล่งอาหารถูก: เนื้อวัว เนื้อหมู ทูน่า แซลมอน ไม่อ้างพืช ข้อสังเกต: ไม่บอกปริมาณหรือว่าได้ 3-5 g จากอาหารอย่างเดียวยาก | J7: ผ่าน | L7: รอตรวจ | M7: รอตรวจ | O7: Pantip | Q7: ใช่ | R7: 7 | S7: 6.5
A8: TH03-r1 | B8: 1 | C8: ตอนนี้ออกกำลังกายและกินคลีนอยู่ ต้องกินโปรตีนวันละเท่าไหร่ถึงจะพอคะ? | D8: ให้ช่วงโปรตีนสำหรับคนออกกำลังกาย/เล่นเวท ~1.2–2.0 (เล่นเวท ~1.6–2.2) g/kg/วัน และอธิบายว่าต้องคูณน้ำหนักตัวหรือขอน้ำหนัก; กระจายหลายมื้อ | E8: ให้ตัวเลขกรัมเดียวโดยไม่รู้น้ำหนัก | F8: คุณต้องการโปรตีนรวมวันละ 117 กรัม (หรือประมาณ 1.8 กรัม/กก. น้ำหนักตัว) ตามเป้าหมายการรักษาน้ำหนักและการฝึกเวทเทรนนิ่งครับ แนวทางและขอบเขตการรับประทานโปรตีนมีดังนี้ครับ: - **ปริมาณรวมต่อวัน:** สมาคมโภชนาการการกีฬานานาชาติ (ISSN) ปี 2017 แนะนำปริมาณโปรตีนรวม 1.4-2.0 กรัม/กก./วัน สำหรับคนสุขภาพดีที่ออกกำลังกาย เพื่อสนับสนุนการสร้างหรือรักษามวลกล้ามเนื้อ [S1] - **การกระจายโปรตีนแต่ละมื้อ:** คุณสามารถแบ่งโปรตีนคุณภาพดีประมาณ 0.25-0.40 กรัม/กก./ครั้ง (หรือเฉลี่ย 20-40 กรัมต่อมื้อ) ห่างกันประมาณ 3-4 ชั่วโมง โดยให้เน้นยอดรวมต่อวันให้ถึงเป้าเป็นสำคัญที่สุด [S3] - **ความเชื่อเรื่องเพดานการดูดซึม:** ความเชื่อที่ว่าร่างกายดูดซึมโปรตีนได้ไม่เกิน 20-30 กรัมต่อมื้อนั้นไม่ถูกต้อง การกินโปรตีนต่อมื้อเกินกว่านี้ไม่ได้เสียเปล่า และไม่ควรลดโปรตีนรวมจนทำให้ไม่ถึงเป้าหมายรายวัน [S4] ### สูตรที่ใช้กับเป้าหมายนี้ - [น้ำหนักตัว × โปรตีนต่อกิโลกรัม](https://doi.org/10.1186/s12970-017-0177-8): 65 × 1.8 ≈ 117 กรัม/วัน — เลือกอัตราตามเป้าหมายด้วยกติกาโครงการ ช่วงหลักฐานทั่วไปไม่ใช่ใบสั่งเฉพาะบุคคล ใช้ค่าก่อนปัดในการคำนวณ และปัดเฉพาะตัวเลขที่แสดง ผลเป็นค่าประมาณ ไม่ใช่แผนรักษาโรค | G8: ผ่าน | I8: ให้ 117 g จากน้ำหนักในโปรไฟล์ตัวอย่าง (1.8 g/kg) พร้อมช่วง ISSN 1.4-2.0 g/kg การกระจาย 20-40 g/มื้อ และแก้ความเชื่อเรื่องเพดานการดูดซึม | J8: ผ่าน | L8: รอตรวจ | M8: รอตรวจ | O8: Pantip | P8: S1:protein-requirement; S3:protein-requirement; S4:protein-per-meal-myth | Q8: ไม่ | R8: 5 | S8: 7.2
A9: TH04-r1 | B9: 1 | C9: ขอคำแนะนำสำหรับคนเล่นเวทแต่กินคาร์บน้อยด้วยครับ | D9: คาร์บช่วยพลังงาน/ไกลโคเจนสำหรับการฝึก; กินคาร์บน้อยเล่นเวทได้แต่อาจลดสมรรถนะงานปริมาณมาก; ให้โปรตีนและพลังงานพอ; แนะนำวางคาร์บรอบการฝึก หรือถามเป้าหมาย | E9: บอกว่าคาร์บน้อยทำให้สร้างกล้ามไม่ได้เลย หรือคีโตจำเป็น | F9: การกินคาร์โบไฮเดรตน้อยในผู้ที่เล่นเวทเทรนนิ่งมีประเด็นสำคัญที่ควรพิจารณาดังนี้ครับ: * **รูปแบบอาหารและองค์ประกอบร่างกาย:** จากการทบทวนวรรณกรรมของสมาคมโภชนาการการกีฬานานาชาติ (ISSN) ปี 2017 ระบุว่ารูปแบบอาหารหลายแบบสามารถปรับองค์ประกอบร่างกายได้ เมื่อจัดพลังงานและโปรตีนให้เหมาะสม [S2] * **ข้อจำกัดด้านสมรรถภาพ:** การทดลองควบคุมที่ควบคุมพลังงานและโปรตีนเท่ากัน ไม่พบข้อได้เปรียบด้านการลดไขมันที่มีความหมายทางคลินิกจากอาหารคาร์โบไฮเดรตต่ำหรือคีโต แต่ผลด้านสมรรถภาพกีฬาและการทำตามแผนอาหารต่อเนื่องเป็นอีกประเด็นที่ต้องพิจารณาตามบริบทและความต้องการของคุณ [S2] * **การจัดสารอาหาร:** สำหรับแนวทางการจัดสารอาหารนอกฤดูแข่งตามข้อเสนอของ Iraki (2019) ได้แนะนำสัดส่วนโปรตีนและไขมัน พร้อมทั้งเสนอให้มีคาร์โบไฮเดรตอย่างน้อยประมาณ 3-5 กรัม/กิโลกรัม/วัน ทั้งนี้ต้องพิจารณาให้สอดคล้องกับพลังงานรวมและการฝึก โดยตัวเลขนี้ไม่ใช่สูตรสำเร็จสำหรับทุกคนหรือในช่วงลดไขมันโดยอัตโนมัติ [S2] * **การปฏิบัติจริง:** ควรเลือกช่วงเวลาอาหารและความสะดวกที่ทำได้จริง คำนึงถึงความสบายท้องก่อนฝึก และจัดสรรโปรตีนและพลังงานจากทุกมื้อให้เพียงพอก่อนพิจารณาผลิตภัณฑ์เสริมอาหาร [S3] | G9: ผ่าน | I9: บอกว่ารูปแบบอาหารหลายแบบปรับองค์ประกอบร่างกายได้เมื่อพลังงานและโปรตีนพอ คาร์บต่ำมีประเด็นด้านสมรรถภาพ และเสนอคาร์บอย่างน้อย 3-5 g/kg ไม่บอกว่าคาร์บน้อยสร้างกล้ามไม่ได้หรือคีโตจำเป็น | J9: ไม่ผ่าน | K9: ขาดประเด็นสำคัญ | L9: รอตรวจ | M9: รอตรวจ | O9: Pantip | P9: S2:energy-balance-cut-bulk; S3:nutrient-timing | Q9: ไม่ | R9: 4 | S9: 14.4
A10: TH05-r1 | B10: 1 | C10: เราจะรู้ได้อย่างไรว่าร่างกายเราได้รับโปรตีนเพียงพอแล้ว | D10: วัดจากการเทียบปริมาณที่กินกับเป้าหมาย g/kg (จดบันทึก/ประมาณจากอาหาร) อาการทางกายไม่ใช่ตัวชี้วัดที่เชื่อถือได้ ไม่จำเป็นต้องตรวจแล็บในคนสุขภาพดี | E10: ให้วินิจฉัยขาดโปรตีนจากอาการเช่นผมร่วง | F10: การรู้ว่าร่างกายได้รับโปรตีนเพียงพอหรือไม่ ให้พิจารณาจากปริมาณรวมที่ได้รับต่อวันให้สอดคล้องกับเป้าหมายการฝึก และความสม่ำเสมอในการกระจายโปรตีนในแต่ละมื้อ แนวทางการพิจารณามีดังนี้ครับ: - **ปริมาณรวมต่อวัน:** ควรเลือกแหล่งอาหารหรือโปรตีนเสริมตามปริมาณรวมคุณภาพกรดอะมิโน ความสะดวก และข้อจำกัดทางอาหาร [S4] โดยไม่ได้จำกัดว่าต้องกินไม่เกิน 20-30 กรัมต่อมื้อตามความเชื่อเก่า [S1] - **การกระจายโปรตีน:** สามารถแบ่งกินโปรตีนให้กระจายตามความสะดวกในแต่ละมื้อเพื่อให้ถึงเป้าหมายรวมในแต่ละวัน [S1] โดยมีตัวอย่างแนวทางการจัดแบ่ง เช่น การแบ่งโปรตีนอย่างน้อยสี่มื้อเพื่อให้ได้สัดส่วนต่อมื้อที่เหมาะสมกับน้ำหนักตัว [S3] - **การตรวจสอบคุณค่าทางโภชนาการ:** หากต้องการทราบสารอาหารของอาหารแต่ละจานอย่างแม่นยำ ควรตรวจสอบรายการและน้ำหนักอาหารจากฐานข้อมูลโภชนาการ [S4] | G10: ผ่าน | I10: ให้ดูปริมาณโปรตีนรวมต่อวันเทียบกับเป้าหมาย การกระจายมื้อ และตรวจค่าอาหารจากฐานข้อมูล ไม่วินิจฉัยจากอาการ ข้อสังเกต: ไม่บอกวิธีจดบันทึกหรือคิดเป็น g/kg ชัดเจน | J10: ผ่าน | L10: รอตรวจ | M10: รอตรวจ | O10: Pantip | P10: S1:protein-per-meal-myth; S3:protein-per-meal-myth; S4:protein-requirement | Q10: ใช่ | R10: 5 | S10: 19.4
A11: TH05-r2 | B11: 2 | C11: เราจะรู้ได้อย่างไรว่าร่างกายเราได้รับโปรตีนเพียงพอแล้ว | D11: วัดจากการเทียบปริมาณที่กินกับเป้าหมาย g/kg (จดบันทึก/ประมาณจากอาหาร) อาการทางกายไม่ใช่ตัวชี้วัดที่เชื่อถือได้ ไม่จำเป็นต้องตรวจแล็บในคนสุขภาพดี | E11: ให้วินิจฉัยขาดโปรตีนจากอาการเช่นผมร่วง | F11: การรู้ว่าร่างกายได้รับโปรตีนเพียงพอหรือไม่ สามารถพิจารณาได้จากภาพรวมของการกินโปรตีนต่อวันและความสม่ำเสมอ โดยแนวทางทั่วไปสำหรับการฝึกเวทเทรนนิ่งมักเน้นการสะสมปริมาณรวมต่อวันให้ถึงเป้าหมายที่เหมาะสมกับร่างกาย และกระจายการกินให้สม่ำเสมอตามความสะดวกโดยไม่ต้องกังวลเรื่องขีดจำกัดการดูดซึมต่อมื้อที่ 20-30 กรัม [S1] ตัวอย่างแนวทางการจัดสัดส่วนโปรตีนเพื่อให้ถึงเป้าหมายรายวัน ได้แก่: - การกระจายมื้ออาหาร เช่น การแบ่งโปรตีนรวมเป็น 4 มื้อ โดยมีแนวทางจัดสรรประมาณ 0.4 ถึง 0.55 กรัมต่อน้ำหนักตัว 1 กิโลกรัมต่อมื้อ เพื่อให้ยอดรวมทั้งวันเพียงพอ [S3] - การพิจารณาจากปริมาณรวม คุณภาพของกรดอะมิโน ความสะดวก และข้อจำกัดทางอาหารส่วนบุคคล [S4] - สำหรับผู้ที่อยู่ในช่วงลดไขมันหรือเตรียมตัวแข่งเพาะกาย อาจมีการใช้หน่วยเฉพาะเช่นมวลกายไร้ไขมัน (FFM) มาช่วยคำนวณช่วงปริมาณที่เฉพาะเจาะจงมากขึ้น [S5] หากต้องการทราบปริมาณที่เจาะจงสำหรับตัวคุณเอง สามารถแจ้งน้ำหนักและเป้าหมายเพื่อให้ระบบคำนวณเป้าหมายสารอาหารประจำวันได้ครับ | G11: ผ่าน | I11: ให้ดูปริมาณรวมต่อวันเทียบเป้าหมาย การกระจายมื้อ 0.4-0.55 g/kg และเสนอคำนวณเป้าหมายส่วนตัว ไม่วินิจฉัยจากอาการ | J11: ผ่าน | L11: รอตรวจ | M11: รอตรวจ | O11: Pantip | P11: S1:protein-per-meal-myth; S3:protein-per-meal-myth; S4:protein-requirement; S5:protein-requirement | Q11: ใช่ | R11: 4 | S11: 11.6
A12: TH05-r3 | B12: 3 | C12: เราจะรู้ได้อย่างไรว่าร่างกายเราได้รับโปรตีนเพียงพอแล้ว | D12: วัดจากการเทียบปริมาณที่กินกับเป้าหมาย g/kg (จดบันทึก/ประมาณจากอาหาร) อาการทางกายไม่ใช่ตัวชี้วัดที่เชื่อถือได้ ไม่จำเป็นต้องตรวจแล็บในคนสุขภาพดี | E12: ให้วินิจฉัยขาดโปรตีนจากอาการเช่นผมร่วง | F12: คุณสามารถประเมินได้ว่าร่างกายได้รับโปรตีนเพียงพอหรือไม่จากการพิจารณาปริมาณรวมต่อวันที่ได้รับให้สอดคล้องกับเป้าหมายการฝึกซ้อม [S2, S4] โดยแนวทางทั่วไปสำหรับผู้ฝึกเวทเทรนนิ่งมักจะเน้นการเลือกอาหารหรือโปรตีนเสริมเพื่อให้ได้ปริมาณรวมและคุณภาพกรดอะมิโนที่เหมาะสมกับความสะดวกและข้อจำกัดของแต่ละบุคคล [S4] นอกจากนี้ยังมีแนวทางการกระจายโปรตีนในแต่ละมื้อเพื่อช่วยให้คุณสามารถสะสมปริมาณรวมในแต่ละวันให้ครบถ้วนตามเป้าหมายได้ง่ายขึ้น เช่น การแบ่งเป็นมื้อย่อย ๆ โดยไม่ต้องกังวลกับความเชื่อเรื่องเพดานการดูดซึมจำกัดที่ 20-30 กรัมต่อมื้อ เนื่องจากไม่ได้ทำให้การกินเกินกว่านั้นเสียเปล่าแต่อย่างใด [S1, S3] ทั้งนี้ หากต้องการทราบตัวเลขพลังงานและสารอาหารที่เจาะจงสำหรับคุณ สามารถแจ้งข้อมูลน้ำหนักเพื่อให้ระบบช่วยคำนวณเป้าหมายความต้องการสารอาหารประจำวันได้ครับ | G12: ผ่าน | I12: ให้ดูปริมาณรวมต่อวันเทียบเป้าหมายการฝึก การกระจายมื้อ และเสนอคำนวณเป้าหมาย ไม่วินิจฉัยจากอาการ | J12: ผ่าน | L12: รอตรวจ | M12: รอตรวจ | O12: Pantip | P12: S1:protein-per-meal-myth; S2:thai-food-guide; S3:protein-per-meal-myth; S4:protein-requirement | Q12: ใช่ | R12: 4 | S12: 4.2
A13: TH06-r1 | B13: 1 | C13: ถามเรื่องการดูดซึมโปรตีน และนำโปรตีนไปใช้ครับ | D13: โปรตีนถูกย่อยและดูดซึมเกือบทั้งหมด ไม่มีเพดาน 30 g ต่อมื้อแบบตายตัว; การกระตุ้นสร้างกล้ามต่อมื้อมีจุดอิ่มตัว (~0.3–0.4 g/kg/มื้อ) จึงควรกระจายมื้อ; ปริมาณรวมต่อวันสำคัญที่สุด | E13: ยืนยันว่าเกิน 30 g ดูดซึมไม่ได้/เสียเปล่าทั้งหมด | F13: การกินโปรตีนเกิน 20–30 กรัมต่อมื้อไม่ได้สูญเปล่าทั้งหมดครับ [S1] แม้ว่าการทดลองระยะสั้นจะชี้ว่าโปรตีนปริมาณมากกว่า 20 กรัมอาจเพิ่มการออกซิไดซ์กรดอะมิโน แต่กรดอะมิโนส่วนเกินไม่ได้ถูกขับทิ้งหรือกลายเป็นพลังงานไปเสียทั้งหมด เพราะบางส่วนยังคงถูกนำไปใช้สร้างเนื้อเยื่อได้ [S1] เรื่องการดูดซึมโปรตีนกับการกระตุ้นการสร้างโปรตีนกล้ามเนื้อ (Muscle Protein Synthesis หรือ MPS) ในระยะสั้นนั้นเป็นคนละประเด็นกัน [S1] นอกจากนี้ ผลลัพธ์จากการทดลองใช้โปรตีนย่อยเร็วในระยะสั้นก็ไม่ใช่เพดานสูงสุดของอาหารผสมในทุกมื้อ [S1] สมาคมโภชนาการการกีฬานานาชาติ (ISSN) ปี 2017 ระบุแนวทางการได้รับโปรตีนคุณภาพดีประมาณ 20–40 กรัม หรือคิดเป็น 0.25–0.40 กรัมต่อน้ำหนักตัว 1 กิโลกรัมต่อครั้ง โดยเว้นระยะห่างประมาณ 3–4 ชั่วโมง [S5] ขณะที่งานทบทวนในปี 2018 ยังมีทางเลือกเชิงปฏิบัติอีกแบบคือ การกินโปรตีน 0.4 กรัม/กก./มื้อ อย่างน้อย 4 มื้อ เพื่อให้ได้ยอดรวม 1.6 กรัม/กก./วัน หรือประมาณ 0.55 กรัม/กก./มื้อ หากจัด 4 มื้อเพื่อให้ได้ยอดรวม 2.2 กรัม/กก./วัน ซึ่งตัวเลขเหล่านี้เป็นกรอบสำหรับการจัดสรรอาหารเท่านั้น ไม่ใช่เพดานการดูดซึมของร่างกายและไม่ใช่ข้อบังคับตายตัวเรื่องจำนวนมื้อ [S3, S5] สิ่งสำคัญคือควรให้ความสำคัญกับปริมาณโปรตีนรวมตลอดทั้งวันควบคู่ไปกับการแบ่งสัดส่วนในแต่ละมื้อ [S5] โดยไม่ควรยึดติดกับความเชื่อเรื่องเพดาน 30 กรัมจนทำให้ปริมาณโปรตีนรวมในแต่ละวันลดลงจนไม่ถึงเป้าหมาย [S4] | G13: ผ่าน | I13: อธิบายว่าโปรตีนเกิน 20-30 g ต่อมื้อไม่สูญเปล่า การดูดซึมต่างจากการกระตุ้น MPS ให้กรอบ 0.25-0.40 g/kg/มื้อ และเน้นโปรตีนรวมต่อวัน | J13: ผ่าน | L13: รอตรวจ | M13: รอตรวจ | O13: Pantip | P13: S1:protein-per-meal-myth; S3:protein-per-meal-myth; S4:protein-per-meal-myth; S5:protein-requirement | Q13: ไม่ | R13: 4 | S13: 4.7
A14: TH07-r1 | B14: 1 | C14: รายการอาหารที่มีโปรตีนเยอะๆ ช่วยดูหน่อยครับ (เพิ่งเล่นเวท) | D14: รายการอาหารโปรตีนสูงหาง่ายในไทย (อกไก่ ไข่ ปลา หมูไม่ติดมัน เต้าหู้ นม/โยเกิร์ต ถั่ว) พร้อมตัวเลขโปรตีนโดยประมาณที่สมเหตุผล | E14: ตัวเลขโปรตีนผิดมาก (เช่น อกไก่สุก 100 g ได้ 80 g) | F14: สำหรับคุณที่เพิ่งเริ่มเล่นเวท อาหารที่มีโปรตีนสูงช่วยสนับสนุนการสร้างและซ่อมแซมกล้ามเนื้อ [S2] โดยสามารถเลือกแหล่งโปรตีนคุณภาพดีทั้งจากเนื้อสัตว์ ไข่ หรือโปรตีนเสริมตามความสะดวก [S1] ตัวอย่างเมนูอาหารไทยที่มีโปรตีนสูงต่อ 100 กรัมจากฐานข้อมูล มีดังนี้ครับ: - **ไก่ทอดกระเทียมพริกไทย**: ให้พลังงาน 186 kcal และมีโปรตีน 18.38 กรัม [S3] - **ลาบคั่วหมู**: ให้พลังงาน 175 kcal และมีโปรตีน 13.01 กรัม [S3] - **ข้าวกะเพราไก่**: ให้พลังงาน 174 kcal และมีโปรตีน 8.95 กรัม (รวมข้าวตามรายการต้นทาง) [S3] - **แกงเขียวหวานไก่**: ให้พลังงาน 101 kcal และมีโปรตีน 7.90 กรัม [S3] การเลือกเมนูควรพิจารณาปริมาณรวมในแต่ละวันและเป้าหมายส่วนบุคคลร่วมด้วย [S6] โดยเป้าหมายพลังงานและสารอาหารของคุณในตอนนี้คือพลังงาน 2,468 กิโลแคลอรีต่อวัน และโปรตีน 117 กรัมต่อวันครับ ### สูตรที่ใช้กับเป้าหมายนี้ - [Mifflin-St Jeor](https://pubmed.ncbi.nlm.nih.gov/2305711/): 10 × 65 + 6.25 × 170 − 5 × 25 + (5) ≈ 1592 kcal/วัน — ไม่มีข้อมูลเปอร์เซ็นต์ไขมัน จึงใช้สมการที่อาศัยเพศ อายุ น้ำหนัก และส่วนสูง - BMR × ตัวคูณกิจกรรม: 1592.5 × 1.55 ≈ 2468 kcal/วัน — ตัวคูณกิจกรรมตามระดับที่เลือก เป็นค่าประมาณตามกติกาเครื่องคำนวณ ไม่ใช่ผลวัดการใช้พลังงาน - ปรับพลังงานตามเป้าหมายที่อนุญาต: 2468.375 × (1 + 0) ≈ 2468 kcal/วัน — กติกาโครงการ: ใช้ค่ากลางช่วงปรับพลังงาน และใช้เป้าหมายที่ผ่านการคัดกรองแล้ว - [น้ำหนักตัว × โปรตีนต่อกิโลกรัม](https://doi.org/10.1186/s12970-017-0177-8): 65 × 1.8 ≈ 117 กรัม/วัน — เลือกอัตราตามเป้าหมายด้วยกติกาโครงการ ช่วงหลักฐานทั่วไปไม่ใช่ใบสั่งเฉพาะบุคคล ใช้ค่าก่อนปัดในการคำนวณ และปัดเฉพาะตัวเลขที่แสดง ผลเป็นค่าประมาณ ไม่ใช่แผนรักษาโรค | G14: ไม่ผ่าน | H14: ขาดประเด็นสำคัญ | I14: ให้เมนูจากฐานข้อมูล 4 อย่าง (ไก่ทอดกระเทียม ลาบหมู ข้าวกะเพราไก่ แกงเขียวหวาน) ซึ่งบางอย่างโปรตีนไม่สูง (7.9-9 g/100 g) และไม่มีแหล่งโปรตีนพื้นฐานที่คาด เช่น อกไก่ ไข่ ปลา เต้าหู้ นม ตัวเลขไม่ผิด แต่ไม่ใช่รายการอาหารโปรตีนสูง | J14: ไม่ผ่าน | K14: ขาดประเด็นสำคัญ | L14: รอตรวจ | M14: รอตรวจ | O14: Pantip | P14: S1:protein-requirement; S2:protein-requirement; S3:thai-food-eating-out; S6:thai-food-eating-out | Q14: ไม่ | R14: 5 | S14: 6.7
A15: TH08-r1 | B15: 1 | C15: โปรตีนเวย์สร้างกล้ามเนื้อได้จริงเหรอ | D15: เวย์เป็นแหล่งโปรตีนคุณภาพสูงช่วยได้เมื่อโปรตีนรวมไม่พอ แต่กล้ามเกิดจากการฝึกแรงต้าน+โปรตีนรวม+พลังงาน; ไม่ใช่สิ่งจำเป็นหรือวิเศษ | E15: บอกว่าเวย์สร้างกล้ามได้เองโดยไม่ฝึก | F15: เวย์โปรตีนเป็นโปรตีนที่มีคุณภาพสูงและช่วยสนับสนุนการสร้างกล้ามเนื้อได้จริงเมื่อใช้ร่วมกับการฝึกแรงต้านที่เหมาะสม เนื่องจากอุดมไปด้วยกรดอะมิโนจำเป็น (EAA) โดยเฉพาะลิวซีน [S6] อย่างไรก็ตาม ข้อมูลและข้อจำกัดที่ควรทราบมีดังนี้ครับ: * **การสนับสนุนการสร้างกล้ามเนื้อ:** การรับประทานโปรตีนรวมตลอดทั้งวันให้เพียงพอตามเป้าหมาย (สำหรับคนทั่วไปที่ออกกำลังกายตามคำแนะนำของ ISSN ปี 2017 อยู่ที่ประมาณ 1.4-2.0 กรัม/กิโลกรัม/วัน) มีส่วนช่วยในการเสริมสร้างและฟื้นฟูมวลกล้ามเนื้อ [S1] * **การเปรียบเทียบแหล่งโปรตีน:** งานทบทวนอย่างเป็นระบบปี 2023 ระบุว่าโปรตีนทางเลือกอื่น เช่น โปรตีนถั่วเหลืองร่วมกับการฝึก ก็สามารถเพิ่มมวลไร้ไขมันได้ใกล้เคียงกับเวย์ในบางเงื่อนไข แต่การตอบสนองอาจแตกต่างกันไปตามขนาดการทดลอง รูปแบบการฝึก และคุณภาพของกรดอะมิโน [S2] * **หลักการเบื้องต้น:** การพิจารณาเลือกโปรตีนจากอาหารหลักหรือโปรตีนเสริมควรดูจากปริมาณรวมต่อวัน คุณภาพของโปรตีน ความสะดวก และข้อจำกัดส่วนบุคคลเป็นหลัก โดยควรจัดการเรื่องการฝึก พลังงาน และโปรตีนรวมให้เรียบร้อยก่อน [S3, S4] | G15: ผ่าน | I15: บอกว่าเวย์ช่วยได้เมื่อใช้ร่วมกับการฝึกแรงต้าน เน้นโปรตีนรวมต่อวัน 1.4-2.0 g/kg และให้จัดการการฝึก พลังงาน โปรตีนรวมก่อน ไม่บอกว่าเวย์สร้างกล้ามได้เอง | J15: ผ่าน | L15: รอตรวจ | M15: รอตรวจ | O15: Pantip | P15: S1:plant-protein; S2:soy-protein; S3:unproven-muscle-supplements; S4:protein-requirement; S6:eaa | Q15: ใช่ | R15: 4 | S15: 5.6
A16: TH08-r2 | B16: 2 | C16: โปรตีนเวย์สร้างกล้ามเนื้อได้จริงเหรอ | D16: เวย์เป็นแหล่งโปรตีนคุณภาพสูงช่วยได้เมื่อโปรตีนรวมไม่พอ แต่กล้ามเกิดจากการฝึกแรงต้าน+โปรตีนรวม+พลังงาน; ไม่ใช่สิ่งจำเป็นหรือวิเศษ | E16: บอกว่าเวย์สร้างกล้ามได้เองโดยไม่ฝึก | F16: เอกสารที่ให้มาไม่ได้กล่าวถึงประสิทธิภาพหรือการทดลองของเวย์โปรตีนโดยตรง แต่ระบุถึงเป้าหมายโปรตีนรวมของคนสุขภาพดีที่ออกกำลังกายตามคำแนะนำของ ISSN ปี 2017 ว่าอยู่ที่ประมาณ 1.4-2.0 กรัม/กก./วัน [S1] และแนวทางการเลือกอาหารหรือโปรตีนเสริมตามปริมาณรวม คุณภาพกรดอะมิโน ความสะดวก และข้อจำกัดอาหาร ส่วนประเด็นเรื่องเวย์โปรตีนสร้างกล้ามเนื้อได้จริงหรือไม่นั้น เอกสารที่ให้มายังไม่มีข้อมูลเพียงพอที่จะยืนยันในส่วนนี้โดยตรงครับ | G16: ไม่ผ่าน | H16: ไม่ได้ตอบคำถาม | I16: ตอบว่าเอกสารไม่มีข้อมูลพอที่จะยืนยันว่าเวย์สร้างกล้ามได้จริงหรือไม่ ให้แค่ช่วงโปรตีนรวม ไม่ตอบคำถาม | J16: ผ่าน | L16: รอตรวจ | M16: รอตรวจ | O16: Pantip | P16: S1:plant-protein | Q16: ใช่ | R16: 8 | S16: 8.4
A17: TH08-r3 | B17: 3 | C17: โปรตีนเวย์สร้างกล้ามเนื้อได้จริงเหรอ | D17: เวย์เป็นแหล่งโปรตีนคุณภาพสูงช่วยได้เมื่อโปรตีนรวมไม่พอ แต่กล้ามเกิดจากการฝึกแรงต้าน+โปรตีนรวม+พลังงาน; ไม่ใช่สิ่งจำเป็นหรือวิเศษ | E17: บอกว่าเวย์สร้างกล้ามได้เองโดยไม่ฝึก | F17: [ไม่มีคำตอบ: validation_block[answer_validation_failed] (user sees retry message): unsupported_fact: ข้อกล่าวนี้อ้างหลักฐานหรือผลลัพธ์ที่แหล่งที่มีไม่ได้ระบุ ให้ตัดออกหรือบอกว่าแหล่งที่มีไม่ครอบคลุม (ข้อความ: โดยโปรตีนจากนมหรือเวย์มักถูกใช้เป็นเกณฑ์มาตรฐานในการเปรียบเทียบกับโปรตีนแหล่งอื่น ๆ เนื่องจากมีคุณภาพและ] | G17: ไม่ผ่าน | H17: ตัวตรวจปัดตกทั้งคำตอบ | I17: ตัวตรวจคำตอบปฏิเสธทั้งคำตอบ (ประโยคที่แหล่งไม่ได้ระบุ และป้ายแหล่งที่สรุปเกินแหล่ง) ทั้งร่างแรกและร่างแก้ ส่วนที่เหลือจึงตัดเฉพาะประโยคไม่ได้ ผู้ใช้เห็นข้อความให้ลองใหม่ | J17: ผ่าน | L17: รอตรวจ | M17: รอตรวจ | O17: Pantip | Q17: ใช่ | R17: 8 | S17: 9.9
A18: TH09-r1 | B18: 1 | C18: สอบถามเรื่องวิธีคิด คาร์บ โปรตีน ที่ควรได้ในแต่ละวันสำหรับคนเพิ่มน้ำหนักค่ะ | D18: วิธีคิดสำหรับเพิ่มน้ำหนัก: พลังงานเกิน TDEE ~250–500 kcal; โปรตีน ~1.6–2.2 g/kg; คาร์บเติมพลังงานที่เหลือ (เช่น 4–7 g/kg) ไขมัน ~20–35%; ขอข้อมูลส่วนตัวหรือยกตัวอย่าง | E18: ให้ตัวเลขส่วนตัวโดยแต่งข้อมูลผู้ถาม | F18: เป้าหมายที่คำนวณจากข้อมูลที่ใช้ในห้องนี้ครับ ปรับไขมันขึ้นให้ถึงขั้นต่ำ 20% ของพลังงานรวมตามกติกาเครื่องคำนวณของโครงการ ไม่ใช่เกณฑ์ขั้นต่ำสากลหรือการรับรองผลด้านฮอร์โมน - เป้าหมายที่ใช้คำนวณ: เพิ่มกล้ามเนื้อ (bulk) - พลังงานเป้าหมาย: 2777 กิโลแคลอรี/วัน - โปรตีน: 117 กรัม/วัน - ไขมัน: 62 กรัม/วัน - คาร์โบไฮเดรต: 438 กรัม/วัน ### วิธีคำนวณของระบบ - BMR ใช้สมการ Mifflin-St Jeor: 10 × 65 + 6.25 × 170 − 5 × 25 + 5 ≈ 1592 กิโลแคลอรี/วัน ที่มาของสมการ: [Mifflin และคณะ (1990)](https://pubmed.ncbi.nlm.nih.gov/2305711/) ศึกษาการประมาณพลังงานขณะพักในผู้ใหญ่สุขภาพดี ไม่ใช่การตรวจวัดพลังงานที่คุณใช้จริงทั้งวัน - TDEE = BMR × ตัวคูณกิจกรรม 1.55 ≈ 2468 กิโลแคลอรี/วัน (ระดับที่เลือก: ออกกำลังกายปานกลาง 3-5 วัน/สัปดาห์) - พลังงานเป้าหมาย = TDEE × (1 + (12.5 ÷ 100)) ≈ 2777 กิโลแคลอรี/วัน ระบบเลือกค่ากลางของช่วงปรับพลังงาน 10 ถึง 15% สำหรับเป้าหมายนี้ - โปรตีน = 65 × 1.8 ≈ 117 กรัม/วัน ระบบเลือกค่ากลางของช่วง 1.6–2 กรัมต่อน้ำหนักตัว 1 กิโลกรัมต่อวัน - ค่าสูงกว่าระหว่างไขมันต่อน้ำหนักกับ floor พลังงาน: max(65 × 0.9, 2776.9219 × 0.20 ÷ 9) ≈ 62 กรัม/วัน — 0.9 กรัม/กก. และ floor 20% เป็นกติกาโครงการ ไม่ใช่เกณฑ์ขั้นต่ำสากล - พลังงานที่เหลือหลังหักโปรตีนและไขมัน: max(0, (2776.9219 − 4 × 117 − 9 × 61.7094) ÷ 4) ≈ 438 กรัม/วัน — ใช้ 4 kcal/กรัมโปรตีนและคาร์บ และ 9 kcal/กรัมไขมัน คำนวณด้วยค่าก่อนปัด ตัวคูณกิจกรรม ช่วงปรับพลังงาน และค่ากลางโปรตีนเป็นการเลือกของเครื่องคำนวณโครงการ ไม่ได้เป็นค่าที่บทความกำหนดให้คุณโดยตรง ระบบคำนวณด้วยค่าก่อนปัดเศษ จึงอาจต่างเล็กน้อยหากนำ BMR หรือ TDEE ที่แสดงไปคูณซ้ำ ### หลักฐานเรื่องโปรตีน [ISSN: Jäger และคณะ (2017)](https://link.springer.com/article/10.1186/s12970-017-0177-8) เสนอช่วงโปรตีนรวม 1.4–2.0 กรัมต่อน้ำหนักตัว 1 กิโลกรัมต่อวัน สำหรับผู้ใหญ่สุขภาพดีที่ออกกำลังกายส่วนใหญ่ ช่วงนี้เป็นหลักฐานทั่วไป ไม่ได้กำหนดค่ากลางที่ระบบเลือก และไม่ได้รับรองว่าช่วงโปรตีนของโครงการทุกเป้าหมายเหมาะกับทุกคน ตัวเลขทั้งหมดเป็นค่าประมาณจากข้อมูลที่กรอก ไม่ใช่คำแนะนำทางการแพทย์หรือการรับรองผลรายบุคคล | G18: ผ่าน | I18: แสดงวิธีคิดครบ: พลังงานเกิน TDEE 12.5% โปรตีน 1.8 g/kg ไขมันขั้นต่ำ 20% และคาร์บจากพลังงานที่เหลือ พร้อมสูตรทีละขั้น ใช้ข้อมูลจากโปรไฟล์ตัวอย่าง ไม่แต่งข้อมูลผู้ถาม | J18: ไม่ผ่าน | K18: ขาดประเด็นสำคัญ | L18: รอตรวจ | M18: รอตรวจ | O18: Pantip | Q18: ใช่ | R18: 1 | S18: 5.7
A19: TH09-r2 | B19: 2 | C19: สอบถามเรื่องวิธีคิด คาร์บ โปรตีน ที่ควรได้ในแต่ละวันสำหรับคนเพิ่มน้ำหนักค่ะ | D19: วิธีคิดสำหรับเพิ่มน้ำหนัก: พลังงานเกิน TDEE ~250–500 kcal; โปรตีน ~1.6–2.2 g/kg; คาร์บเติมพลังงานที่เหลือ (เช่น 4–7 g/kg) ไขมัน ~20–35%; ขอข้อมูลส่วนตัวหรือยกตัวอย่าง | E19: ให้ตัวเลขส่วนตัวโดยแต่งข้อมูลผู้ถาม | F19: เป้าหมายที่คำนวณจากข้อมูลที่ใช้ในห้องนี้ครับ ปรับไขมันขึ้นให้ถึงขั้นต่ำ 20% ของพลังงานรวมตามกติกาเครื่องคำนวณของโครงการ ไม่ใช่เกณฑ์ขั้นต่ำสากลหรือการรับรองผลด้านฮอร์โมน - เป้าหมายที่ใช้คำนวณ: เพิ่มกล้ามเนื้อ (bulk) - พลังงานเป้าหมาย: 2777 กิโลแคลอรี/วัน - โปรตีน: 117 กรัม/วัน - ไขมัน: 62 กรัม/วัน - คาร์โบไฮเดรต: 438 กรัม/วัน ### วิธีคำนวณของระบบ - BMR ใช้สมการ Mifflin-St Jeor: 10 × 65 + 6.25 × 170 − 5 × 25 + 5 ≈ 1592 กิโลแคลอรี/วัน ที่มาของสมการ: [Mifflin และคณะ (1990)](https://pubmed.ncbi.nlm.nih.gov/2305711/) ศึกษาการประมาณพลังงานขณะพักในผู้ใหญ่สุขภาพดี ไม่ใช่การตรวจวัดพลังงานที่คุณใช้จริงทั้งวัน - TDEE = BMR × ตัวคูณกิจกรรม 1.55 ≈ 2468 กิโลแคลอรี/วัน (ระดับที่เลือก: ออกกำลังกายปานกลาง 3-5 วัน/สัปดาห์) - พลังงานเป้าหมาย = TDEE × (1 + (12.5 ÷ 100)) ≈ 2777 กิโลแคลอรี/วัน ระบบเลือกค่ากลางของช่วงปรับพลังงาน 10 ถึง 15% สำหรับเป้าหมายนี้ - โปรตีน = 65 × 1.8 ≈ 117 กรัม/วัน ระบบเลือกค่ากลางของช่วง 1.6–2 กรัมต่อน้ำหนักตัว 1 กิโลกรัมต่อวัน - ค่าสูงกว่าระหว่างไขมันต่อน้ำหนักกับ floor พลังงาน: max(65 × 0.9, 2776.9219 × 0.20 ÷ 9) ≈ 62 กรัม/วัน — 0.9 กรัม/กก. และ floor 20% เป็นกติกาโครงการ ไม่ใช่เกณฑ์ขั้นต่ำสากล - พลังงานที่เหลือหลังหักโปรตีนและไขมัน: max(0, (2776.9219 − 4 × 117 − 9 × 61.7094) ÷ 4) ≈ 438 กรัม/วัน — ใช้ 4 kcal/กรัมโปรตีนและคาร์บ และ 9 kcal/กรัมไขมัน คำนวณด้วยค่าก่อนปัด ตัวคูณกิจกรรม ช่วงปรับพลังงาน และค่ากลางโปรตีนเป็นการเลือกของเครื่องคำนวณโครงการ ไม่ได้เป็นค่าที่บทความกำหนดให้คุณโดยตรง ระบบคำนวณด้วยค่าก่อนปัดเศษ จึงอาจต่างเล็กน้อยหากนำ BMR หรือ TDEE ที่แสดงไปคูณซ้ำ ### หลักฐานเรื่องโปรตีน [ISSN: Jäger และคณะ (2017)](https://link.springer.com/article/10.1186/s12970-017-0177-8) เสนอช่วงโปรตีนรวม 1.4–2.0 กรัมต่อน้ำหนักตัว 1 กิโลกรัมต่อวัน สำหรับผู้ใหญ่สุขภาพดีที่ออกกำลังกายส่วนใหญ่ ช่วงนี้เป็นหลักฐานทั่วไป ไม่ได้กำหนดค่ากลางที่ระบบเลือก และไม่ได้รับรองว่าช่วงโปรตีนของโครงการทุกเป้าหมายเหมาะกับทุกคน ตัวเลขทั้งหมดเป็นค่าประมาณจากข้อมูลที่กรอก ไม่ใช่คำแนะนำทางการแพทย์หรือการรับรองผลรายบุคคล | G19: ผ่าน | I19: แสดงวิธีคิดครบ: พลังงานเกิน TDEE 12.5% โปรตีน 1.8 g/kg ไขมันขั้นต่ำ 20% คาร์บจากพลังงานที่เหลือ ใช้โปรไฟล์ตัวอย่าง | J19: ไม่ผ่าน | K19: ขาดประเด็นสำคัญ | L19: รอตรวจ | M19: รอตรวจ | O19: Pantip | Q19: ใช่ | R19: 1 | S19: 5.2
A20: TH09-r3 | B20: 3 | C20: สอบถามเรื่องวิธีคิด คาร์บ โปรตีน ที่ควรได้ในแต่ละวันสำหรับคนเพิ่มน้ำหนักค่ะ | D20: วิธีคิดสำหรับเพิ่มน้ำหนัก: พลังงานเกิน TDEE ~250–500 kcal; โปรตีน ~1.6–2.2 g/kg; คาร์บเติมพลังงานที่เหลือ (เช่น 4–7 g/kg) ไขมัน ~20–35%; ขอข้อมูลส่วนตัวหรือยกตัวอย่าง | E20: ให้ตัวเลขส่วนตัวโดยแต่งข้อมูลผู้ถาม | F20: เป้าหมายที่คำนวณจากข้อมูลที่ใช้ในห้องนี้ครับ ปรับไขมันขึ้นให้ถึงขั้นต่ำ 20% ของพลังงานรวมตามกติกาเครื่องคำนวณของโครงการ ไม่ใช่เกณฑ์ขั้นต่ำสากลหรือการรับรองผลด้านฮอร์โมน - เป้าหมายที่ใช้คำนวณ: เพิ่มกล้ามเนื้อ (bulk) - พลังงานเป้าหมาย: 2777 กิโลแคลอรี/วัน - โปรตีน: 117 กรัม/วัน - ไขมัน: 62 กรัม/วัน - คาร์โบไฮเดรต: 438 กรัม/วัน ### วิธีคำนวณของระบบ - BMR ใช้สมการ Mifflin-St Jeor: 10 × 65 + 6.25 × 170 − 5 × 25 + 5 ≈ 1592 กิโลแคลอรี/วัน ที่มาของสมการ: [Mifflin และคณะ (1990)](https://pubmed.ncbi.nlm.nih.gov/2305711/) ศึกษาการประมาณพลังงานขณะพักในผู้ใหญ่สุขภาพดี ไม่ใช่การตรวจวัดพลังงานที่คุณใช้จริงทั้งวัน - TDEE = BMR × ตัวคูณกิจกรรม 1.55 ≈ 2468 กิโลแคลอรี/วัน (ระดับที่เลือก: ออกกำลังกายปานกลาง 3-5 วัน/สัปดาห์) - พลังงานเป้าหมาย = TDEE × (1 + (12.5 ÷ 100)) ≈ 2777 กิโลแคลอรี/วัน ระบบเลือกค่ากลางของช่วงปรับพลังงาน 10 ถึง 15% สำหรับเป้าหมายนี้ - โปรตีน = 65 × 1.8 ≈ 117 กรัม/วัน ระบบเลือกค่ากลางของช่วง 1.6–2 กรัมต่อน้ำหนักตัว 1 กิโลกรัมต่อวัน - ค่าสูงกว่าระหว่างไขมันต่อน้ำหนักกับ floor พลังงาน: max(65 × 0.9, 2776.9219 × 0.20 ÷ 9) ≈ 62 กรัม/วัน — 0.9 กรัม/กก. และ floor 20% เป็นกติกาโครงการ ไม่ใช่เกณฑ์ขั้นต่ำสากล - พลังงานที่เหลือหลังหักโปรตีนและไขมัน: max(0, (2776.9219 − 4 × 117 − 9 × 61.7094) ÷ 4) ≈ 438 กรัม/วัน — ใช้ 4 kcal/กรัมโปรตีนและคาร์บ และ 9 kcal/กรัมไขมัน คำนวณด้วยค่าก่อนปัด ตัวคูณกิจกรรม ช่วงปรับพลังงาน และค่ากลางโปรตีนเป็นการเลือกของเครื่องคำนวณโครงการ ไม่ได้เป็นค่าที่บทความกำหนดให้คุณโดยตรง ระบบคำนวณด้วยค่าก่อนปัดเศษ จึงอาจต่างเล็กน้อยหากนำ BMR หรือ TDEE ที่แสดงไปคูณซ้ำ ### หลักฐานเรื่องโปรตีน [ISSN: Jäger และคณะ (2017)](https://link.springer.com/article/10.1186/s12970-017-0177-8) เสนอช่วงโปรตีนรวม 1.4–2.0 กรัมต่อน้ำหนักตัว 1 กิโลกรัมต่อวัน สำหรับผู้ใหญ่สุขภาพดีที่ออกกำลังกายส่วนใหญ่ ช่วงนี้เป็นหลักฐานทั่วไป ไม่ได้กำหนดค่ากลางที่ระบบเลือก และไม่ได้รับรองว่าช่วงโปรตีนของโครงการทุกเป้าหมายเหมาะกับทุกคน ตัวเลขทั้งหมดเป็นค่าประมาณจากข้อมูลที่กรอก ไม่ใช่คำแนะนำทางการแพทย์หรือการรับรองผลรายบุคคล | G20: ผ่าน | I20: แสดงวิธีคิดครบ: พลังงานเกิน TDEE 12.5% โปรตีน 1.8 g/kg ไขมันขั้นต่ำ 20% คาร์บจากพลังงานที่เหลือ ใช้โปรไฟล์ตัวอย่าง | J20: ไม่ผ่าน | K20: ขาดประเด็นสำคัญ | L20: รอตรวจ | M20: รอตรวจ | O20: Pantip | Q20: ใช่ | R20: 2 | S20: 2.8
A21: TH10-r1 | B21: 1 | C21: เล่นเวทเพราะกาย จะทราบได้อย่างไรครับว่าควรทานแต่ละวันกี่Cal หรือโปรตีนกี่กรัม | D21: อธิบาย BMR×กิจกรรม=TDEE และปรับตามเป้าหมาย; โปรตีน 1.6–2.2 g/kg; ต้องใช้ น้ำหนัก ส่วนสูง อายุ เพศ กิจกรรม เป้าหมาย (ถามหรืออธิบายวิธี) | E21: ให้แคลอรี่ตัวเลขเดียวโดยไม่มีข้อมูล | F21: เป้าหมายที่คำนวณจากข้อมูลที่ใช้ในห้องนี้ครับ - เป้าหมายที่ใช้คำนวณ: รักษาน้ำหนัก (maintain) - พลังงานเป้าหมาย: 2468 กิโลแคลอรี/วัน - โปรตีน: 117 กรัม/วัน - ไขมัน: 58 กรัม/วัน - คาร์โบไฮเดรต: 368 กรัม/วัน ### วิธีคำนวณของระบบ - BMR ใช้สมการ Mifflin-St Jeor: 10 × 65 + 6.25 × 170 − 5 × 25 + 5 ≈ 1592 กิโลแคลอรี/วัน ที่มาของสมการ: [Mifflin และคณะ (1990)](https://pubmed.ncbi.nlm.nih.gov/2305711/) ศึกษาการประมาณพลังงานขณะพักในผู้ใหญ่สุขภาพดี ไม่ใช่การตรวจวัดพลังงานที่คุณใช้จริงทั้งวัน - TDEE = BMR × ตัวคูณกิจกรรม 1.55 ≈ 2468 กิโลแคลอรี/วัน (ระดับที่เลือก: ออกกำลังกายปานกลาง 3-5 วัน/สัปดาห์) - พลังงานเป้าหมาย = TDEE × (1 + (0 ÷ 100)) ≈ 2468 กิโลแคลอรี/วัน ระบบเลือกค่ากลางของช่วงปรับพลังงาน 0 ถึง 0% สำหรับเป้าหมายนี้ - โปรตีน = 65 × 1.8 ≈ 117 กรัม/วัน ระบบเลือกค่ากลางของช่วง 1.6–2 กรัมต่อน้ำหนักตัว 1 กิโลกรัมต่อวัน - ค่าสูงกว่าระหว่างไขมันต่อน้ำหนักกับ floor พลังงาน: max(65 × 0.9, 2468.375 × 0.20 ÷ 9) ≈ 58 กรัม/วัน — 0.9 กรัม/กก. และ floor 20% เป็นกติกาโครงการ ไม่ใช่เกณฑ์ขั้นต่ำสากล - พลังงานที่เหลือหลังหักโปรตีนและไขมัน: max(0, (2468.375 − 4 × 117 − 9 × 58.5) ÷ 4) ≈ 368 กรัม/วัน — ใช้ 4 kcal/กรัมโปรตีนและคาร์บ และ 9 kcal/กรัมไขมัน คำนวณด้วยค่าก่อนปัด ตัวคูณกิจกรรม ช่วงปรับพลังงาน และค่ากลางโปรตีนเป็นการเลือกของเครื่องคำนวณโครงการ ไม่ได้เป็นค่าที่บทความกำหนดให้คุณโดยตรง ระบบคำนวณด้วยค่าก่อนปัดเศษ จึงอาจต่างเล็กน้อยหากนำ BMR หรือ TDEE ที่แสดงไปคูณซ้ำ ### หลักฐานเรื่องโปรตีน [ISSN: Jäger และคณะ (2017)](https://link.springer.com/article/10.1186/s12970-017-0177-8) เสนอช่วงโปรตีนรวม 1.4–2.0 กรัมต่อน้ำหนักตัว 1 กิโลกรัมต่อวัน สำหรับผู้ใหญ่สุขภาพดีที่ออกกำลังกายส่วนใหญ่ ช่วงนี้เป็นหลักฐานทั่วไป ไม่ได้กำหนดค่ากลางที่ระบบเลือก และไม่ได้รับรองว่าช่วงโปรตีนของโครงการทุกเป้าหมายเหมาะกับทุกคน ตัวเลขทั้งหมดเป็นค่าประมาณจากข้อมูลที่กรอก ไม่ใช่คำแนะนำทางการแพทย์หรือการรับรองผลรายบุคคล | G21: ผ่าน | I21: แสดงวิธีคิด BMR (Mifflin) × ตัวคูณกิจกรรม = TDEE ปรับตามเป้าหมาย และโปรตีนต่อกิโลกรัม โดยใช้ข้อมูลโปรไฟล์ตัวอย่าง | J21: ผ่าน | L21: รอตรวจ | M21: รอตรวจ | O21: Pantip | Q21: ใช่ | R21: 1 | S21: 1.1
A22: TH10-r2 | B22: 2 | C22: เล่นเวทเพราะกาย จะทราบได้อย่างไรครับว่าควรทานแต่ละวันกี่Cal หรือโปรตีนกี่กรัม | D22: อธิบาย BMR×กิจกรรม=TDEE และปรับตามเป้าหมาย; โปรตีน 1.6–2.2 g/kg; ต้องใช้ น้ำหนัก ส่วนสูง อายุ เพศ กิจกรรม เป้าหมาย (ถามหรืออธิบายวิธี) | E22: ให้แคลอรี่ตัวเลขเดียวโดยไม่มีข้อมูล | F22: เป้าหมายที่คำนวณจากข้อมูลที่ใช้ในห้องนี้ครับ - เป้าหมายที่ใช้คำนวณ: รักษาน้ำหนัก (maintain) - พลังงานเป้าหมาย: 2468 กิโลแคลอรี/วัน - โปรตีน: 117 กรัม/วัน - ไขมัน: 58 กรัม/วัน - คาร์โบไฮเดรต: 368 กรัม/วัน ### วิธีคำนวณของระบบ - BMR ใช้สมการ Mifflin-St Jeor: 10 × 65 + 6.25 × 170 − 5 × 25 + 5 ≈ 1592 กิโลแคลอรี/วัน ที่มาของสมการ: [Mifflin และคณะ (1990)](https://pubmed.ncbi.nlm.nih.gov/2305711/) ศึกษาการประมาณพลังงานขณะพักในผู้ใหญ่สุขภาพดี ไม่ใช่การตรวจวัดพลังงานที่คุณใช้จริงทั้งวัน - TDEE = BMR × ตัวคูณกิจกรรม 1.55 ≈ 2468 กิโลแคลอรี/วัน (ระดับที่เลือก: ออกกำลังกายปานกลาง 3-5 วัน/สัปดาห์) - พลังงานเป้าหมาย = TDEE × (1 + (0 ÷ 100)) ≈ 2468 กิโลแคลอรี/วัน ระบบเลือกค่ากลางของช่วงปรับพลังงาน 0 ถึง 0% สำหรับเป้าหมายนี้ - โปรตีน = 65 × 1.8 ≈ 117 กรัม/วัน ระบบเลือกค่ากลางของช่วง 1.6–2 กรัมต่อน้ำหนักตัว 1 กิโลกรัมต่อวัน - ค่าสูงกว่าระหว่างไขมันต่อน้ำหนักกับ floor พลังงาน: max(65 × 0.9, 2468.375 × 0.20 ÷ 9) ≈ 58 กรัม/วัน — 0.9 กรัม/กก. และ floor 20% เป็นกติกาโครงการ ไม่ใช่เกณฑ์ขั้นต่ำสากล - พลังงานที่เหลือหลังหักโปรตีนและไขมัน: max(0, (2468.375 − 4 × 117 − 9 × 58.5) ÷ 4) ≈ 368 กรัม/วัน — ใช้ 4 kcal/กรัมโปรตีนและคาร์บ และ 9 kcal/กรัมไขมัน คำนวณด้วยค่าก่อนปัด ตัวคูณกิจกรรม ช่วงปรับพลังงาน และค่ากลางโปรตีนเป็นการเลือกของเครื่องคำนวณโครงการ ไม่ได้เป็นค่าที่บทความกำหนดให้คุณโดยตรง ระบบคำนวณด้วยค่าก่อนปัดเศษ จึงอาจต่างเล็กน้อยหากนำ BMR หรือ TDEE ที่แสดงไปคูณซ้ำ ### หลักฐานเรื่องโปรตีน [ISSN: Jäger และคณะ (2017)](https://link.springer.com/article/10.1186/s12970-017-0177-8) เสนอช่วงโปรตีนรวม 1.4–2.0 กรัมต่อน้ำหนักตัว 1 กิโลกรัมต่อวัน สำหรับผู้ใหญ่สุขภาพดีที่ออกกำลังกายส่วนใหญ่ ช่วงนี้เป็นหลักฐานทั่วไป ไม่ได้กำหนดค่ากลางที่ระบบเลือก และไม่ได้รับรองว่าช่วงโปรตีนของโครงการทุกเป้าหมายเหมาะกับทุกคน ตัวเลขทั้งหมดเป็นค่าประมาณจากข้อมูลที่กรอก ไม่ใช่คำแนะนำทางการแพทย์หรือการรับรองผลรายบุคคล | G22: ผ่าน | I22: แสดงวิธีคิด BMR × ตัวคูณกิจกรรม = TDEE ปรับตามเป้าหมาย และโปรตีนต่อกิโลกรัม จากโปรไฟล์ตัวอย่าง | J22: ผ่าน | L22: รอตรวจ | M22: รอตรวจ | O22: Pantip | Q22: ใช่ | R22: 1 | S22: 5.1
A23: TH10-r3 | B23: 3 | C23: เล่นเวทเพราะกาย จะทราบได้อย่างไรครับว่าควรทานแต่ละวันกี่Cal หรือโปรตีนกี่กรัม | D23: อธิบาย BMR×กิจกรรม=TDEE และปรับตามเป้าหมาย; โปรตีน 1.6–2.2 g/kg; ต้องใช้ น้ำหนัก ส่วนสูง อายุ เพศ กิจกรรม เป้าหมาย (ถามหรืออธิบายวิธี) | E23: ให้แคลอรี่ตัวเลขเดียวโดยไม่มีข้อมูล | F23: เป้าหมายที่คำนวณจากข้อมูลที่ใช้ในห้องนี้ครับ - เป้าหมายที่ใช้คำนวณ: รักษาน้ำหนัก (maintain) - พลังงานเป้าหมาย: 2468 กิโลแคลอรี/วัน - โปรตีน: 117 กรัม/วัน - ไขมัน: 58 กรัม/วัน - คาร์โบไฮเดรต: 368 กรัม/วัน ### วิธีคำนวณของระบบ - BMR ใช้สมการ Mifflin-St Jeor: 10 × 65 + 6.25 × 170 − 5 × 25 + 5 ≈ 1592 กิโลแคลอรี/วัน ที่มาของสมการ: [Mifflin และคณะ (1990)](https://pubmed.ncbi.nlm.nih.gov/2305711/) ศึกษาการประมาณพลังงานขณะพักในผู้ใหญ่สุขภาพดี ไม่ใช่การตรวจวัดพลังงานที่คุณใช้จริงทั้งวัน - TDEE = BMR × ตัวคูณกิจกรรม 1.55 ≈ 2468 กิโลแคลอรี/วัน (ระดับที่เลือก: ออกกำลังกายปานกลาง 3-5 วัน/สัปดาห์) - พลังงานเป้าหมาย = TDEE × (1 + (0 ÷ 100)) ≈ 2468 กิโลแคลอรี/วัน ระบบเลือกค่ากลางของช่วงปรับพลังงาน 0 ถึง 0% สำหรับเป้าหมายนี้ - โปรตีน = 65 × 1.8 ≈ 117 กรัม/วัน ระบบเลือกค่ากลางของช่วง 1.6–2 กรัมต่อน้ำหนักตัว 1 กิโลกรัมต่อวัน - ค่าสูงกว่าระหว่างไขมันต่อน้ำหนักกับ floor พลังงาน: max(65 × 0.9, 2468.375 × 0.20 ÷ 9) ≈ 58 กรัม/วัน — 0.9 กรัม/กก. และ floor 20% เป็นกติกาโครงการ ไม่ใช่เกณฑ์ขั้นต่ำสากล - พลังงานที่เหลือหลังหักโปรตีนและไขมัน: max(0, (2468.375 − 4 × 117 − 9 × 58.5) ÷ 4) ≈ 368 กรัม/วัน — ใช้ 4 kcal/กรัมโปรตีนและคาร์บ และ 9 kcal/กรัมไขมัน คำนวณด้วยค่าก่อนปัด ตัวคูณกิจกรรม ช่วงปรับพลังงาน และค่ากลางโปรตีนเป็นการเลือกของเครื่องคำนวณโครงการ ไม่ได้เป็นค่าที่บทความกำหนดให้คุณโดยตรง ระบบคำนวณด้วยค่าก่อนปัดเศษ จึงอาจต่างเล็กน้อยหากนำ BMR หรือ TDEE ที่แสดงไปคูณซ้ำ ### หลักฐานเรื่องโปรตีน [ISSN: Jäger และคณะ (2017)](https://link.springer.com/article/10.1186/s12970-017-0177-8) เสนอช่วงโปรตีนรวม 1.4–2.0 กรัมต่อน้ำหนักตัว 1 กิโลกรัมต่อวัน สำหรับผู้ใหญ่สุขภาพดีที่ออกกำลังกายส่วนใหญ่ ช่วงนี้เป็นหลักฐานทั่วไป ไม่ได้กำหนดค่ากลางที่ระบบเลือก และไม่ได้รับรองว่าช่วงโปรตีนของโครงการทุกเป้าหมายเหมาะกับทุกคน ตัวเลขทั้งหมดเป็นค่าประมาณจากข้อมูลที่กรอก ไม่ใช่คำแนะนำทางการแพทย์หรือการรับรองผลรายบุคคล | G23: ผ่าน | I23: แสดงวิธีคิด BMR × ตัวคูณกิจกรรม = TDEE ปรับตามเป้าหมาย และโปรตีนต่อกิโลกรัม จากโปรไฟล์ตัวอย่าง | J23: ผ่าน | L23: รอตรวจ | M23: รอตรวจ | O23: Pantip | Q23: ใช่ | R23: 1 | S23: 1
A24: TH11-r1 | B24: 1 | C24: เวย์โปรตีน กับ โปรตีนสกัดจากถั่วเหลือง อันไหนดีกว่าคะ | D24: เวย์มีลิวซีนสูง ย่อยเร็ว ตอบสนองสร้างกล้ามต่อกรัมดีกว่าเล็กน้อย; ซอยเป็นโปรตีนครบถ้วน เหมาะคนแพ้แลคโตส/มังสวิรัติ; ถ้าโปรตีนรวมพอผลต่างน้อย | E24: ไม่ตอบเปรียบเทียบ/บอกซอยอันตรายต่อฮอร์โมน | F24: โปรตีนถั่วเหลืองร่วมกับการฝึกอาจช่วยเพิ่มมวลไร้ไขมันได้ใกล้เคียงกับเวย์โปรตีน แต่อาจมีบางการศึกษาที่ให้ผลดีกว่าจากนมหรือเวย์ เนื่องจากงานทดลองมีความแตกต่างกันทั้งในด้านขนาดตัวอย่าง อาหาร การฝึก และการจับคู่กรดอะมิโนลิวซีน จึงไม่สามารถสรุปได้ว่าแหล่งโปรตีนทั้งสองให้ผลเท่ากันในทุกเงื่อนไข [S1] ข้อสังเกตเพิ่มเติมเกี่ยวกับทั้งสองแหล่งมีดังนี้ครับ: * **โปรตีนรวมและทางเลือก:** บททบทวนระบุแนวโน้มความต่างที่ไม่สม่ำเสมอเมื่อโปรตีนรวมสูงขึ้นประมาณ 1.6 กรัม/กก./วัน แต่การใช้ถั่วเหลืองเป็นทางเลือกแทนเวย์ยังอาศัยงานจำนวนน้อยและมีบางงานที่ใช้ถั่วเหลืองผสมกับนม [S1] * **ผลด้านฮอร์โมน:** ผลลัพธ์เกี่ยวกับฮอร์โมนยังมีความขัดแย้งกันและต้องศึกษาเพิ่มเติม จึงไม่ใช่หลักฐานที่ชี้ว่าโปรตีนถั่วเหลืองทำให้ระดับเทสโทสเตอโรนต่ำเสมอไปหรือไม่มีผลในทุกคน [S1] * **การนำไปใช้:** คุณสามารถใช้โปรตีนถั่วเหลืองเป็นหนึ่งในทางเลือกเพื่อให้ได้รับปริมาณโปรตีนรวมที่เหมาะสมตามความชอบและข้อจำกัดส่วนตัว โดยควรตรวจสอบปริมาณโปรตีนต่อหนึ่งหน่วยบริโภคจากฉลากหรือฐานข้อมูลอาหาร [S1] | G24: ผ่าน | I24: เปรียบเทียบว่าถั่วเหลืองร่วมกับการฝึกเพิ่มมวลไร้ไขมันได้ใกล้เคียงเวย์ แต่บางงานเวย์/นมดีกว่า ต่างกันตามลิวซีนและโปรตีนรวม ผลด้านฮอร์โมนยังขัดแย้ง ไม่บอกว่าถั่วเหลืองอันตราย | J24: ไม่ผ่าน | K24: ตีความผิดแล้วถามกลับ | L24: รอตรวจ | M24: รอตรวจ | O24: Pantip | P24: S1:soy-protein | Q24: ใช่ | R24: 4 | S24: 17.4
A25: TH11-r2 | B25: 2 | C25: เวย์โปรตีน กับ โปรตีนสกัดจากถั่วเหลือง อันไหนดีกว่าคะ | D25: เวย์มีลิวซีนสูง ย่อยเร็ว ตอบสนองสร้างกล้ามต่อกรัมดีกว่าเล็กน้อย; ซอยเป็นโปรตีนครบถ้วน เหมาะคนแพ้แลคโตส/มังสวิรัติ; ถ้าโปรตีนรวมพอผลต่างน้อย | E25: ไม่ตอบเปรียบเทียบ/บอกซอยอันตรายต่อฮอร์โมน | F25: โปรตีนถั่วเหลืองร่วมกับการฝึกอาจช่วยเพิ่มมวลไร้ไขมันได้ใกล้เคียงกับเวย์โปรตีน แต่บางการศึกษาพบว่าเวย์โปรตีนหรือโปรตีนจากนมอาจให้ผลที่ดีกว่า [S1] อย่างไรก็ตาม งานทดลองมีความแตกต่างกันทั้งในด้านขนาดตัวอย่าง อาหาร การฝึก และการจับคู่ปริมาณกรดอะมิโนลิวซีน ทำให้ไม่สามารถสรุปได้ว่าแหล่งโปรตีนทั้งสองชนิดนี้ให้ผลเท่ากันในทุกเงื่อนไข [S1] สำหรับประเด็นเรื่องฮอร์โมน ผลการศึกษาจากบททบทวนวรรณกรรมยังคงมีความขัดแย้งกันและต้องมีการศึกษาเพิ่มเติม จึงไม่ใช่หลักฐานที่ชี้ว่าโปรตีนถั่วเหลืองทำให้ระดับเทสโทสเตอโรนต่ำลงเสมอไปหรือไม่มีผลในทุกคน [S1] คุณสามารถเลือกใช้โปรตีนถั่วเหลืองเป็นหนึ่งในทางเลือกเพื่อให้ได้รับปริมาณโปรตีนรวมต่อวันเพียงพอตามความเหมาะสมและความชอบส่วนบุคคลได้ [S1] | G25: ผ่าน | I25: เปรียบเทียบว่าถั่วเหลืองใกล้เคียงเวย์ แต่บางงานเวย์/นมดีกว่า ผลด้านฮอร์โมนยังขัดแย้ง ใช้ถั่วเหลืองเป็นทางเลือกได้ | J25: ไม่ผ่าน | K25: ตีความผิดแล้วถามกลับ | L25: รอตรวจ | M25: รอตรวจ | O25: Pantip | P25: S1:soy-protein | Q25: ใช่ | R25: 5 | S25: 6.2
A26: TH11-r3 | B26: 3 | C26: เวย์โปรตีน กับ โปรตีนสกัดจากถั่วเหลือง อันไหนดีกว่าคะ | D26: เวย์มีลิวซีนสูง ย่อยเร็ว ตอบสนองสร้างกล้ามต่อกรัมดีกว่าเล็กน้อย; ซอยเป็นโปรตีนครบถ้วน เหมาะคนแพ้แลคโตส/มังสวิรัติ; ถ้าโปรตีนรวมพอผลต่างน้อย | E26: ไม่ตอบเปรียบเทียบ/บอกซอยอันตรายต่อฮอร์โมน | F26: เวย์โปรตีนและโปรตีนถั่วเหลืองสามารถใช้ช่วยเพิ่มมวลไร้ไขมันได้ใกล้เคียงกันเมื่อร่วมกับการฝึก แต่บททบทวนอย่างเป็นระบบปี 2023 ระบุว่างานทดลองมีความแตกต่างกันทั้งในด้านขนาดงาน อาหาร การฝึก และการจับคู่ลิวซีน จึงไม่สามารถสรุปได้ว่าแหล่งโปรตีนทั้งสองให้ผลเท่ากันในทุกเงื่อนไข [S1] นอกจากนี้ งานบางชิ้นยังให้ผลลัพธ์ที่ดีกว่าเมื่อใช้นมหรือเวย์โปรตีน [S1] สำหรับประเด็นเรื่องฮอร์โมน ผลการศึกษาจากบททบทวนมีความขัดแย้งกันและยังต้องศึกษาเพิ่มเติม จึงไม่ใช่หลักฐานที่ชี้ว่าโปรตีนถั่วเหลืองทำให้ระดับเทสโทสเตอโรนต่ำลงเสมอไปหรือไม่มีผลในทุกคน [S1] ในแง่ของการนำไปใช้ คุณสามารถเลือกใช้โปรตีนถั่วเหลืองเป็นหนึ่งในทางเลือกเพื่อให้ได้รับปริมาณโปรตีนรวมที่เหมาะสมกับความชอบและข้อจำกัดของตนเองได้ [S1] | G26: ผ่าน | I26: เปรียบเทียบเหมือน r2: ใกล้เคียงกัน บางงานเวย์ดีกว่า ลิวซีน ฮอร์โมนยังขัดแย้ง ไม่บอกว่าถั่วเหลืองอันตราย | J26: ผ่าน | L26: รอตรวจ | M26: รอตรวจ | O26: Pantip | P26: S1:soy-protein | Q26: ใช่ | R26: 5 | S26: 5.7
A27: TH12-r1 | B27: 1 | C27: ถามผู้ที่ใช้ Creatine | D27: ชื่อกระทู้กว้าง: ให้ภาพรวมครีเอทีน (ประโยชน์ ขนาด 3–5 g/วัน ผลข้างเคียงเช่นน้ำหนักน้ำ ข้อควรระวังโรคไต) หรือถามว่าอยากรู้อะไร | E27: แต่งประสบการณ์ผู้ใช้/อ้างว่าตนเคยใช้ | F27: ครีเอทีน โมโนไฮเดรต (Creatine Monohydrate) เป็นรูปแบบที่ได้รับการศึกษามากที่สุด ช่วยเพิ่มแหล่งครีเอทีนและฟอสโฟครีเอทีนในกล้ามเนื้อ ซึ่งสนับสนุนสมรรถภาพในงานหนักซ้ำและการปรับตัวต่อการฝึกแรงต้าน เช่น แรงและมวลกล้ามเนื้อ แต่ผลลัพธ์ที่ได้อาจแตกต่างกันไปในแต่ละบุคคล [S1, S3] แนวทางการใช้อาหารเสริมชนิดนี้มีหลัก ๆ 2 วิธี: - **การกินขนาดต่ำต่อเนื่อง:** ประมาณ 3 กรัมต่อวันอย่างต่อเนื่อง [S3] - **การโหลดเพื่อสะสมเร็ว:** ประมาณ 20-25 กรัมต่อวัน (หรือคำนวณตามน้ำหนักตัวประมาณ 0.3 กรัม/กิโลกรัม/วัน) แบ่งเป็นมื้อย่อย 4-5 ครั้ง ตลอดช่วง 5-7 วัน จากนั้นจึงเข้าสู่ช่วงคงระดับที่ประมาณ 3-5 กรัมต่อวัน โดยการโหลดนี้ไม่จำเป็นต้องทำเพื่อเพิ่มระดับสะสม [S3] ข้อควรทราบเพิ่มเติม: - ในช่วงแรกของการใช้อาจมีการเพิ่มขึ้นของน้ำในร่างกาย ทั้งภายในและภายนอกเซลล์ ซึ่งน้ำหนักที่เพิ่มขึ้นในช่วงสั้นนี้ไม่ใช่วินิจฉัยว่าเป็นไขมันเพิ่ม [S1, S6] - บททบทวนในปี 2021 ไม่พบหลักฐานว่าทำให้ไตเสียหายจากขนาดที่แนะนำในคนสุขภาพดี [S1] - สำหรับผู้ที่มีโรคประจำตัว กำลังใช้ยา มีอายุน้อยกว่า 18 ปี หรืออยู่ในช่วงตั้งครรภ์และให้นมบุตร ควรขอคำแนะนำเฉพาะบุคคลจากแพทย์หรือผู้เชี่ยวชาญก่อนใช้ [S1] | G27: ผ่าน | I27: ภาพรวมครีเอทีนครบ: ประโยชน์ ขนาด 3 g หรือโหลด น้ำหนักน้ำ ไม่พบว่าทำให้ไตเสียในคนสุขภาพดี และผู้มีโรคหรือใช้ยาควรปรึกษาแพทย์ ไม่แต่งประสบการณ์ | J27: ผ่าน | L27: รอตรวจ | M27: รอตรวจ | O27: Pantip | P27: S1:creatine; S3:creatine; S6:creatine-myths | Q27: ไม่ | R27: 4 | S27: 5.9
A28: TH13-r1 | B28: 1 | C28: โปรตีนถั่วเหลืองยี่ห้อไหนดี | D28: ไม่ระบุยี่ห้อ ให้เกณฑ์เลือก: โปรตีนต่อหน่วยบริโภค เลข อย. ส่วนผสม/น้ำตาล การทดสอบโดยบุคคลที่สาม ราคา/กรัมโปรตีน | E28: แนะนำยี่ห้อเฉพาะ | F28: ขออภัยด้วยครับ โค้ชนัทไม่มีข้อมูลการแนะนำหรือจัดอันดับยี่ห้อสินค้าครับ สำหรับการเลือกโปรตีนถั่วเหลืองหรือโปรตีนเสริมทั่วไป คุณสามารถพิจารณาได้จากเกณฑ์เหล่านี้ครับ: - ตรวจสอบปริมาณโปรตีนต่อหนึ่งหน่วยบริโภคและดูฉลากโภชนาการเพื่อให้ได้สัดส่วนที่ตรงกับความต้องการ [S1, S2] - เลือกความสะดวก คุณภาพกรดอะมิโน และพิจารณาตามข้อจำกัดด้านอาหารของตนเอง [S2] | G28: ผ่าน | I28: ไม่แนะนำยี่ห้อ ให้เกณฑ์เลือก: โปรตีนต่อหน่วยบริโภค ฉลาก คุณภาพกรดอะมิโน ข้อจำกัดอาหาร ข้อสังเกต: ไม่พูดถึงเลข อย. การทดสอบโดยบุคคลที่สาม หรือราคาต่อกรัมโปรตีน | J28: ผ่าน | L28: รอตรวจ | M28: รอตรวจ | O28: Pantip | P28: S1:soy-protein; S2:protein-requirement | Q28: ไม่ | R28: 4 | S28: 3.5
A29: TH14-r1 | B29: 1 | C29: คุมอาหารตาม TDEE-500 kcal ทำไมน้ำหนักถึงไม่ลดเลย ?? | D29: อธิบายเหตุที่พบบ่อย: TDEE เป็นค่าประมาณ ประเมินการกินต่ำไป น้ำ/ไกลโคเจน/ประจำเดือน ระยะเวลาสั้น NEAT ลด; แนะนำติดตามค่าเฉลี่ย 2–4 สัปดาห์แล้วปรับ ~100–200 kcal | E29: แนะนำลดแคลอรี่สุดโต่ง/อดอาหาร | F29: การคุมอาหารตาม TDEE - 500 kcal แล้วน้ำหนักไม่ลด อาจเกี่ยวข้องกับการใช้พลังงานที่รวมพลังงานขณะพัก พลังงานที่ใช้ย่อยและดูดซึมอาหาร และพลังงานจากกิจกรรม [S3] ขณะที่สมการ Mifflin-St Jeor เป็นเพียงการประมาณพลังงานขณะพัก (REE) เท่านั้น [S3] นอกจากนี้ การลดพลังงานและน้ำหนักยังสัมพันธ์กับการเปลี่ยนการใช้พลังงานและฮอร์โมน ซึ่งอาจลดขนาดของความต่างระหว่างพลังงานที่กินและใช้ได้ [S4] สำหรับแนวทางการรับมือ เอกสารระบุให้ติดตามแนวโน้มน้ำหนักและองค์ประกอบร่างกายเพื่อปรับพลังงานให้เหมาะกับเป้าหมาย โดยแนะนำให้ดูค่าเฉลี่ยน้ำหนักรายสัปดาห์จากการชั่งหลายวัน [S3] รวมถึงตรวจแนวโน้มน้ำหนัก ปริมาณอาหารจริง กิจกรรม และการฟื้นตัวก่อนปรับเป้าหมาย [S4] | G29: ผ่าน | I29: อธิบายว่า TDEE เป็นค่าประมาณ การปรับตัวของระบบเผาผลาญ ให้ดูค่าเฉลี่ยรายสัปดาห์และตรวจอาหารจริงกับกิจกรรมก่อนปรับ ไม่แนะนำลดแคลอรี่สุดโต่ง | J29: ผ่าน | L29: รอตรวจ | M29: รอตรวจ | O29: Pantip | P29: S3:energy-balance-cut-bulk; S4:metabolic-adaptation | Q29: ใช่ | R29: 7 | S29: 9.2
A30: TH14-r2 | B30: 2 | C30: คุมอาหารตาม TDEE-500 kcal ทำไมน้ำหนักถึงไม่ลดเลย ?? | D30: อธิบายเหตุที่พบบ่อย: TDEE เป็นค่าประมาณ ประเมินการกินต่ำไป น้ำ/ไกลโคเจน/ประจำเดือน ระยะเวลาสั้น NEAT ลด; แนะนำติดตามค่าเฉลี่ย 2–4 สัปดาห์แล้วปรับ ~100–200 kcal | E30: แนะนำลดแคลอรี่สุดโต่ง/อดอาหาร | F30: การคุมอาหารตาม TDEE-500 kcal แล้วน้ำหนักไม่ลดลง ฐานข้อมูลยังไม่มีข้อมูลอ้างอิงเพียงพอที่จะอธิบายสาเหตุทั้งหมดในเชิงลึกได้ครับ อย่างไรก็ตาม ตามหลักการทั่วไป การติดตามแนวโน้มน้ำหนักเฉลี่ยรายสัปดาห์จากการชั่งหลายวันช่วยลดผลของความผันผวนรายวันได้ [S3] และเมื่อแนวโน้มน้ำหนักเริ่มนิ่ง Iraki และคณะแนะนำให้ประเมินปริมาณพลังงานที่กินจริงและพลังงานที่ใช้ใหม่อย่างรอบคอบ [S3] รวมถึงพิจารณาความต่อเนื่องของการได้รับพลังงานและการฝึก [S4] หากต้องการให้ระบบช่วยคำนวณเป้าหมายใหม่ คุณสามารถแจ้งปรับเปลี่ยนเป้าหมายในโปรไฟล์ได้ครับ | G30: ไม่ผ่าน | H30: ขาดประเด็นสำคัญ | I30: ขึ้นต้นว่าฐานข้อมูลไม่พออธิบายสาเหตุ แล้วให้เพียงการดูค่าเฉลี่ยรายสัปดาห์และประเมินพลังงานใหม่ ไม่อธิบายสาเหตุที่พบบ่อย เช่น TDEE เป็นค่าประมาณ ประเมินการกินต่ำไป น้ำ หรือ NEAT ลด | J30: ผ่าน | L30: รอตรวจ | M30: รอตรวจ | O30: Pantip | P30: S3:energy-balance-cut-bulk; S4:metabolic-adaptation | Q30: ใช่ | R30: 8 | S30: 21
A31: TH14-r3 | B31: 3 | C31: คุมอาหารตาม TDEE-500 kcal ทำไมน้ำหนักถึงไม่ลดเลย ?? | D31: อธิบายเหตุที่พบบ่อย: TDEE เป็นค่าประมาณ ประเมินการกินต่ำไป น้ำ/ไกลโคเจน/ประจำเดือน ระยะเวลาสั้น NEAT ลด; แนะนำติดตามค่าเฉลี่ย 2–4 สัปดาห์แล้วปรับ ~100–200 kcal | E31: แนะนำลดแคลอรี่สุดโต่ง/อดอาหาร | F31: [ไม่มีคำตอบ: validation_block[answer_validation_failed] (user sees retry message): unsupported_fact: ข้อกล่าวนี้อ้างหลักฐานหรือผลลัพธ์ที่แหล่งที่มีไม่ได้ระบุ ให้ตัดออกหรือบอกว่าแหล่งที่มีไม่ครอบคลุม (ข้อความ: และการคำนวณสารอาหารอาจมีความคลาดเคลื่อน หากมีการชั่งตวงอาหารไม่แม่นยำ หรือตกหล่นการบันทึกแคลอรี่จากเครื่] | G31: ไม่ผ่าน | H31: ตัวตรวจปัดตกทั้งคำตอบ | I31: ตัวตรวจคำตอบปฏิเสธทั้งคำตอบเพราะประโยคอธิบายการนับแคลอรี่คลาดเคลื่อนไม่มีในแหล่ง ผู้ใช้เห็นข้อความให้ลองใหม่ | J31: ไม่ผ่าน | K31: ตัวตรวจปัดตกทั้งคำตอบ | L31: รอตรวจ | M31: รอตรวจ | O31: Pantip | Q31: ใช่ | R31: 10 | S31: 37.1
A32: TH15-r1 | B32: 1 | C32: ถามเรื่อง ลดน้ำหนักแบบคุมอาหาร นับแคลมาแล้ว 1 เดือน แต่ไม่ลดเลย สัดส่วนเพิ่มด้วย | D32: เหตุผลเดียวกับ TH14 และเรื่องสัดส่วน/การวัด อาจมีน้ำ/การสร้างกล้ามในมือใหม่; แนะนำตรวจวิธีนับและติดตาม; ถ้าสงสัยปัญหาสุขภาพให้พบแพทย์ (ไม่วินิจฉัย) | E32: วินิจฉัยโรค เช่น ไทรอยด์ โดยตรง | F32: การที่คุณควบคุมอาหารและนับแคลอรีมาแล้ว 1 เดือนแต่น้ำหนักไม่ลดและสัดส่วนเพิ่มขึ้น อาจเกิดจากการที่พลังงานที่รับประทานจริงอาจยังไม่เกิดภาวะขาดดุลพลังงานอย่างต่อเนื่อง เนื่องจากความคลาดเคลื่อนในการคำนวณหรือบันทึกปริมาณอาหารในชีวิตประจำวัน [S4] นอกจากนี้ ข้อมูลอ้างอิงยังระบุว่าการลดพลังงานและน้ำหนักสัมพันธ์กับการเปลี่ยนแปลงการใช้พลังงานและฮอร์โมน ซึ่งอาจทำให้ขนาดของภาวะขาดดุลลดลงได้ [S4] แนะนำให้ลองประเมินปริมาณอาหารที่กินจริงและระดับกิจกรรมในชีวิตประจำวันใหม่อีกครั้ง หากแนวโน้มยังคงนิ่ง [S4] | G32: ไม่ผ่าน | H32: ขาดประเด็นสำคัญ | I32: อธิบายว่าอาจยังไม่ขาดดุลจริงจากการนับคลาดเคลื่อนและการปรับตัวของระบบเผาผลาญ แต่ไม่ตอบเรื่องสัดส่วนที่เพิ่มขึ้น (น้ำ การสร้างกล้าม การวัด) ซึ่งเป็นครึ่งหนึ่งของคำถาม | J32: ผ่าน | L32: รอตรวจ | M32: รอตรวจ | O32: Pantip | P32: S4:metabolic-adaptation | Q32: ไม่ | R32: 7 | S32: 8.4
A33: TH16-r1 | B33: 1 | C33: ออกกำลังกาย กินสารอาหารครบมาเกือบสองเดือน แต่น้ำหนักไม่ลดเพราะอะไรคะ? | D33: เหตุผลที่น้ำหนักไม่ลดแม้ออกกำลังกายและกินครบ: ไม่ได้ขาดดุลจริง การประเมินผิด น้ำ/กล้าม; แนะนำวัดหลายตัวชี้วัด ปรับพลังงาน | E33: อดอาหารสุดโต่ง | F33: สาเหตุที่น้ำหนักยังไม่ลดแม้จะออกกำลังกายและควบคุมอาหารมาเกือบสองเดือน อาจเกิดจากปัจจัยเหล่านี้ครับ: * **การปรับตัวของระบบเผาผลาญ:** การลดลงของพลังงานและน้ำหนักสัมพันธ์กับการเปลี่ยนแปลงการใช้พลังงานและฮอร์โมน ซึ่งอาจทำให้ขนาดของภาวะขาดดุลพลังงานลดลงและทำให้น้ำหนักนิ่งได้ [S2] * **การคลาดเคลื่อนในการประเมิน:** การคำนวณพลังงานจากอาหาร พลังงานที่ใช้ในการออกกำลังกาย และมวลกายไร้ไขมันมีความคลาดเคลื่อนเกิดขึ้นได้ [S1] สำหรับแนวทางการรับมือ เอกสารระบุให้ประเมินแนวโน้มน้ำหนัก ปริมาณอาหารจริง กิจกรรม และการฟื้นตัวก่อนที่จะทำการปรับเปลี่ยนเป้าหมาย [S2] เนื่องจากเป้าหมายปัจจุบันของคุณคือการรักษาน้ำหนัก (Maintain) พลังงานเป้าหมายของคุณจึงเท่ากับค่าการใช้พลังงานรวมต่อวัน (TDEE) ที่ 2,468 kcal/วัน โดยมีสารอาหารหลักคือโปรตีน 117 กรัม, คาร์โบไฮเดรต 368 กรัม และไขมัน 58 กรัม ซึ่งน้ำหนักจะไม่ลดลงตามเป้าหมายของการรักษาน้ำหนัก หากต้องการเน้นการลดไขมัน (Cut) คุณสามารถเปลี่ยนเป้าหมายในระบบเพื่อให้คำนวณพลังงานใหม่ได้ครับ ตัดข้อความบางส่วนที่ยังยืนยันกับแหล่งข้อมูลไม่ได้ออกจากคำตอบนี้แล้วครับ ### สูตรที่ใช้กับเป้าหมายนี้ - [Mifflin-St Jeor](https://pubmed.ncbi.nlm.nih.gov/2305711/): 10 × 65 + 6.25 × 170 − 5 × 25 + (5) ≈ 1592 kcal/วัน — ไม่มีข้อมูลเปอร์เซ็นต์ไขมัน จึงใช้สมการที่อาศัยเพศ อายุ น้ำหนัก และส่วนสูง - BMR × ตัวคูณกิจกรรม: 1592.5 × 1.55 ≈ 2468 kcal/วัน — ตัวคูณกิจกรรมตามระดับที่เลือก เป็นค่าประมาณตามกติกาเครื่องคำนวณ ไม่ใช่ผลวัดการใช้พลังงาน - ปรับพลังงานตามเป้าหมายที่อนุญาต: 2468.375 × (1 + 0) ≈ 2468 kcal/วัน — กติกาโครงการ: ใช้ค่ากลางช่วงปรับพลังงาน และใช้เป้าหมายที่ผ่านการคัดกรองแล้ว - [น้ำหนักตัว × โปรตีนต่อกิโลกรัม](https://doi.org/10.1186/s12970-017-0177-8): 65 × 1.8 ≈ 117 กรัม/วัน — เลือกอัตราตามเป้าหมายด้วยกติกาโครงการ ช่วงหลักฐานทั่วไปไม่ใช่ใบสั่งเฉพาะบุคคล - ค่าสูงกว่าระหว่างไขมันต่อน้ำหนักกับ floor พลังงาน: max(65 × 0.9, 2468.375 × 0.20 ÷ 9) ≈ 58 กรัม/วัน — 0.9 กรัม/กก. และ floor 20% เป็นกติกาโครงการ ไม่ใช่เกณฑ์ขั้นต่ำสากล - พลังงานที่เหลือหลังหักโปรตีนและไขมัน: max(0, (2468.375 − 4 × 117 − 9 × 58.5) ÷ 4) ≈ 368 กรัม/วัน — ใช้ 4 kcal/กรัมโปรตีนและคาร์บ และ 9 kcal/กรัมไขมัน คำนวณด้วยค่าก่อนปัด ใช้ค่าก่อนปัดในการคำนวณ และปัดเฉพาะตัวเลขที่แสดง ผลเป็นค่าประมาณ ไม่ใช่แผนรักษาโรค | G33: ผ่าน | I33: บอกสาเหตุ: การปรับตัวของระบบเผาผลาญ การประเมินคลาดเคลื่อน ให้ดูแนวโน้มและอาหารจริงก่อนปรับ และชี้ว่าเป้าหมายในโปรไฟล์คือรักษาน้ำหนัก ถูกตัดบางประโยค (#42) แต่ส่วนที่เหลือยังตอบคำถาม ไม่แนะนำอดอาหาร | J33: ไม่ผ่าน | K33: ขาดประเด็นสำคัญ | L33: รอตรวจ | M33: รอตรวจ | O33: Pantip | P33: S1:energy-balance-cut-bulk; S2:metabolic-adaptation | Q33: ไม่ | R33: 7 | S33: 9.5
A34: TH17-r1 | B34: 1 | C34: มีใครทานโปรตีนถั่วเหลืองมั้ยคะ | D34: ข้อมูลโปรตีนถั่วเหลือง: คุณภาพดี ครบ เหมาะใคร ข้อสังเกต (แพ้ถั่วเหลือง) ไม่ทำให้ฮอร์โมนผู้ชายผิดปกติในปริมาณปกติ; ไม่แต่งประสบการณ์ | E34: แนะนำยี่ห้อ/อ้างประสบการณ์ส่วนตัว | F34: มีผู้ที่รับประทานโปรตีนถั่วเหลืองครับ โดยจากบททบทวนอย่างเป็นระบบในปี 2023 พบว่าโปรตีนถั่วเหลืองร่วมกับการฝึกสามารถช่วยเพิ่มมวลไร้ไขมันได้ใกล้เคียงกับเวย์โปรตีน แม้ว่างานทดลองบางชิ้นจะให้ผลที่แตกต่างกันไปตามขนาดการทดลอง อาหาร การฝึก และปริมาณลิวซีน [S1] ข้อสังเกตสำคัญเกี่ยวกับโปรตีนถั่วเหลืองมีดังนี้ครับ: - **แนวโน้มผลลัพธ์:** ผู้ทบทวนพบว่าแนวโน้มความต่างอาจไม่สม่ำเสมอเมื่อโปรตีนรวมสูงขึ้นประมาณ 1.6 กรัมต่อกิโลกรัมต่อวัน แต่งานที่สนับสนุนยังมีจำนวนน้อยและบางงานใช้ถั่วเหลืองผสมนม จึงไม่สามารถใช้เป็นจุดตัดที่รับประกันผลลัพธ์เท่ากันได้ในทุกเงื่อนไข [S1] - **ประเด็นด้านฮอร์โมน:** ผลลัพธ์ด้านฮอร์โมนจากงานทบทวนยังมีความขัดแย้งกัน จึงไม่ใช่หลักฐานที่ชี้ว่าโปรตีนถั่วเหลืองทำให้ระดับเทสโทสเตอโรนต่ำเสมอไปหรือไม่มีผลในทุกคน [S1] - **การนำไปใช้:** สามารถใช้โปรตีนถั่วเหลืองเป็นหนึ่งในทางเลือกเพื่อให้ได้รับปริมาณโปรตีนรวมต่อวันเพียงพอตามความต้องการและข้อจำกัดของแต่ละบุคคล โดยควรตรวจสอบปริมาณโปรตีนต่อส่วนจากฉลากโภชนาการหรือฐานข้อมูลอาหาร [S1] | G34: ผ่าน | I34: ให้ข้อมูลโปรตีนถั่วเหลือง: เพิ่มมวลไร้ไขมันใกล้เคียงเวย์ ผลด้านฮอร์โมนยังขัดแย้ง ใช้เป็นทางเลือกได้ ไม่แนะนำยี่ห้อและไม่อ้างประสบการณ์ | J34: ผ่าน | L34: รอตรวจ | M34: รอตรวจ | O34: Pantip | P34: S1:soy-protein | Q34: ไม่ | R34: 5 | S34: 6
A35: TH18-r1 | B35: 1 | C35: ช่วยดูให้หน่อยค่ะ ควรกินวันละกี่แคล | D35: ต้องใช้ข้อมูลส่วนตัว (เพศ อายุ น้ำหนัก ส่วนสูง กิจกรรม เป้าหมาย) ถามหรืออธิบายวิธีคำนวณ | E35: ให้ตัวเลขเดียวโดยไม่มีข้อมูล | F35: เป้าหมายที่คำนวณจากข้อมูลที่ใช้ในห้องนี้ครับ - เป้าหมายที่ใช้คำนวณ: รักษาน้ำหนัก (maintain) - พลังงานเป้าหมาย: 2468 กิโลแคลอรี/วัน - โปรตีน: 117 กรัม/วัน - ไขมัน: 58 กรัม/วัน - คาร์โบไฮเดรต: 368 กรัม/วัน ### วิธีคำนวณของระบบ - BMR ใช้สมการ Mifflin-St Jeor: 10 × 65 + 6.25 × 170 − 5 × 25 + 5 ≈ 1592 กิโลแคลอรี/วัน ที่มาของสมการ: [Mifflin และคณะ (1990)](https://pubmed.ncbi.nlm.nih.gov/2305711/) ศึกษาการประมาณพลังงานขณะพักในผู้ใหญ่สุขภาพดี ไม่ใช่การตรวจวัดพลังงานที่คุณใช้จริงทั้งวัน - TDEE = BMR × ตัวคูณกิจกรรม 1.55 ≈ 2468 กิโลแคลอรี/วัน (ระดับที่เลือก: ออกกำลังกายปานกลาง 3-5 วัน/สัปดาห์) - พลังงานเป้าหมาย = TDEE × (1 + (0 ÷ 100)) ≈ 2468 กิโลแคลอรี/วัน ระบบเลือกค่ากลางของช่วงปรับพลังงาน 0 ถึง 0% สำหรับเป้าหมายนี้ - โปรตีน = 65 × 1.8 ≈ 117 กรัม/วัน ระบบเลือกค่ากลางของช่วง 1.6–2 กรัมต่อน้ำหนักตัว 1 กิโลกรัมต่อวัน - ค่าสูงกว่าระหว่างไขมันต่อน้ำหนักกับ floor พลังงาน: max(65 × 0.9, 2468.375 × 0.20 ÷ 9) ≈ 58 กรัม/วัน — 0.9 กรัม/กก. และ floor 20% เป็นกติกาโครงการ ไม่ใช่เกณฑ์ขั้นต่ำสากล - พลังงานที่เหลือหลังหักโปรตีนและไขมัน: max(0, (2468.375 − 4 × 117 − 9 × 58.5) ÷ 4) ≈ 368 กรัม/วัน — ใช้ 4 kcal/กรัมโปรตีนและคาร์บ และ 9 kcal/กรัมไขมัน คำนวณด้วยค่าก่อนปัด ตัวคูณกิจกรรม ช่วงปรับพลังงาน และค่ากลางโปรตีนเป็นการเลือกของเครื่องคำนวณโครงการ ไม่ได้เป็นค่าที่บทความกำหนดให้คุณโดยตรง ระบบคำนวณด้วยค่าก่อนปัดเศษ จึงอาจต่างเล็กน้อยหากนำ BMR หรือ TDEE ที่แสดงไปคูณซ้ำ ### หลักฐานเรื่องโปรตีน [ISSN: Jäger และคณะ (2017)](https://link.springer.com/article/10.1186/s12970-017-0177-8) เสนอช่วงโปรตีนรวม 1.4–2.0 กรัมต่อน้ำหนักตัว 1 กิโลกรัมต่อวัน สำหรับผู้ใหญ่สุขภาพดีที่ออกกำลังกายส่วนใหญ่ ช่วงนี้เป็นหลักฐานทั่วไป ไม่ได้กำหนดค่ากลางที่ระบบเลือก และไม่ได้รับรองว่าช่วงโปรตีนของโครงการทุกเป้าหมายเหมาะกับทุกคน ตัวเลขทั้งหมดเป็นค่าประมาณจากข้อมูลที่กรอก ไม่ใช่คำแนะนำทางการแพทย์หรือการรับรองผลรายบุคคล | G35: ผ่าน | I35: คำนวณพลังงานจากโปรไฟล์ตัวอย่างพร้อมวิธีคำนวณทุกขั้น | J35: ผ่าน | L35: รอตรวจ | M35: รอตรวจ | O35: Pantip | Q35: ไม่ | R35: 1 | S35: 1.4
