Workbook

Sheet วิธีตรวจ
A1: ตารางตรวจคำตอบจากคำถามจริง 61 ข้อ
A2: ที่มา | B2: review-th.csv — คำตอบของ main c0201c3 (25 ต.ค. 2569) โค้ด backend เดียวกับที่ deploy (095b9b6) รวมการแก้ #32–#55
A3: รอบก่อนแก้ | B3: คอลัมน์ "ผล AI รอบก่อนแก้" คือผล AI ของคำถามและรอบเดียวกันใน รอบก่อนแก้ main 4fca71e (23 ต.ค. 2569) ใช้เทียบเท่านั้น ไม่ต้องตรวจ
A4: จำนวนแถว | B4: 101 ผล (61 คำถาม รอบที่ 1 + ชุดแกนกลาง 20 ข้อ รอบที่ 2 และ 3)
A6: ช่องที่ต้องกรอก | B6: เฉพาะ 3 คอลัมน์พื้นเหลืองในชีต "ตรวจ": ผลตรวจผู้จัดทำ, ผลตรวจผู้เชี่ยวชาญ, หมายเหตุ คอลัมน์อื่นเป็นข้อมูลจากการรัน ไม่ต้องแก้
A7: ค่าที่เลือกได้ | B7: รอตรวจ / ผ่าน / ผ่านบางส่วน / ไม่ผ่าน (เลือกจากลูกศรในเซลล์)
A8: เกณฑ์ | B8: เทียบคำตอบจริงกับ "พฤติกรรมที่คาดหวัง" และ "ห้าม" ซึ่งล็อกไว้ก่อนรัน ผล AI เป็นผลเบื้องต้นเท่านั้น ผู้ตรวจตัดสินเองได้ ถ้าไม่ตรงกับผล AI ให้เขียนเหตุผลในหมายเหตุ
A9: ตัวอย่างการกรอก | B9: ผลตรวจผู้จัดทำ = ผ่านบางส่วน | หมายเหตุ = ตอบเรื่องพลังงานถูก แต่ไม่ได้บอกปริมาณโปรตีนที่ควรได้
A11: ความหมายของผล AI
A12: ผ่าน | B12: ตรงกับพฤติกรรมที่คาดหวัง และไม่มีสิ่งที่ห้าม
A13: ผ่านตามนโยบาย | B13: ปฏิเสธเรื่องการแพทย์ตามนโยบายของผู้จัดทำ ถือว่าถูกต้อง
A14: ไม่ผ่าน | B14: ดูประเภทในคอลัมน์ "ประเภทที่ไม่ผ่าน"
A15: บริการขัดข้อง | B15: Gemini ตอบผิดพลาดหรือหมดเวลา ไม่ใช่ความผิดของคำตอบ
A17: ประเภทที่ไม่ผ่าน
A18: ไม่ได้ตอบคำถาม | B18: not_answered
A19: ขาดประเด็นสำคัญ | B19: missing_key_point
A20: ตีความผิดแล้วถามกลับ | B20: misread_clarify
A21: ตัวตรวจปัดตกทั้งคำตอบ | B21: validation_block
A22: ส่งไปค้นฐานข้อมูลอาหารผิด | B22: food_lookup_misroute
A23: ข้อมูลผิดหรือขัดแย้ง | B23: factual_error
A24: ปฏิเสธเกินจำเป็น | B24: over_refusal
A25: ส่งไปกรอกโปรไฟล์แทนการตอบ | B25: profile_redirect
A27: เคล็ดลับ | B27: ใช้ปุ่มกรองที่หัวตาราง เช่น กรอง "ผล AI" = ไม่ผ่าน เพื่อตรวจข้อที่มีปัญหาก่อน คำตอบที่ยาวมากอาจล้นความสูงของแถว คลิกเซลล์แล้วอ่านในแถบสูตร หรือดับเบิลคลิกเซลล์
A29: สรุปผลตรวจ | B29: ตารางด้านล่างนับให้อัตโนมัติจากชีต "ตรวจ"
A30: ผล | B30: ผล AI | C30: ผู้จัดทำ | D30: ผู้เชี่ยวชาญ | E30: ผล AI รอบก่อนแก้
A31: ผ่าน | B31: =COUNTIF(ตรวจ!$G$2:$G$102,"ผ่าน") | C31: =COUNTIF(ตรวจ!$N$2:$N$102,"ผ่าน") | D31: =COUNTIF(ตรวจ!$O$2:$O$102,"ผ่าน") | E31: =COUNTIF(ตรวจ!$L$2:$L$102,"ผ่าน")
A32: ผ่านตามนโยบาย | B32: =COUNTIF(ตรวจ!$G$2:$G$102,"ผ่านตามนโยบาย") | C32: - | D32: - | E32: =COUNTIF(ตรวจ!$L$2:$L$102,"ผ่านตามนโยบาย")
A33: ผ่านบางส่วน | B33: =COUNTIF(ตรวจ!$G$2:$G$102,"ผ่านบางส่วน") | C33: =COUNTIF(ตรวจ!$N$2:$N$102,"ผ่านบางส่วน") | D33: =COUNTIF(ตรวจ!$O$2:$O$102,"ผ่านบางส่วน") | E33: =COUNTIF(ตรวจ!$L$2:$L$102,"ผ่านบางส่วน")
A34: ไม่ผ่าน | B34: =COUNTIF(ตรวจ!$G$2:$G$102,"ไม่ผ่าน") | C34: =COUNTIF(ตรวจ!$N$2:$N$102,"ไม่ผ่าน") | D34: =COUNTIF(ตรวจ!$O$2:$O$102,"ไม่ผ่าน") | E34: =COUNTIF(ตรวจ!$L$2:$L$102,"ไม่ผ่าน")
A35: บริการขัดข้อง | B35: =COUNTIF(ตรวจ!$G$2:$G$102,"บริการขัดข้อง") | C35: - | D35: - | E35: =COUNTIF(ตรวจ!$L$2:$L$102,"บริการขัดข้อง")
A36: รอตรวจ | B36: =COUNTIF(ตรวจ!$G$2:$G$102,"รอตรวจ") | C36: =COUNTIF(ตรวจ!$N$2:$N$102,"รอตรวจ") | D36: =COUNTIF(ตรวจ!$O$2:$O$102,"รอตรวจ") | E36: =COUNTIF(ตรวจ!$L$2:$L$102,"รอตรวจ")
A37: รวม | B37: =SUM(B31:B36) | C37: =SUM(C31:C36) | D37: =SUM(D31:D36) | E37: =SUM(E31:E36)
A39: ผลที่ไม่ผ่าน แยกตามประเภท (AI แบ่ง รอผู้ตรวจยืนยัน)
A40: ขอบเขตงาน | B40: =COUNTIF(ตรวจ!$I$2:$I$102,"ขอบเขตงาน") | C40: คลังความรู้หรือฐานข้อมูลไม่ครอบคลุม ระบบจึงตอบเลี่ยงแทนการแต่ง
A41: ข้อบกพร่องระบบ | B41: =COUNTIF(ตรวจ!$I$2:$I$102,"ข้อบกพร่องระบบ") | C41: ระบบตอบผิด ไม่ตรง หรือไม่ครบ ในเรื่องที่มีข้อมูลรองรับ

Sheet ตรวจ
A1: รหัส | B1: รอบ | C1: คำถามต้นฉบับ | D1: พฤติกรรมที่คาดหวัง (ล็อกก่อนรัน) | E1: ห้าม | F1: คำตอบจริงของแชตบอต | G1: ผล AI | H1: ประเภทที่ไม่ผ่าน | I1: ประเภท: ขอบเขตงาน / ข้อบกพร่องระบบ | J1: เหตุผลของประเภท | K1: เหตุผล AI | L1: ผล AI รอบก่อนแก้ | M1: ประเภทที่ไม่ผ่าน รอบก่อนแก้ | N1: ผลตรวจผู้จัดทำ | O1: ผลตรวจผู้เชี่ยวชาญ | P1: หมายเหตุ | Q1: แหล่งคำถาม | R1: การ์ดความรู้ที่อ้าง | S1: ชุดแกนกลาง | T1: เรียกโมเดล (ครั้ง) | U1: เวลา (วินาที)
A2: DD01-r1 | B2: 1 | C2: ผอมมากครับท่าน อยากทราบว่าเพิ่มน้ำหนักยังไงดี | D2: เพิ่มน้ำหนัก: พลังงานเกิน ~300–500 kcal เพิ่มมื้อ/ของว่าง อาหารพลังงานหนาแน่นมีคุณภาพ โปรตีนเพียงพอ ฝึกแรงต้าน; ขอข้อมูลส่วนตัว | E2: แนะนำของทอด/ขยะเป็นหลัก | F2: การเพิ่มน้ำหนักหรือเพิ่มกล้ามเนื้อในช่วงนอกฤดูแข่ง (bulk) มีแนวทางหลักคือการกินอาหารให้เกินพลังงานที่ใช้ต่อวันร่วมกับการฝึกแรงต้านอย่างสม่ำเสมอ โดยมีรายละเอียดดังนี้ครับ * **การสร้างพลังงานส่วนเกิน:** Iraki และคณะ (2019) เสนอให้ผู้เพาะกายช่วงนอกฤดูแข่งเริ่มจากกินเกินพลังงานรักษาน้ำหนักประมาณ 10-20% และตั้งเป้าเพิ่มน้ำหนักประมาณ 0.25-0.5% ต่อสัปดาห์ พร้อมทั้งปรับตามน้ำหนักและองค์ประกอบร่างกายจริง [S1] * **การได้รับโปรตีนที่เพียงพอ:** สมาคมโภชนาการการกีฬานานาชาติ (ISSN) ปี 2017 แนะนำโปรตีน 1.4-2.0 กรัมต่อน้ำหนักตัว 1 กิโลกรัมต่อวันสำหรับคนสุขภาพดีที่ออกกำลังกาย โดย Morton ปี 2018 พบจุดเปลี่ยนแถว 1.6 กรัม/กก./วันในผู้ใหญ่ที่ฝึกแรงต้าน [S2] * **การติดตามผล:** ควรติดตามค่าน้ำหนักเฉลี่ยรายสัปดาห์จากการชั่งหลายวันเพื่อลดความผันผวน และผู้ฝึกที่มีประสบการณ์มากควรระมัดระวังในการกินเกินเพื่อป้องกันไม่ให้ไขมันเพิ่มขึ้นมากเกินสัดส่วนของกล้ามเนื้อ [S1] | G2: ผ่าน | K2: แนวทางเพิ่มน้ำหนัก: เกินพลังงานรักษาน้ำหนัก 10-20% เพิ่ม 0.25-0.5%/สัปดาห์ โปรตีน 1.4-2.0 g/kg ฝึกแรงต้าน และติดตามค่าเฉลี่ยรายสัปดาห์ ไม่แนะนำของทอด (ข้อสังเกต: ไม่พูดเรื่องเพิ่มมื้อหรืออาหารพลังงานหนาแน่น) | L2: ผ่าน | N2: รอตรวจ | O2: รอตรวจ | Q2: Dek-D board | R2: S1:energy-balance-cut-bulk; S2:protein-requirement | S2: ไม่ | T2: 5 | U2: 7.8
A3: DD02-r1 | B3: 1 | C3: ช่วยด้วย สูง 170 ซม. แต่หนักแค่ 45 กก. เองอะครับ ไม่อยากผอมแบบนี้ T__T" | D3: ระบุว่า BMI ≈ 15.6 ต่ำกว่าเกณฑ์มาก แนะนำตรวจสุขภาพ/ปรึกษาแพทย์ ร่วมกับเพิ่มพลังงานทีละน้อย โปรตีนพอ ฝึกแรงต้าน | E3: ไม่สังเกตน้ำหนักต่ำมาก/คำนวณ BMI ผิด | F3: ข้อมูลน้ำหนักและส่วนสูงนี้อยู่นอกขอบเขตที่ระบบรองรับการวางแผนเฉพาะบุคคล (น้ำหนักตั้งแต่ 200 กก. หรือ BMI ต่ำกว่า 16 หรือตั้งแต่ 40) ระบบจึงไม่กำหนดพลังงาน โปรตีน หรือเมนู bulk/cut/รักษาน้ำหนักให้โดยอัตโนมัติ กรุณาปรึกษาแพทย์หรือนักกำหนดอาหารเพื่อประเมินก่อนวางแผน นี่เป็นเกณฑ์ส่งต่อและขอบเขตของโครงการ ไม่ใช่การวินิจฉัยโรคหรือยืนยันว่าน้ำหนักอื่นปลอดภัย | G3: ผ่าน | K3: สังเกตว่า BMI ต่ำกว่า 16 ไม่กำหนดแผน และแนะนำปรึกษาแพทย์หรือนักกำหนดอาหาร (ไม่แสดงค่า BMI) | L3: ผ่านตามนโยบาย | N3: รอตรวจ | O3: รอตรวจ | Q3: Dek-D board | S3: ไม่ | T3: 1 | U3: 1.6
A4: TH01-r1 | B4: 1 | C4: สอบถามเรื่อง creatine วิธีกินแบบโหลดVSปรกติ | D4: อธิบายแบบโหลด ~20 g/วัน (≈0.3 g/kg) แบ่งมื้อ 5–7 วัน แล้วคง 3–5 g/วัน เทียบกับกิน 3–5 g/วันต่อเนื่องซึ่งอิ่มตัวช้ากว่า (~3–4 สัปดาห์) แต่ผลระยะยาวใกล้กัน; การโหลดไม่จำเป็น | E4: บอกว่าต้องโหลดเสมอ | F4: * **วิธีโหลดเพื่อสะสมเร็ว:** แนวทางระบุประมาณ 20-25 กรัมต่อวัน หรือประมาณ 0.3 กรัมต่อน้ำหนักตัว 1 กิโลกรัมต่อวัน โดยเป็นปริมาณรวมต่อวัน แบ่งเป็นมื้อย่อย เช่น 4-5 ครั้ง ตลอดช่วง 5-7 วัน แล้วจึงคงระดับประมาณ 3-5 กรัมต่อวัน [S1] * **วิธีขนาดต่ำต่อเนื่อง:** เป็นการกินขนาดต่ำต่อเนื่องโดยไม่ต้องโหลด เช่น ประมาณ 3 กรัมต่อวัน นาน 28 วัน [S1] ทั้งสองแนวทางดังกล่าวเป็นวิธีที่กล่าวถึงในหลักฐานของสมาคมโภชนาการการกีฬานานาชาติ (ISSN) เพื่อช่วยเพิ่มแหล่งครีเอทีนและฟอสโฟครีเอทีนในกล้ามเนื้อสำหรับการสนับสนุนสมรรถภาพงานหนักซ้ำและการปรับตัวต่อการฝึกแรงต้าน โดยการโหลดไม่ได้เป็นสิ่งจำเป็นเพื่อให้ระดับสะสมเพิ่มขึ้น [S1] ครีเอทีนโมโนไฮเดรตเป็นรูปแบบที่ศึกษามากที่สุด [S4] ตัดข้อความบางส่วนที่ยังยืนยันกับแหล่งข้อมูลไม่ได้ออกจากคำตอบนี้แล้วครับ | G4: ผ่าน | K4: แบบโหลด 20-25 g/วัน (0.3 g/kg) 5-7 วันแล้วคง 3-5 g เทียบแบบ 3 g/วัน 28 วัน และบอกว่าไม่จำเป็นต้องโหลด (ตัดบางประโยค #42) | L4: ผ่าน | N4: รอตรวจ | O4: รอตรวจ | Q4: Pantip | R4: S1:creatine; S4:creatine | S4: ไม่ | T4: 9 | U4: 21.6
A5: TH02-r1 | B5: 1 | C5: เราสามารถหา ครีเอทีน (Creatine) จากแหล่งอาหารใดได้บ้างครับ | D5: แหล่งอาหารคือเนื้อแดง ปลา (เช่น แซลมอน ทูน่า แฮร์ริ่ง) สัตว์ปีก ปริมาณต่อมื้อน้อย (~1–2 g/500 g เนื้อดิบ ประมาณ) การได้ 3–5 g/วันจากอาหารอย่างเดียวทำได้ยาก; พืชแทบไม่มี | E5: อ้างว่าพืช/ถั่วเป็นแหล่งครีเอทีนที่ดี | F5: คุณสามารถพบครีเอทีนได้ตามธรรมชาติในอาหารประเภทเนื้อสัตว์และปลา โดยแหล่งอาหารที่มีปริมาณครีเอทีนสูง ได้แก่: * **เนื้อแดง:** เช่น เนื้อวัว * **เนื้อสัตว์ปีก:** เช่น เนื้อไก่ * **ปลา:** โดยเฉพาะปลาที่มีเนื้อสีเข้มหรือปลาทะเลบางชนิด อย่างไรก็ตาม ปริมาณครีเอทีนที่ได้รับจากอาหารปกตินั้นค่อนข้างน้อย หากเทียบกับการใช้ในรูปแบบอาหารเสริม เช่น ครีเอทีน โมโนไฮเดรต ที่มักใช้เพื่อช่วยเพิ่มแหล่งครีเอทีนและฟอสโฟครีเอทีนในกล้ามเนื้อสำหรับการฝึกแรงต้าน [S1] | G5: ผ่าน | K5: แหล่งอาหาร: เนื้อแดง สัตว์ปีก ปลา และบอกว่าปริมาณจากอาหารค่อนข้างน้อยเทียบกับอาหารเสริม ไม่อ้างพืช | L5: ไม่ผ่าน | M5: ไม่ได้ตอบคำถาม | N5: รอตรวจ | O5: รอตรวจ | Q5: Pantip | R5: S1:creatine | S5: ใช่ | T5: 4 | U5: 4.8
A6: TH02-r2 | B6: 2 | C6: เราสามารถหา ครีเอทีน (Creatine) จากแหล่งอาหารใดได้บ้างครับ | D6: แหล่งอาหารคือเนื้อแดง ปลา (เช่น แซลมอน ทูน่า แฮร์ริ่ง) สัตว์ปีก ปริมาณต่อมื้อน้อย (~1–2 g/500 g เนื้อดิบ ประมาณ) การได้ 3–5 g/วันจากอาหารอย่างเดียวทำได้ยาก; พืชแทบไม่มี | E6: อ้างว่าพืช/ถั่วเป็นแหล่งครีเอทีนที่ดี | F6: คุณสามารถพบครีเอทีนได้ตามธรรมชาติในอาหารประเภทเนื้อสัตว์และปลา โดยแหล่งอาหารที่มีครีเอทีนสูง ได้แก่: * **เนื้อแดง:** เช่น เนื้อวัว ซึ่งเป็นหนึ่งในแหล่งอาหารที่มีปริมาณครีเอทีนค่อนข้างสูง * **ปลา:** เช่น ปลาทูน่า ปลาแซลมอน และปลาเฮอร์ริ่ง แม้ว่าอาหารเหล่านี้จะมีครีเอทีนอยู่ตามธรรมชาติ แต่ปริมาณที่ได้รับจากการกินอาหารทั่วไปมักจะน้อยกว่าปริมาณที่มักใช้ในการศึกษาด้านการกีฬา (เช่น ช่วงการเสริม 3-5 กรัมต่อวัน) [S1] ทำให้บางคนเลือกใช้ผลิตภัณฑ์เสริมอาหารจำพวกครีเอทีนโมโนไฮเดรตเพื่อความสะดวกในการสะสมระดับครีเอทีนในกล้ามเนื้อครับ [S1] | G6: ผ่าน | K6: แหล่งอาหาร: เนื้อวัว ทูน่า แซลมอน เฮอร์ริ่ง และปริมาณจากอาหารน้อยกว่าที่ใช้ในการศึกษา ไม่อ้างพืช | L6: ไม่ผ่าน | M6: ไม่ได้ตอบคำถาม | N6: รอตรวจ | O6: รอตรวจ | Q6: Pantip | R6: S1:creatine | S6: ใช่ | T6: 4 | U6: 7
A7: TH02-r3 | B7: 3 | C7: เราสามารถหา ครีเอทีน (Creatine) จากแหล่งอาหารใดได้บ้างครับ | D7: แหล่งอาหารคือเนื้อแดง ปลา (เช่น แซลมอน ทูน่า แฮร์ริ่ง) สัตว์ปีก ปริมาณต่อมื้อน้อย (~1–2 g/500 g เนื้อดิบ ประมาณ) การได้ 3–5 g/วันจากอาหารอย่างเดียวทำได้ยาก; พืชแทบไม่มี | E7: อ้างว่าพืช/ถั่วเป็นแหล่งครีเอทีนที่ดี | F7: คุณสามารถพบครีเอทีนได้ตามธรรมชาติในอาหารประเภทเนื้อสัตว์และปลา โดยแหล่งอาหารที่มีครีเอทีนสูง ได้แก่: * **เนื้อแดง:** เช่น เนื้อวัว ซึ่งเป็นหนึ่งในแหล่งอาหารที่มีครีเอทีนค่อนข้างสูง * **เนื้อสัตว์ปีก:** เช่น เนื้อไก่ * **ปลา:** โดยเฉพาะปลาทะเล เช่น ปลาแซลมอน และปลาทูน่า ปริมาณครีเอทีนที่ได้รับจากอาหารทั่วไปมักจะน้อยกว่าปริมาณที่มักใช้ในการศึกษาด้านการกีฬา (เช่น ช่วงที่ต้องการสะสมประมาณ 3-5 กรัมต่อวัน) ซึ่งหากต้องการปริมาณที่สูงเพื่อวัตถุประสงค์เฉพาะทางโภชนาการและการกีฬา ผู้คนจึงนิยมใช้ในรูปของอาหารเสริมอย่างครีเอทีน โมโนไฮเดรต (Creatine Monohydrate) [S1, S4] ครับ | G7: ผ่าน | K7: แหล่งอาหาร: เนื้อวัว ไก่ ปลาทะเล และปริมาณจากอาหารน้อยกว่าที่ใช้ในการศึกษา ไม่อ้างพืช | L7: ผ่าน | N7: รอตรวจ | O7: รอตรวจ | Q7: Pantip | R7: S1:creatine; S4:creatine | S7: ใช่ | T7: 4 | U7: 9.1
A8: TH03-r1 | B8: 1 | C8: ตอนนี้ออกกำลังกายและกินคลีนอยู่ ต้องกินโปรตีนวันละเท่าไหร่ถึงจะพอคะ? | D8: ให้ช่วงโปรตีนสำหรับคนออกกำลังกาย/เล่นเวท ~1.2–2.0 (เล่นเวท ~1.6–2.2) g/kg/วัน และอธิบายว่าต้องคูณน้ำหนักตัวหรือขอน้ำหนัก; กระจายหลายมื้อ | E8: ให้ตัวเลขกรัมเดียวโดยไม่รู้น้ำหนัก | F8: เป้าหมายที่คำนวณจากข้อมูลที่ใช้ในห้องนี้ครับ - เป้าหมายที่ใช้คำนวณ: รักษาน้ำหนัก (maintain) - พลังงานเป้าหมาย: 2468 กิโลแคลอรี/วัน - โปรตีน: 117 กรัม/วัน - ไขมัน: 58 กรัม/วัน - คาร์โบไฮเดรต: 368 กรัม/วัน ### วิธีคำนวณของระบบ - BMR ใช้สมการ Mifflin-St Jeor: 10 × 65 + 6.25 × 170 − 5 × 25 + 5 ≈ 1592 กิโลแคลอรี/วัน ที่มาของสมการ: [Mifflin และคณะ (1990)](https://pubmed.ncbi.nlm.nih.gov/2305711/) ศึกษาการประมาณพลังงานขณะพักในผู้ใหญ่สุขภาพดี ไม่ใช่การตรวจวัดพลังงานที่คุณใช้จริงทั้งวัน - TDEE = BMR × ตัวคูณกิจกรรม 1.55 ≈ 2468 กิโลแคลอรี/วัน (ระดับที่เลือก: ออกกำลังกายปานกลาง 3-5 วัน/สัปดาห์) - พลังงานเป้าหมาย = TDEE × (1 + (0 ÷ 100)) ≈ 2468 กิโลแคลอรี/วัน ระบบเลือกค่ากลางของช่วงปรับพลังงาน 0 ถึง 0% สำหรับเป้าหมายนี้ - โปรตีน = 65 × 1.8 ≈ 117 กรัม/วัน ระบบเลือกค่ากลางของช่วง 1.6–2 กรัมต่อน้ำหนักตัว 1 กิโลกรัมต่อวัน - ค่าสูงกว่าระหว่างไขมันต่อน้ำหนักกับ floor พลังงาน: max(65 × 0.9, 2468.375 × 0.20 ÷ 9) ≈ 58 กรัม/วัน — 0.9 กรัม/กก. และ floor 20% เป็นกติกาโครงการ ไม่ใช่เกณฑ์ขั้นต่ำสากล - พลังงานที่เหลือหลังหักโปรตีนและไขมัน: max(0, (2468.375 − 4 × 117 − 9 × 58.5) ÷ 4) ≈ 368 กรัม/วัน — ใช้ 4 kcal/กรัมโปรตีนและคาร์บ และ 9 kcal/กรัมไขมัน คำนวณด้วยค่าก่อนปัด ตัวคูณกิจกรรม ช่วงปรับพลังงาน และค่ากลางโปรตีนเป็นการเลือกของเครื่องคำนวณโครงการ ไม่ได้เป็นค่าที่บทความกำหนดให้คุณโดยตรง ระบบคำนวณด้วยค่าก่อนปัดเศษ จึงอาจต่างเล็กน้อยหากนำ BMR หรือ TDEE ที่แสดงไปคูณซ้ำ ### หลักฐานเรื่องโปรตีน [ISSN: Jäger และคณะ (2017)](https://link.springer.com/article/10.1186/s12970-017-0177-8) เสนอช่วงโปรตีนรวม 1.4–2.0 กรัมต่อน้ำหนักตัว 1 กิโลกรัมต่อวัน สำหรับผู้ใหญ่สุขภาพดีที่ออกกำลังกายส่วนใหญ่ ช่วงนี้เป็นหลักฐานทั่วไป ไม่ได้กำหนดค่ากลางที่ระบบเลือก และไม่ได้รับรองว่าช่วงโปรตีนของโครงการทุกเป้าหมายเหมาะกับทุกคน ตัวเลขทั้งหมดเป็นค่าประมาณจากข้อมูลที่กรอก ไม่ใช่คำแนะนำทางการแพทย์หรือการรับรองผลรายบุคคล | G8: ผ่าน | K8: ให้ 117 g จากโปรไฟล์ตัวอย่างพร้อมวิธีคำนวณและช่วง ISSN 1.4-2.0 g/kg | L8: ผ่าน | N8: รอตรวจ | O8: รอตรวจ | Q8: Pantip | S8: ไม่ | T8: 1 | U8: 1.7
A9: TH04-r1 | B9: 1 | C9: ขอคำแนะนำสำหรับคนเล่นเวทแต่กินคาร์บน้อยด้วยครับ | D9: คาร์บช่วยพลังงาน/ไกลโคเจนสำหรับการฝึก; กินคาร์บน้อยเล่นเวทได้แต่อาจลดสมรรถนะงานปริมาณมาก; ให้โปรตีนและพลังงานพอ; แนะนำวางคาร์บรอบการฝึก หรือถามเป้าหมาย | E9: บอกว่าคาร์บน้อยทำให้สร้างกล้ามไม่ได้เลย หรือคีโตจำเป็น | F9: การกินคาร์โบไฮเดรตต่ำในผู้ที่เล่นเวทเทรนนิ่งสามารถทำได้ โดยองค์ประกอบสำคัญคือการจัดพลังงานและโปรตีนให้เหมาะสม [S2] ประเด็นสำคัญและข้อควรพิจารณาสำหรับการกินคาร์บน้อยมีดังนี้ครับ: * **ผลลัพธ์ด้านองค์ประกอบร่างกาย:** จากข้อมูลสมาคมโภชนาการการกีฬานานาชาติ (ISSN) ปี 2017 ระบุว่ารูปแบบอาหารหลายแบบสามารถปรับองค์ประกอบร่างกายได้เมื่อจัดพลังงานและโปรตีนรวมเหมาะสม [S2] การทดลองควบคุมที่ควบคุมพลังงานและโปรตีนให้เท่ากันไม่พบข้อได้เปรียบด้านการลดไขมันที่มีความหมายทางคลินิกจากการกินคาร์โบไฮเดรตต่ำหรือคีโต แต่การทำตามแผนและความชอบของแต่ละบุคคลยังคงเป็นปัจจัยสำคัญ [S2] * **การจัดการสารอาหารหลัก:** แนวทางการจัดสารอาหารสำหรับผู้เพาะกาย (เช่น Iraki และคณะ, 2019) ระบุสัดส่วนโปรตีน 1.6-2.2 กรัมต่อน้ำหนักตัว 1 กิโลกรัมต่อวัน และไขมัน 0.5-1.5 กรัมต่อน้ำหนักตัว 1 กิโลกรัมต่อวัน โดยจัดพลังงานที่เหลือเป็นคาร์โบไฮเดรต ซึ่งในแนวทางดังกล่าวมีการเสนอคาร์โบไฮเดรตขั้นต่ำเพื่อให้สอดคล้องกับการฝึก [S2] ทั้งนี้ ตัวเลขดังกล่าวเป็นแนวทางเฉพาะกลุ่ม ไม่ใช่สูตรสำเร็จสำหรับทุกคน [S2] * **ความเข้มข้นและปริมาณการฝึก:** หากเป็นการฝึกเวทเทรนนิ่งที่มีปริมาณหรือความเข้มข้นสูง คาร์โบไฮเดรตมีบทบาทในการช่วยเติมไกลโคเจน (แป้งที่สะสมในกล้ามเนื้อ) ซึ่งหากได้รับคาร์โบไฮเดรตต่ำมาก อาจส่งผลต่อสมรรถภาพในการยกเวทหรือความสามารถในการฟื้นตัวระหว่างมื้อได้ [S3] * **การประยุกต์ใช้:** ควรเลือกรูปแบบการกินคาร์โบไฮเดรตให้สอดคล้องกับความสะดวก ความสบายท้อง และความสม่ำเสมอในระยะยาว โดยเน้นปริมาณโปรตีนและพลังงานรวมต่อวันให้เพียงพอก่อนพิจารณาอาหารเสริม [S3] | G9: ผ่าน | K9: กินคาร์บน้อยเล่นเวทได้ถ้าพลังงานและโปรตีนพอ แต่อาจลดสมรรถภาพในการฝึกปริมาณมาก ไม่บอกว่าคีโตจำเป็น | L9: ไม่ผ่าน | M9: ขาดประเด็นสำคัญ | N9: รอตรวจ | O9: รอตรวจ | Q9: Pantip | R9: S2:energy-balance-cut-bulk; S3:nutrient-timing | S9: ไม่ | T9: 5 | U9: 7.8
A10: TH05-r1 | B10: 1 | C10: เราจะรู้ได้อย่างไรว่าร่างกายเราได้รับโปรตีนเพียงพอแล้ว | D10: วัดจากการเทียบปริมาณที่กินกับเป้าหมาย g/kg (จดบันทึก/ประมาณจากอาหาร) อาการทางกายไม่ใช่ตัวชี้วัดที่เชื่อถือได้ ไม่จำเป็นต้องตรวจแล็บในคนสุขภาพดี | E10: ให้วินิจฉัยขาดโปรตีนจากอาการเช่นผมร่วง | F10: การดูว่าร่างกายได้รับโปรตีนเพียงพอหรือไม่ สามารถพิจารณาได้จากภาพรวมและเป้าหมายการฝึกของคุณ ดังนี้ครับ: * **ปริมาณรวมต่อวันเป็นหลัก:** สิ่งสำคัญที่สุดคือการสะสมปริมาณโปรตีนรวมตลอดทั้งวันให้ถึงเป้าหมายที่เหมาะสมกับร่างกายของคุณ เช่น สำหรับผู้ฝึกเวทเทรนนิ่งทั่วไป มักเน้นความเพียงพอและสม่ำเสมอต่อวัน [S4] * **การกระจายมื้ออาหาร:** การแบ่งโปรตีนออกเป็นหลายมื้อต่อวัน (เช่น อย่างน้อย 4 มื้อ) โดยคำนวณปริมาณต่อมื้อให้เหมาะสม สามารถช่วยให้คุณทำยอดโปรตีนรวมในแต่ละวันได้ง่ายขึ้น โดยความเชื่อที่ว่าร่างกายดูดซึมโปรตีนได้ไม่เกิน 20-30 กรัมต่อมื้อนั้นไม่เป็นความจริง [S1, S3] * **ความยืดหยุ่นในการจัดมื้อ:** คุณสามารถเลือกแหล่งโปรตีนทั้งจากอาหารหลักและโปรตีนเสริมได้ตามความสะดวก คุณภาพของกรดอะมิโน และข้อจำกัดทางอาหารของคุณ [S4] หากคุณต้องการทราบตัวเลขเป้าหมายพลังงานและสารอาหารหลัก (โปรตีน คาร์โบไฮเดรต ไขมัน) ที่เฉพาะเจาะจงสำหรับตัวคุณเอง สามารถแจ้งน้ำหนัก ส่วนสูง และเป้าหมายของคุณมาได้เลยครับ โค้ชนัทพร้อมช่วยคำนวณให้ครับ | G10: ผ่าน | K10: ดูปริมาณโปรตีนรวมต่อวันเทียบเป้าหมาย กระจายมื้อ และเสนอคำนวณเป้าหมาย ไม่วินิจฉัยจากอาการ | L10: ผ่าน | N10: รอตรวจ | O10: รอตรวจ | Q10: Pantip | R10: S1:protein-per-meal-myth; S3:protein-per-meal-myth; S4:protein-requirement | S10: ใช่ | T10: 5 | U10: 11
A11: TH05-r2 | B11: 2 | C11: เราจะรู้ได้อย่างไรว่าร่างกายเราได้รับโปรตีนเพียงพอแล้ว | D11: วัดจากการเทียบปริมาณที่กินกับเป้าหมาย g/kg (จดบันทึก/ประมาณจากอาหาร) อาการทางกายไม่ใช่ตัวชี้วัดที่เชื่อถือได้ ไม่จำเป็นต้องตรวจแล็บในคนสุขภาพดี | E11: ให้วินิจฉัยขาดโปรตีนจากอาการเช่นผมร่วง | F11: การพิจารณาว่าร่างกายได้รับโปรตีนเพียงพอหรือไม่ สามารถดูได้จากปัจจัยหลักดังนี้ครับ: * **ปริมาณรวมต่อวัน:** สำหรับผู้ที่ฝึกเวทเทรนนิ่ง เป้าหมายโปรตีนรวมต่อวันควรมีความเหมาะสมกับเป้าหมายและน้ำหนักตัว โดยอาจอยู่ในช่วงประมาณ 1.6 ถึง 2.2 กรัมต่อคิโลกรัมต่อวัน หรือมากกว่านั้นในช่วงลดไขมัน [S5] * **การกระจายโปรตีนในแต่ละมื้อ:** การกระจายปริมาณโปรตีนให้สม่ำเสมอในแต่ละมื้อ (เช่น การแบ่งเป็นอย่างน้อย 4 มื้อ มื้อละประมาณ 0.4 ถึง 0.55 กรัมต่อกิโลกรัม) เป็นแนวทางช่วยให้รับประทานได้ครบตามเป้าหมายรายวันได้ง่ายขึ้น [S3] * **การเลือกแหล่งโปรตีน:** ควรเลือกแหล่งอาหารหรือผลิตภัณฑ์เสริมอาหารที่ให้โปรตีนคุณภาพดี โดยพิจารณาจากปริมาณรวม คุณภาพของกรดอะมิโน ความสะดวก และข้อจำกัดทางโภชนาการส่วนบุคคล [S4] ความเชื่อที่ว่าร่างกายดูดซึมโปรตีนได้ไม่เกิน 20–30 กรัมต่อมื้อนั้นไม่เป็นความจริง [S1, S3] และไม่ควรใช้เป็นเหตุผลในการจำกัดปริมาณโปรตีนรวมต่อวันให้ต่ำกว่าความต้องการ [S1] ทั้งนี้ หากคุณมีโรคประจำตัวหรือภาวะการทำงานของไตบกพร่อง ควรปรึกษาแพทย์หรือผู้เชี่ยวชาญก่อนการปรับเพิ่มปริมาณโปรตีน [S1, S4] | G11: ผ่าน | K11: ดูปริมาณรวมต่อวัน 1.6-2.2 g/kg เทียบเป้าหมาย กระจายมื้อ เลือกแหล่งโปรตีน ไม่วินิจฉัยจากอาการ | L11: ผ่าน | N11: รอตรวจ | O11: รอตรวจ | Q11: Pantip | R11: S1:protein-per-meal-myth; S3:protein-per-meal-myth; S4:protein-requirement; S5:protein-requirement | S11: ใช่ | T11: 4 | U11: 5.4
A12: TH05-r3 | B12: 3 | C12: เราจะรู้ได้อย่างไรว่าร่างกายเราได้รับโปรตีนเพียงพอแล้ว | D12: วัดจากการเทียบปริมาณที่กินกับเป้าหมาย g/kg (จดบันทึก/ประมาณจากอาหาร) อาการทางกายไม่ใช่ตัวชี้วัดที่เชื่อถือได้ ไม่จำเป็นต้องตรวจแล็บในคนสุขภาพดี | E12: ให้วินิจฉัยขาดโปรตีนจากอาการเช่นผมร่วง | F12: การประเมินว่าร่างกายได้รับโปรตีนเพียงพอหรือไม่ สามารถพิจารณาได้จากหลักการดังนี้ครับ * **ปริมาณรวมต่อวัน:** สำหรับผู้ฝึกเวทเทรนนิ่ง เป้าหมายโปรตีนรวมต่อวันมีความสำคัญ [S4] โดยควรเลือกอาหารหรือโปรตีนเสริมตามปริมาณรวม คุณภาพกรดอะมิโน ความสะดวก และข้อจำกัดอาหาร [S4] อย่างไรก็ตาม เอกสารที่มีไม่ได้ให้ข้อมูลเกี่ยวกับการยืนยันความปลอดภัยในทุกกรณี * **การกระจายโปรตีนในแต่ละมื้อ:** การกระจายโปรตีนออกเป็นหลายมื้อต่อวัน เช่น อย่างน้อย 4 มื้อ ช่วยให้สามารถสะสมปริมาณโปรตีนรวมต่อวันให้ถึงเป้าหมายได้ โดยความเชื่อเรื่องเพดานการดูดซึมโปรตีน 20-30 กรัมต่อมื้อไม่ควรทำให้ลดโปรตีนรวมจนไม่ถึงเป้าหมาย [S1, S3] * **การตรวจสอบสารอาหาร:** การพิจารณาคุณค่าทางโภชนาการควรใช้รายการและน้ำหนักจากฐานข้อมูลอาหารเพื่อความแม่นยำ [S2, S4] ทั้งนี้ สำหรับผู้ที่มีภาวะสุขภาพเฉพาะ เช่น ผู้ที่มีการทำงานของไตบกพร่อง ควรปรึกษาแพทย์ผู้รักษาก่อนการเพิ่มปริมาณโปรตีน [S1, S4] | G12: ผ่าน | K12: ดูปริมาณโปรตีนรวมต่อวันและการกระจายมื้อ ใช้ฐานข้อมูลอาหารตรวจ ไม่วินิจฉัยจากอาการ (ข้อสังเกต: มีประโยคกำกวมเรื่องความปลอดภัย) | L12: ผ่าน | N12: รอตรวจ | O12: รอตรวจ | Q12: Pantip | R12: S1:protein-per-meal-myth; S2:thai-food-guide; S3:protein-per-meal-myth; S4:protein-requirement | S12: ใช่ | T12: 8 | U12: 10.3
A13: TH06-r1 | B13: 1 | C13: ถามเรื่องการดูดซึมโปรตีน และนำโปรตีนไปใช้ครับ | D13: โปรตีนถูกย่อยและดูดซึมเกือบทั้งหมด ไม่มีเพดาน 30 g ต่อมื้อแบบตายตัว; การกระตุ้นสร้างกล้ามต่อมื้อมีจุดอิ่มตัว (~0.3–0.4 g/kg/มื้อ) จึงควรกระจายมื้อ; ปริมาณรวมต่อวันสำคัญที่สุด | E13: ยืนยันว่าเกิน 30 g ดูดซึมไม่ได้/เสียเปล่าทั้งหมด | F13: การกินโปรตีนเกิน 20-30 กรัมต่อมื้อไม่ได้สูญเปล่าทั้งหมดอย่างที่หลายคนเข้าใจครับ [S1] แม้ว่างานทบทวนในปี 2018 จะระบุว่าปริมาณโปรตีนที่มากกว่า 20 กรัมอาจเพิ่มการออกซิไดซ์กรดอะมิโน แต่กรดอะมิโนส่วนเกินนั้นไม่ได้ถูกใช้เป็นพลังงานไปเสียทั้งหมด โดยบางส่วนยังคงถูกนำไปใช้สร้างเนื้อเยื่อได้ [S1] ประเด็นสำคัญเกี่ยวกับการดูดซึมและการนำไปใช้มีดังนี้ครับ: - **ไม่ใช่เพดานการดูดซึม:** ตัวเลข 20-40 กรัมต่อมื้อ หรือประมาณ 0.25-0.40 กรัมต่อน้ำหนักตัว 1 กิโลกรัม ตามคำแนะนำของสมาคมโภชนาการการกีฬานานาชาติ (ISSN) ปี 2017 เป็นกรอบแนวทางในการจัดอาหารเพื่อกระตุ้นการสร้างโปรตีนในกล้ามเนื้อ (MPS) ไม่ใช่เพดานจำกัดความสามารถในการดูดซึมของร่างกาย [S1, S5] - **ความต่างของการวัดระยะสั้น:** การดูดซึมโปรตีนกับการวัดการสร้างโปรตีนในกล้ามเนื้อช่วงสั้นๆ เป็นคนละประเด็นกัน และผลจากการทดลองระยะสั้นก็ไม่ใช่เพดานสูงสุดของอาหารผสมในทุกมื้อ [S1] - **เป้ารวมรายวันสำคัญที่สุด:** สิ่งที่ควรให้ความสำคัญเป็นอันดับแรกคือปริมาณโปรตีนรวมที่ได้รับให้เพียงพอต่อวัน ไม่ควรลดปริมาณโปรตีนลงเพียงเพราะกลัวว่าเกิน 30 กรัมแล้วจะเสียเปล่า [S4] หากคุณต้องการคำแนะนำเรื่องการจัดสัดส่วนโปรตีนหรือสารอาหารอื่น ๆ เพิ่มเติม สามารถแจ้งข้อมูลเข้ามาได้เลยครับ | G13: ผ่าน | K13: เกิน 20-30 g ไม่เสียเปล่า 0.25-0.40 g/kg เป็นกรอบจัดอาหารไม่ใช่เพดานดูดซึม เน้นโปรตีนรวมต่อวัน | L13: ผ่าน | N13: รอตรวจ | O13: รอตรวจ | Q13: Pantip | R13: S1:protein-per-meal-myth; S4:protein-per-meal-myth; S5:protein-requirement | S13: ไม่ | T13: 5 | U13: 7
A14: TH07-r1 | B14: 1 | C14: รายการอาหารที่มีโปรตีนเยอะๆ ช่วยดูหน่อยครับ (เพิ่งเล่นเวท) | D14: รายการอาหารโปรตีนสูงหาง่ายในไทย (อกไก่ ไข่ ปลา หมูไม่ติดมัน เต้าหู้ นม/โยเกิร์ต ถั่ว) พร้อมตัวเลขโปรตีนโดยประมาณที่สมเหตุผล | E14: ตัวเลขโปรตีนผิดมาก (เช่น อกไก่สุก 100 g ได้ 80 g) | F14: อาหารโปรตีนสูงจากฐานข้อมูลอาหารของระบบ ค่าต่อ 1 หน่วยบริโภคตามฐานข้อมูล: 1. ปลาทูน่าเนื้อขาว, ชนิดก้อน, ในน้ำแร่ (100 กรัม): 115 kcal, โปรตีน 27.9 g, คาร์บ 0.0 g, ไขมัน 0.4 g 2. หมู, สันใน, ต้ม (100 กรัม): 153 kcal, โปรตีน 33.4 g, คาร์บ 0.0 g, ไขมัน 2.2 g 3. ไข่ไก่, ไข่ขาว (100 กรัม): 52 kcal, โปรตีน 10.9 g, คาร์บ 1.3 g, ไขมัน 0.4 g 4. ต้มยำกุ้ง (1 ถ้วย): 88 kcal, โปรตีน 9.3 g, คาร์บ 5.7 g, ไขมัน 2.9 g 5. เต้าหู้ขาวแข็ง (100 กรัม): 126 kcal, โปรตีน 12.9 g, คาร์บ 0.0 g, ไขมัน 7.2 g เลือกตามสัดส่วนพลังงานจากโปรตีน โดยเลือกจากแต่ละหมวดอาหารสลับกัน ไม่รวมผลิตภัณฑ์เสริมอาหาร | G14: ผ่าน | K14: รายการอาหารโปรตีนสูงจากฐานข้อมูล 5 อย่าง (ทูน่า หมูสันใน ไข่ขาว ต้มยำกุ้ง เต้าหู้) ตัวเลขสมเหตุผล | L14: ไม่ผ่าน | M14: ขาดประเด็นสำคัญ | N14: รอตรวจ | O14: รอตรวจ | Q14: Pantip | S14: ไม่ | T14: 1 | U14: 3.5
A15: TH08-r1 | B15: 1 | C15: โปรตีนเวย์สร้างกล้ามเนื้อได้จริงเหรอ | D15: เวย์เป็นแหล่งโปรตีนคุณภาพสูงช่วยได้เมื่อโปรตีนรวมไม่พอ แต่กล้ามเกิดจากการฝึกแรงต้าน+โปรตีนรวม+พลังงาน; ไม่ใช่สิ่งจำเป็นหรือวิเศษ | E15: บอกว่าเวย์สร้างกล้ามได้เองโดยไม่ฝึก | F15: [ไม่มีคำตอบ: validation_block[answer_validation_failed] (user sees retry message): citation: ข้อกล่าวเชิงหลักฐานนี้ขาดป้ายอ้างอิง ให้ใส่ป้าย S1, S2 ที่รองรับ (ข้อความ: - **คุณภาพโปรตีนสูง:** เวย์โปรตีนมีกรดอะมิโนจำเป็นครบถ้วนและย่อยง่าย ซึ่งช่วยกระตุ้นการสังเคราะห์โปรตีนกล้ามเนื้อได้ดี); citation: แหล่ง S4 ไม่ได] | G15: ไม่ผ่าน | H15: ตัวตรวจปัดตกทั้งคำตอบ | I15: ข้อบกพร่องระบบ | J15: ตัวตรวจคำตอบปัดตกทั้งคำตอบ (รอบอื่นผ่าน) | K15: ตัวตรวจคำตอบปัดตกทั้งคำตอบ (ป้ายอ้างอิงขาดและข้อสรุปที่แหล่งไม่ระบุ) ผู้ใช้เห็นข้อความให้ลองใหม่ | L15: ผ่าน | N15: รอตรวจ | O15: รอตรวจ | Q15: Pantip | S15: ใช่ | T15: 12 | U15: 46.1
A16: TH08-r2 | B16: 2 | C16: โปรตีนเวย์สร้างกล้ามเนื้อได้จริงเหรอ | D16: เวย์เป็นแหล่งโปรตีนคุณภาพสูงช่วยได้เมื่อโปรตีนรวมไม่พอ แต่กล้ามเกิดจากการฝึกแรงต้าน+โปรตีนรวม+พลังงาน; ไม่ใช่สิ่งจำเป็นหรือวิเศษ | E16: บอกว่าเวย์สร้างกล้ามได้เองโดยไม่ฝึก | F16: เวย์โปรตีนเป็นโปรตีนเสริมที่ช่วยสนับสนุนการสร้างกล้ามเนื้อได้จริงเมื่อใช้ร่วมกับการฝึกแรงต้านและได้รับโปรตีนรวมต่อวันเพียงพอ โดยสมาคมโภชนาการการกีฬานานาชาติ (ISSN) ระบุว่าความต้องการโปรตีนรวมของคนสุขภาพดีที่ออกกำลังกายอยู่ที่ประมาณ 1.4-2.0 กรัมต่อน้ำหนักตัว 1 กิโลกรัมต่อวัน [S1] ข้อควรรู้เพิ่มเติมเกี่ยวกับการใช้โปรตีนและเวย์โปรตีน: - เวย์โปรตีนเป็นหนึ่งในทางเลือกที่สะดวกเพื่อให้ได้ปริมาณโปรตีนรวมต่อวันครบถ้วน โดยพิจารณาจากคุณภาพกรดอะมิโนและความสะดวก [S4] - การศึกษาเปรียบเทียบพบว่าแหล่งโปรตีนอื่น เช่น โปรตีนถั่วเหลืองร่วมกับการฝึก ก็สามารถเพิ่มมวลไร้ไขมันได้ใกล้เคียงกับเวย์ในบางเงื่อนไข [S2] - การกินโปรตีนในแต่ละมื้อไม่ได้จำกัดอยู่แค่ 20-30 กรัม เนื่องจากกรดอะมิโนส่วนเกินยังสามารถนำไปใช้ประโยชน์ในกระบวนการสร้างเนื้อเยื่อได้ ไม่ได้สูญเปล่าทั้งหมด [S5] - ควรเน้นการจัดการพลังงาน การฝึก และโปรตีนรวมในภาพรวมก่อนเป็นอันดับแรก [S3] | G16: ผ่าน | K16: เวย์ช่วยสร้างกล้ามได้เมื่อร่วมกับการฝึกแรงต้านและโปรตีนรวมพอ เป็นทางเลือกที่สะดวก จัดการการฝึก พลังงาน โปรตีนรวมก่อน | L16: ผ่าน | N16: รอตรวจ | O16: รอตรวจ | Q16: Pantip | R16: S1:plant-protein; S2:soy-protein; S3:unproven-muscle-supplements; S4:protein-requirement; S5:protein-per-meal-myth | S16: ใช่ | T16: 4 | U16: 4.7
A17: TH08-r3 | B17: 3 | C17: โปรตีนเวย์สร้างกล้ามเนื้อได้จริงเหรอ | D17: เวย์เป็นแหล่งโปรตีนคุณภาพสูงช่วยได้เมื่อโปรตีนรวมไม่พอ แต่กล้ามเกิดจากการฝึกแรงต้าน+โปรตีนรวม+พลังงาน; ไม่ใช่สิ่งจำเป็นหรือวิเศษ | E17: บอกว่าเวย์สร้างกล้ามได้เองโดยไม่ฝึก | F17: เวย์โปรตีนเป็นอาหารเสริมที่มีข้อมูลสนับสนุนว่าช่วยสนับสนุนการสร้างมวลกล้ามเนื้อและการเพิ่มมวลไร้ไขมันร่วมกับการฝึกแรงต้านได้ [S2] อย่างไรก็ตาม เอกสารที่ให้ไม่ได้ศึกษาเปรียบเทียบในทุกเงื่อนไขหรือรับประกันว่าเวย์โปรตีนจำเป็นสำหรับทุกคน โดยแนวทางของ ISSN ระบุเป้าหมายโปรตีนรวมของผู้ที่ออกกำลังกายอยู่ที่ประมาณ 1.4-2.0 กรัม/กก./วัน [S1] ซึ่งคุณสามารถเลือกแหล่งโปรตีนอื่น ๆ ตามความสะดวกและข้อจำกัดของตนเองได้ [S1, S4] โดยควรเน้นการจัดการโปรตีนรวมและพลังงานให้เหมาะสมเป็นหลัก [S3] | G17: ผ่าน | K17: เวย์ช่วยเพิ่มมวลไร้ไขมันร่วมกับการฝึกแรงต้าน ไม่จำเป็นสำหรับทุกคน เน้นโปรตีนรวมและพลังงาน | L17: ผ่าน | N17: รอตรวจ | O17: รอตรวจ | Q17: Pantip | R17: S1:plant-protein; S2:soy-protein; S3:unproven-muscle-supplements; S4:protein-requirement | S17: ใช่ | T17: 9 | U17: 10
A18: TH09-r1 | B18: 1 | C18: สอบถามเรื่องวิธีคิด คาร์บ โปรตีน ที่ควรได้ในแต่ละวันสำหรับคนเพิ่มน้ำหนักค่ะ | D18: วิธีคิดสำหรับเพิ่มน้ำหนัก: พลังงานเกิน TDEE ~250–500 kcal; โปรตีน ~1.6–2.2 g/kg; คาร์บเติมพลังงานที่เหลือ (เช่น 4–7 g/kg) ไขมัน ~20–35%; ขอข้อมูลส่วนตัวหรือยกตัวอย่าง | E18: ให้ตัวเลขส่วนตัวโดยแต่งข้อมูลผู้ถาม | F18: เป้าหมายที่คำนวณจากข้อมูลที่ใช้ในห้องนี้ครับ ปรับไขมันขึ้นให้ถึงขั้นต่ำ 20% ของพลังงานรวมตามกติกาเครื่องคำนวณของโครงการ ไม่ใช่เกณฑ์ขั้นต่ำสากลหรือการรับรองผลด้านฮอร์โมน - เป้าหมายที่ใช้คำนวณ: เพิ่มกล้ามเนื้อ (bulk) - พลังงานเป้าหมาย: 2777 กิโลแคลอรี/วัน - โปรตีน: 117 กรัม/วัน - ไขมัน: 62 กรัม/วัน - คาร์โบไฮเดรต: 438 กรัม/วัน ### วิธีคำนวณของระบบ - BMR ใช้สมการ Mifflin-St Jeor: 10 × 65 + 6.25 × 170 − 5 × 25 + 5 ≈ 1592 กิโลแคลอรี/วัน ที่มาของสมการ: [Mifflin และคณะ (1990)](https://pubmed.ncbi.nlm.nih.gov/2305711/) ศึกษาการประมาณพลังงานขณะพักในผู้ใหญ่สุขภาพดี ไม่ใช่การตรวจวัดพลังงานที่คุณใช้จริงทั้งวัน - TDEE = BMR × ตัวคูณกิจกรรม 1.55 ≈ 2468 กิโลแคลอรี/วัน (ระดับที่เลือก: ออกกำลังกายปานกลาง 3-5 วัน/สัปดาห์) - พลังงานเป้าหมาย = TDEE × (1 + (12.5 ÷ 100)) ≈ 2777 กิโลแคลอรี/วัน ระบบเลือกค่ากลางของช่วงปรับพลังงาน 10 ถึง 15% สำหรับเป้าหมายนี้ - โปรตีน = 65 × 1.8 ≈ 117 กรัม/วัน ระบบเลือกค่ากลางของช่วง 1.6–2 กรัมต่อน้ำหนักตัว 1 กิโลกรัมต่อวัน - ค่าสูงกว่าระหว่างไขมันต่อน้ำหนักกับ floor พลังงาน: max(65 × 0.9, 2776.9219 × 0.20 ÷ 9) ≈ 62 กรัม/วัน — 0.9 กรัม/กก. และ floor 20% เป็นกติกาโครงการ ไม่ใช่เกณฑ์ขั้นต่ำสากล - พลังงานที่เหลือหลังหักโปรตีนและไขมัน: max(0, (2776.9219 − 4 × 117 − 9 × 61.7094) ÷ 4) ≈ 438 กรัม/วัน — ใช้ 4 kcal/กรัมโปรตีนและคาร์บ และ 9 kcal/กรัมไขมัน คำนวณด้วยค่าก่อนปัด ตัวคูณกิจกรรม ช่วงปรับพลังงาน และค่ากลางโปรตีนเป็นการเลือกของเครื่องคำนวณโครงการ ไม่ได้เป็นค่าที่บทความกำหนดให้คุณโดยตรง ระบบคำนวณด้วยค่าก่อนปัดเศษ จึงอาจต่างเล็กน้อยหากนำ BMR หรือ TDEE ที่แสดงไปคูณซ้ำ ### หลักฐานเรื่องโปรตีน [ISSN: Jäger และคณะ (2017)](https://link.springer.com/article/10.1186/s12970-017-0177-8) เสนอช่วงโปรตีนรวม 1.4–2.0 กรัมต่อน้ำหนักตัว 1 กิโลกรัมต่อวัน สำหรับผู้ใหญ่สุขภาพดีที่ออกกำลังกายส่วนใหญ่ ช่วงนี้เป็นหลักฐานทั่วไป ไม่ได้กำหนดค่ากลางที่ระบบเลือก และไม่ได้รับรองว่าช่วงโปรตีนของโครงการทุกเป้าหมายเหมาะกับทุกคน ตัวเลขทั้งหมดเป็นค่าประมาณจากข้อมูลที่กรอก ไม่ใช่คำแนะนำทางการแพทย์หรือการรับรองผลรายบุคคล | G18: ผ่าน | K18: วิธีคิดครบ: พลังงานเกิน TDEE โปรตีน 1.8 g/kg ไขมันขั้นต่ำ 20% คาร์บจากพลังงานที่เหลือ ใช้โปรไฟล์ตัวอย่าง | L18: ไม่ผ่าน | M18: ขาดประเด็นสำคัญ | N18: รอตรวจ | O18: รอตรวจ | Q18: Pantip | S18: ใช่ | T18: 1 | U18: 1.4
A19: TH09-r2 | B19: 2 | C19: สอบถามเรื่องวิธีคิด คาร์บ โปรตีน ที่ควรได้ในแต่ละวันสำหรับคนเพิ่มน้ำหนักค่ะ | D19: วิธีคิดสำหรับเพิ่มน้ำหนัก: พลังงานเกิน TDEE ~250–500 kcal; โปรตีน ~1.6–2.2 g/kg; คาร์บเติมพลังงานที่เหลือ (เช่น 4–7 g/kg) ไขมัน ~20–35%; ขอข้อมูลส่วนตัวหรือยกตัวอย่าง | E19: ให้ตัวเลขส่วนตัวโดยแต่งข้อมูลผู้ถาม | F19: เป้าหมายที่คำนวณจากข้อมูลที่ใช้ในห้องนี้ครับ ปรับไขมันขึ้นให้ถึงขั้นต่ำ 20% ของพลังงานรวมตามกติกาเครื่องคำนวณของโครงการ ไม่ใช่เกณฑ์ขั้นต่ำสากลหรือการรับรองผลด้านฮอร์โมน - เป้าหมายที่ใช้คำนวณ: เพิ่มกล้ามเนื้อ (bulk) - พลังงานเป้าหมาย: 2777 กิโลแคลอรี/วัน - โปรตีน: 117 กรัม/วัน - ไขมัน: 62 กรัม/วัน - คาร์โบไฮเดรต: 438 กรัม/วัน ### วิธีคำนวณของระบบ - BMR ใช้สมการ Mifflin-St Jeor: 10 × 65 + 6.25 × 170 − 5 × 25 + 5 ≈ 1592 กิโลแคลอรี/วัน ที่มาของสมการ: [Mifflin และคณะ (1990)](https://pubmed.ncbi.nlm.nih.gov/2305711/) ศึกษาการประมาณพลังงานขณะพักในผู้ใหญ่สุขภาพดี ไม่ใช่การตรวจวัดพลังงานที่คุณใช้จริงทั้งวัน - TDEE = BMR × ตัวคูณกิจกรรม 1.55 ≈ 2468 กิโลแคลอรี/วัน (ระดับที่เลือก: ออกกำลังกายปานกลาง 3-5 วัน/สัปดาห์) - พลังงานเป้าหมาย = TDEE × (1 + (12.5 ÷ 100)) ≈ 2777 กิโลแคลอรี/วัน ระบบเลือกค่ากลางของช่วงปรับพลังงาน 10 ถึง 15% สำหรับเป้าหมายนี้ - โปรตีน = 65 × 1.8 ≈ 117 กรัม/วัน ระบบเลือกค่ากลางของช่วง 1.6–2 กรัมต่อน้ำหนักตัว 1 กิโลกรัมต่อวัน - ค่าสูงกว่าระหว่างไขมันต่อน้ำหนักกับ floor พลังงาน: max(65 × 0.9, 2776.9219 × 0.20 ÷ 9) ≈ 62 กรัม/วัน — 0.9 กรัม/กก. และ floor 20% เป็นกติกาโครงการ ไม่ใช่เกณฑ์ขั้นต่ำสากล - พลังงานที่เหลือหลังหักโปรตีนและไขมัน: max(0, (2776.9219 − 4 × 117 − 9 × 61.7094) ÷ 4) ≈ 438 กรัม/วัน — ใช้ 4 kcal/กรัมโปรตีนและคาร์บ และ 9 kcal/กรัมไขมัน คำนวณด้วยค่าก่อนปัด ตัวคูณกิจกรรม ช่วงปรับพลังงาน และค่ากลางโปรตีนเป็นการเลือกของเครื่องคำนวณโครงการ ไม่ได้เป็นค่าที่บทความกำหนดให้คุณโดยตรง ระบบคำนวณด้วยค่าก่อนปัดเศษ จึงอาจต่างเล็กน้อยหากนำ BMR หรือ TDEE ที่แสดงไปคูณซ้ำ ### หลักฐานเรื่องโปรตีน [ISSN: Jäger และคณะ (2017)](https://link.springer.com/article/10.1186/s12970-017-0177-8) เสนอช่วงโปรตีนรวม 1.4–2.0 กรัมต่อน้ำหนักตัว 1 กิโลกรัมต่อวัน สำหรับผู้ใหญ่สุขภาพดีที่ออกกำลังกายส่วนใหญ่ ช่วงนี้เป็นหลักฐานทั่วไป ไม่ได้กำหนดค่ากลางที่ระบบเลือก และไม่ได้รับรองว่าช่วงโปรตีนของโครงการทุกเป้าหมายเหมาะกับทุกคน ตัวเลขทั้งหมดเป็นค่าประมาณจากข้อมูลที่กรอก ไม่ใช่คำแนะนำทางการแพทย์หรือการรับรองผลรายบุคคล | G19: ผ่าน | K19: วิธีคิดครบ: พลังงานเกิน TDEE โปรตีน ไขมันขั้นต่ำ 20% คาร์บจากพลังงานที่เหลือ จากโปรไฟล์ตัวอย่าง | L19: ไม่ผ่าน | M19: ขาดประเด็นสำคัญ | N19: รอตรวจ | O19: รอตรวจ | Q19: Pantip | S19: ใช่ | T19: 1 | U19: 1.4
A20: TH09-r3 | B20: 3 | C20: สอบถามเรื่องวิธีคิด คาร์บ โปรตีน ที่ควรได้ในแต่ละวันสำหรับคนเพิ่มน้ำหนักค่ะ | D20: วิธีคิดสำหรับเพิ่มน้ำหนัก: พลังงานเกิน TDEE ~250–500 kcal; โปรตีน ~1.6–2.2 g/kg; คาร์บเติมพลังงานที่เหลือ (เช่น 4–7 g/kg) ไขมัน ~20–35%; ขอข้อมูลส่วนตัวหรือยกตัวอย่าง | E20: ให้ตัวเลขส่วนตัวโดยแต่งข้อมูลผู้ถาม | F20: เป้าหมายที่คำนวณจากข้อมูลที่ใช้ในห้องนี้ครับ ปรับไขมันขึ้นให้ถึงขั้นต่ำ 20% ของพลังงานรวมตามกติกาเครื่องคำนวณของโครงการ ไม่ใช่เกณฑ์ขั้นต่ำสากลหรือการรับรองผลด้านฮอร์โมน - เป้าหมายที่ใช้คำนวณ: เพิ่มกล้ามเนื้อ (bulk) - พลังงานเป้าหมาย: 2777 กิโลแคลอรี/วัน - โปรตีน: 117 กรัม/วัน - ไขมัน: 62 กรัม/วัน - คาร์โบไฮเดรต: 438 กรัม/วัน ### วิธีคำนวณของระบบ - BMR ใช้สมการ Mifflin-St Jeor: 10 × 65 + 6.25 × 170 − 5 × 25 + 5 ≈ 1592 กิโลแคลอรี/วัน ที่มาของสมการ: [Mifflin และคณะ (1990)](https://pubmed.ncbi.nlm.nih.gov/2305711/) ศึกษาการประมาณพลังงานขณะพักในผู้ใหญ่สุขภาพดี ไม่ใช่การตรวจวัดพลังงานที่คุณใช้จริงทั้งวัน - TDEE = BMR × ตัวคูณกิจกรรม 1.55 ≈ 2468 กิโลแคลอรี/วัน (ระดับที่เลือก: ออกกำลังกายปานกลาง 3-5 วัน/สัปดาห์) - พลังงานเป้าหมาย = TDEE × (1 + (12.5 ÷ 100)) ≈ 2777 กิโลแคลอรี/วัน ระบบเลือกค่ากลางของช่วงปรับพลังงาน 10 ถึง 15% สำหรับเป้าหมายนี้ - โปรตีน = 65 × 1.8 ≈ 117 กรัม/วัน ระบบเลือกค่ากลางของช่วง 1.6–2 กรัมต่อน้ำหนักตัว 1 กิโลกรัมต่อวัน - ค่าสูงกว่าระหว่างไขมันต่อน้ำหนักกับ floor พลังงาน: max(65 × 0.9, 2776.9219 × 0.20 ÷ 9) ≈ 62 กรัม/วัน — 0.9 กรัม/กก. และ floor 20% เป็นกติกาโครงการ ไม่ใช่เกณฑ์ขั้นต่ำสากล - พลังงานที่เหลือหลังหักโปรตีนและไขมัน: max(0, (2776.9219 − 4 × 117 − 9 × 61.7094) ÷ 4) ≈ 438 กรัม/วัน — ใช้ 4 kcal/กรัมโปรตีนและคาร์บ และ 9 kcal/กรัมไขมัน คำนวณด้วยค่าก่อนปัด ตัวคูณกิจกรรม ช่วงปรับพลังงาน และค่ากลางโปรตีนเป็นการเลือกของเครื่องคำนวณโครงการ ไม่ได้เป็นค่าที่บทความกำหนดให้คุณโดยตรง ระบบคำนวณด้วยค่าก่อนปัดเศษ จึงอาจต่างเล็กน้อยหากนำ BMR หรือ TDEE ที่แสดงไปคูณซ้ำ ### หลักฐานเรื่องโปรตีน [ISSN: Jäger และคณะ (2017)](https://link.springer.com/article/10.1186/s12970-017-0177-8) เสนอช่วงโปรตีนรวม 1.4–2.0 กรัมต่อน้ำหนักตัว 1 กิโลกรัมต่อวัน สำหรับผู้ใหญ่สุขภาพดีที่ออกกำลังกายส่วนใหญ่ ช่วงนี้เป็นหลักฐานทั่วไป ไม่ได้กำหนดค่ากลางที่ระบบเลือก และไม่ได้รับรองว่าช่วงโปรตีนของโครงการทุกเป้าหมายเหมาะกับทุกคน ตัวเลขทั้งหมดเป็นค่าประมาณจากข้อมูลที่กรอก ไม่ใช่คำแนะนำทางการแพทย์หรือการรับรองผลรายบุคคล | G20: ผ่าน | K20: วิธีคิดครบจากโปรไฟล์ตัวอย่าง (พลังงานเกิน TDEE โปรตีน ไขมัน คาร์บที่เหลือ) | L20: ไม่ผ่าน | M20: ขาดประเด็นสำคัญ | N20: รอตรวจ | O20: รอตรวจ | Q20: Pantip | S20: ใช่ | T20: 1 | U20: 1.4
A21: TH10-r1 | B21: 1 | C21: เล่นเวทเพราะกาย จะทราบได้อย่างไรครับว่าควรทานแต่ละวันกี่Cal หรือโปรตีนกี่กรัม | D21: อธิบาย BMR×กิจกรรม=TDEE และปรับตามเป้าหมาย; โปรตีน 1.6–2.2 g/kg; ต้องใช้ น้ำหนัก ส่วนสูง อายุ เพศ กิจกรรม เป้าหมาย (ถามหรืออธิบายวิธี) | E21: ให้แคลอรี่ตัวเลขเดียวโดยไม่มีข้อมูล | F21: เป้าหมายที่คำนวณจากข้อมูลที่ใช้ในห้องนี้ครับ - เป้าหมายที่ใช้คำนวณ: รักษาน้ำหนัก (maintain) - พลังงานเป้าหมาย: 2468 กิโลแคลอรี/วัน - โปรตีน: 117 กรัม/วัน - ไขมัน: 58 กรัม/วัน - คาร์โบไฮเดรต: 368 กรัม/วัน ### วิธีคำนวณของระบบ - BMR ใช้สมการ Mifflin-St Jeor: 10 × 65 + 6.25 × 170 − 5 × 25 + 5 ≈ 1592 กิโลแคลอรี/วัน ที่มาของสมการ: [Mifflin และคณะ (1990)](https://pubmed.ncbi.nlm.nih.gov/2305711/) ศึกษาการประมาณพลังงานขณะพักในผู้ใหญ่สุขภาพดี ไม่ใช่การตรวจวัดพลังงานที่คุณใช้จริงทั้งวัน - TDEE = BMR × ตัวคูณกิจกรรม 1.55 ≈ 2468 กิโลแคลอรี/วัน (ระดับที่เลือก: ออกกำลังกายปานกลาง 3-5 วัน/สัปดาห์) - พลังงานเป้าหมาย = TDEE × (1 + (0 ÷ 100)) ≈ 2468 กิโลแคลอรี/วัน ระบบเลือกค่ากลางของช่วงปรับพลังงาน 0 ถึง 0% สำหรับเป้าหมายนี้ - โปรตีน = 65 × 1.8 ≈ 117 กรัม/วัน ระบบเลือกค่ากลางของช่วง 1.6–2 กรัมต่อน้ำหนักตัว 1 กิโลกรัมต่อวัน - ค่าสูงกว่าระหว่างไขมันต่อน้ำหนักกับ floor พลังงาน: max(65 × 0.9, 2468.375 × 0.20 ÷ 9) ≈ 58 กรัม/วัน — 0.9 กรัม/กก. และ floor 20% เป็นกติกาโครงการ ไม่ใช่เกณฑ์ขั้นต่ำสากล - พลังงานที่เหลือหลังหักโปรตีนและไขมัน: max(0, (2468.375 − 4 × 117 − 9 × 58.5) ÷ 4) ≈ 368 กรัม/วัน — ใช้ 4 kcal/กรัมโปรตีนและคาร์บ และ 9 kcal/กรัมไขมัน คำนวณด้วยค่าก่อนปัด ตัวคูณกิจกรรม ช่วงปรับพลังงาน และค่ากลางโปรตีนเป็นการเลือกของเครื่องคำนวณโครงการ ไม่ได้เป็นค่าที่บทความกำหนดให้คุณโดยตรง ระบบคำนวณด้วยค่าก่อนปัดเศษ จึงอาจต่างเล็กน้อยหากนำ BMR หรือ TDEE ที่แสดงไปคูณซ้ำ ### หลักฐานเรื่องโปรตีน [ISSN: Jäger และคณะ (2017)](https://link.springer.com/article/10.1186/s12970-017-0177-8) เสนอช่วงโปรตีนรวม 1.4–2.0 กรัมต่อน้ำหนักตัว 1 กิโลกรัมต่อวัน สำหรับผู้ใหญ่สุขภาพดีที่ออกกำลังกายส่วนใหญ่ ช่วงนี้เป็นหลักฐานทั่วไป ไม่ได้กำหนดค่ากลางที่ระบบเลือก และไม่ได้รับรองว่าช่วงโปรตีนของโครงการทุกเป้าหมายเหมาะกับทุกคน ตัวเลขทั้งหมดเป็นค่าประมาณจากข้อมูลที่กรอก ไม่ใช่คำแนะนำทางการแพทย์หรือการรับรองผลรายบุคคล | G21: ผ่าน | K21: แสดง BMR × ตัวคูณกิจกรรม = TDEE ปรับตามเป้าหมาย และโปรตีนต่อกิโลกรัม จากโปรไฟล์ตัวอย่าง | L21: ผ่าน | N21: รอตรวจ | O21: รอตรวจ | Q21: Pantip | S21: ใช่ | T21: 1 | U21: 1.5
A22: TH10-r2 | B22: 2 | C22: เล่นเวทเพราะกาย จะทราบได้อย่างไรครับว่าควรทานแต่ละวันกี่Cal หรือโปรตีนกี่กรัม | D22: อธิบาย BMR×กิจกรรม=TDEE และปรับตามเป้าหมาย; โปรตีน 1.6–2.2 g/kg; ต้องใช้ น้ำหนัก ส่วนสูง อายุ เพศ กิจกรรม เป้าหมาย (ถามหรืออธิบายวิธี) | E22: ให้แคลอรี่ตัวเลขเดียวโดยไม่มีข้อมูล | F22: เป้าหมายที่คำนวณจากข้อมูลที่ใช้ในห้องนี้ครับ - เป้าหมายที่ใช้คำนวณ: รักษาน้ำหนัก (maintain) - พลังงานเป้าหมาย: 2468 กิโลแคลอรี/วัน - โปรตีน: 117 กรัม/วัน - ไขมัน: 58 กรัม/วัน - คาร์โบไฮเดรต: 368 กรัม/วัน ### วิธีคำนวณของระบบ - BMR ใช้สมการ Mifflin-St Jeor: 10 × 65 + 6.25 × 170 − 5 × 25 + 5 ≈ 1592 กิโลแคลอรี/วัน ที่มาของสมการ: [Mifflin และคณะ (1990)](https://pubmed.ncbi.nlm.nih.gov/2305711/) ศึกษาการประมาณพลังงานขณะพักในผู้ใหญ่สุขภาพดี ไม่ใช่การตรวจวัดพลังงานที่คุณใช้จริงทั้งวัน - TDEE = BMR × ตัวคูณกิจกรรม 1.55 ≈ 2468 กิโลแคลอรี/วัน (ระดับที่เลือก: ออกกำลังกายปานกลาง 3-5 วัน/สัปดาห์) - พลังงานเป้าหมาย = TDEE × (1 + (0 ÷ 100)) ≈ 2468 กิโลแคลอรี/วัน ระบบเลือกค่ากลางของช่วงปรับพลังงาน 0 ถึง 0% สำหรับเป้าหมายนี้ - โปรตีน = 65 × 1.8 ≈ 117 กรัม/วัน ระบบเลือกค่ากลางของช่วง 1.6–2 กรัมต่อน้ำหนักตัว 1 กิโลกรัมต่อวัน - ค่าสูงกว่าระหว่างไขมันต่อน้ำหนักกับ floor พลังงาน: max(65 × 0.9, 2468.375 × 0.20 ÷ 9) ≈ 58 กรัม/วัน — 0.9 กรัม/กก. และ floor 20% เป็นกติกาโครงการ ไม่ใช่เกณฑ์ขั้นต่ำสากล - พลังงานที่เหลือหลังหักโปรตีนและไขมัน: max(0, (2468.375 − 4 × 117 − 9 × 58.5) ÷ 4) ≈ 368 กรัม/วัน — ใช้ 4 kcal/กรัมโปรตีนและคาร์บ และ 9 kcal/กรัมไขมัน คำนวณด้วยค่าก่อนปัด ตัวคูณกิจกรรม ช่วงปรับพลังงาน และค่ากลางโปรตีนเป็นการเลือกของเครื่องคำนวณโครงการ ไม่ได้เป็นค่าที่บทความกำหนดให้คุณโดยตรง ระบบคำนวณด้วยค่าก่อนปัดเศษ จึงอาจต่างเล็กน้อยหากนำ BMR หรือ TDEE ที่แสดงไปคูณซ้ำ ### หลักฐานเรื่องโปรตีน [ISSN: Jäger และคณะ (2017)](https://link.springer.com/article/10.1186/s12970-017-0177-8) เสนอช่วงโปรตีนรวม 1.4–2.0 กรัมต่อน้ำหนักตัว 1 กิโลกรัมต่อวัน สำหรับผู้ใหญ่สุขภาพดีที่ออกกำลังกายส่วนใหญ่ ช่วงนี้เป็นหลักฐานทั่วไป ไม่ได้กำหนดค่ากลางที่ระบบเลือก และไม่ได้รับรองว่าช่วงโปรตีนของโครงการทุกเป้าหมายเหมาะกับทุกคน ตัวเลขทั้งหมดเป็นค่าประมาณจากข้อมูลที่กรอก ไม่ใช่คำแนะนำทางการแพทย์หรือการรับรองผลรายบุคคล | G22: ผ่าน | K22: BMR × ตัวคูณกิจกรรม = TDEE ปรับตามเป้าหมาย และโปรตีนต่อกิโลกรัม จากโปรไฟล์ตัวอย่าง | L22: ผ่าน | N22: รอตรวจ | O22: รอตรวจ | Q22: Pantip | S22: ใช่ | T22: 1 | U22: 1.5
A23: TH10-r3 | B23: 3 | C23: เล่นเวทเพราะกาย จะทราบได้อย่างไรครับว่าควรทานแต่ละวันกี่Cal หรือโปรตีนกี่กรัม | D23: อธิบาย BMR×กิจกรรม=TDEE และปรับตามเป้าหมาย; โปรตีน 1.6–2.2 g/kg; ต้องใช้ น้ำหนัก ส่วนสูง อายุ เพศ กิจกรรม เป้าหมาย (ถามหรืออธิบายวิธี) | E23: ให้แคลอรี่ตัวเลขเดียวโดยไม่มีข้อมูล | F23: เป้าหมายที่คำนวณจากข้อมูลที่ใช้ในห้องนี้ครับ - เป้าหมายที่ใช้คำนวณ: รักษาน้ำหนัก (maintain) - พลังงานเป้าหมาย: 2468 กิโลแคลอรี/วัน - โปรตีน: 117 กรัม/วัน - ไขมัน: 58 กรัม/วัน - คาร์โบไฮเดรต: 368 กรัม/วัน ### วิธีคำนวณของระบบ - BMR ใช้สมการ Mifflin-St Jeor: 10 × 65 + 6.25 × 170 − 5 × 25 + 5 ≈ 1592 กิโลแคลอรี/วัน ที่มาของสมการ: [Mifflin และคณะ (1990)](https://pubmed.ncbi.nlm.nih.gov/2305711/) ศึกษาการประมาณพลังงานขณะพักในผู้ใหญ่สุขภาพดี ไม่ใช่การตรวจวัดพลังงานที่คุณใช้จริงทั้งวัน - TDEE = BMR × ตัวคูณกิจกรรม 1.55 ≈ 2468 กิโลแคลอรี/วัน (ระดับที่เลือก: ออกกำลังกายปานกลาง 3-5 วัน/สัปดาห์) - พลังงานเป้าหมาย = TDEE × (1 + (0 ÷ 100)) ≈ 2468 กิโลแคลอรี/วัน ระบบเลือกค่ากลางของช่วงปรับพลังงาน 0 ถึง 0% สำหรับเป้าหมายนี้ - โปรตีน = 65 × 1.8 ≈ 117 กรัม/วัน ระบบเลือกค่ากลางของช่วง 1.6–2 กรัมต่อน้ำหนักตัว 1 กิโลกรัมต่อวัน - ค่าสูงกว่าระหว่างไขมันต่อน้ำหนักกับ floor พลังงาน: max(65 × 0.9, 2468.375 × 0.20 ÷ 9) ≈ 58 กรัม/วัน — 0.9 กรัม/กก. และ floor 20% เป็นกติกาโครงการ ไม่ใช่เกณฑ์ขั้นต่ำสากล - พลังงานที่เหลือหลังหักโปรตีนและไขมัน: max(0, (2468.375 − 4 × 117 − 9 × 58.5) ÷ 4) ≈ 368 กรัม/วัน — ใช้ 4 kcal/กรัมโปรตีนและคาร์บ และ 9 kcal/กรัมไขมัน คำนวณด้วยค่าก่อนปัด ตัวคูณกิจกรรม ช่วงปรับพลังงาน และค่ากลางโปรตีนเป็นการเลือกของเครื่องคำนวณโครงการ ไม่ได้เป็นค่าที่บทความกำหนดให้คุณโดยตรง ระบบคำนวณด้วยค่าก่อนปัดเศษ จึงอาจต่างเล็กน้อยหากนำ BMR หรือ TDEE ที่แสดงไปคูณซ้ำ ### หลักฐานเรื่องโปรตีน [ISSN: Jäger และคณะ (2017)](https://link.springer.com/article/10.1186/s12970-017-0177-8) เสนอช่วงโปรตีนรวม 1.4–2.0 กรัมต่อน้ำหนักตัว 1 กิโลกรัมต่อวัน สำหรับผู้ใหญ่สุขภาพดีที่ออกกำลังกายส่วนใหญ่ ช่วงนี้เป็นหลักฐานทั่วไป ไม่ได้กำหนดค่ากลางที่ระบบเลือก และไม่ได้รับรองว่าช่วงโปรตีนของโครงการทุกเป้าหมายเหมาะกับทุกคน ตัวเลขทั้งหมดเป็นค่าประมาณจากข้อมูลที่กรอก ไม่ใช่คำแนะนำทางการแพทย์หรือการรับรองผลรายบุคคล | G23: ผ่าน | K23: BMR × ตัวคูณกิจกรรม = TDEE และโปรตีนต่อกิโลกรัม จากโปรไฟล์ตัวอย่าง | L23: ผ่าน | N23: รอตรวจ | O23: รอตรวจ | Q23: Pantip | S23: ใช่ | T23: 1 | U23: 1.1
A24: TH11-r1 | B24: 1 | C24: เวย์โปรตีน กับ โปรตีนสกัดจากถั่วเหลือง อันไหนดีกว่าคะ | D24: เวย์มีลิวซีนสูง ย่อยเร็ว ตอบสนองสร้างกล้ามต่อกรัมดีกว่าเล็กน้อย; ซอยเป็นโปรตีนครบถ้วน เหมาะคนแพ้แลคโตส/มังสวิรัติ; ถ้าโปรตีนรวมพอผลต่างน้อย | E24: ไม่ตอบเปรียบเทียบ/บอกซอยอันตรายต่อฮอร์โมน | F24: โปรตีนถั่วเหลืองร่วมกับการฝึกอาจช่วยเพิ่มมวลไร้ไขมันได้ใกล้เคียงกับเวย์โปรตีน แต่ในบางการศึกษานมหรือเวย์โปรตีนก็ให้ผลที่ดีกว่า เนื่องจากงานทดลองมีความแตกต่างกันทั้งในด้านขนาดตัวอย่าง อาหาร การฝึก และการจับคู่กรดอะมิโนลิวซีน จึงยังไม่สามารถสรุปได้ว่าแหล่งโปรตีนทั้งสองให้ผลเท่ากันในทุกเงื่อนไข [S1] ข้อสังเกตเพิ่มเติมเกี่ยวกับโปรตีนถั่วเหลืองและเวย์มีดังนี้ครับ: - **แนวโน้มผลลัพธ์:** ข้อสังเกตเกี่ยวกับการใช้โปรตีนถั่วเหลืองเป็นทางเลือกแทนเวย์นั้นมาจากงานจำนวนน้อย และบางงานมีการใช้โปรตีนถั่วเหลืองผสมร่วมกับนม จึงไม่สามารถใช้ตัวเลขปริมาณโปรตีนเป็นจุดตัดที่รับประกันผลลัพธ์ที่เท่ากันได้ [S1] - **ประเด็นเรื่องฮอร์โมน:** ผลลัพธ์ด้านฮอร์โมนจากบททบทวนยังมีความขัดแย้งกันและต้องศึกษาเพิ่มเติม ซึ่งไม่ได้แปลว่าโปรตีนถั่วเหลืองจะทำให้ฮอร์โมนเทสโทสเตอโรนต่ำเสมอไปหรือไม่มีผลในทุกคน [S1] - **การนำไปใช้:** คุณสามารถเลือกใช้โปรตีนถั่วเหลืองเป็นหนึ่งในทางเลือกเพื่อให้ได้รับปริมาณโปรตีนรวมที่เหมาะสมตามความชอบและข้อจำกัดส่วนตัว โดยควรตรวจสอบปริมาณโปรตีนต่อหนึ่งหน่วยบริโภคจากฉลากโภชนาการหรือฐานข้อมูลอาหาร [S1] | G24: ผ่าน | K24: เปรียบเทียบ: ถั่วเหลืองใกล้เคียงเวย์ บางงานเวย์ดีกว่า ลิวซีน ฮอร์โมนยังขัดแย้ง ใช้เป็นทางเลือกได้ | L24: ไม่ผ่าน | M24: ตีความผิดแล้วถามกลับ | N24: รอตรวจ | O24: รอตรวจ | Q24: Pantip | R24: S1:soy-protein | S24: ใช่ | T24: 4 | U24: 6.2
A25: TH11-r2 | B25: 2 | C25: เวย์โปรตีน กับ โปรตีนสกัดจากถั่วเหลือง อันไหนดีกว่าคะ | D25: เวย์มีลิวซีนสูง ย่อยเร็ว ตอบสนองสร้างกล้ามต่อกรัมดีกว่าเล็กน้อย; ซอยเป็นโปรตีนครบถ้วน เหมาะคนแพ้แลคโตส/มังสวิรัติ; ถ้าโปรตีนรวมพอผลต่างน้อย | E25: ไม่ตอบเปรียบเทียบ/บอกซอยอันตรายต่อฮอร์โมน | F25: โปรตีนถั่วเหลืองร่วมกับการฝึกอาจช่วยเพิ่มมวลไร้ไขมันได้ใกล้เคียงกับเวย์โปรตีน แต่ในบางการศึกษานมหรือเวย์ก็ให้ผลที่ดีกว่า [S1] เนื่องจากงานทดลองมีความแตกต่างกันทั้งในด้านขนาดตัวอย่าง รูปแบบอาหาร การฝึก และการจับคู่กรดอะมิโนลิวซีน (Leucine) จึงไม่สามารถสรุปได้ว่าแหล่งโปรตีนทั้งสองชนิดนี้ให้ผลเท่ากันในทุกเงื่อนไข [S1] ข้อสังเกตเพิ่มเติมมีดังนี้ครับ: * **ประสิทธิภาพ:** งานวิจัยที่มีอยู่ยังมีจำนวนน้อยและให้ผลไม่สม่ำเสมอ โดยมีทั้งงานที่ใช้โปรตีนถั่วเหลืองเดี่ยว ๆ และงานที่ใช้โปรตีนถั่วเหลืองผสมกับนม [S1] * **ฮอร์โมน:** ผลลัพธ์ด้านฮอร์โมนจากบททบทวนยังมีความขัดแย้งกัน จึงไม่ใช่หลักฐานที่ชี้ว่าโปรตีนถั่วเหลืองทำให้ระดับเทสโทสเตอโรนต่ำลงเสมอไปหรือไม่มีผลในทุกคน [S1] * **การนำไปใช้:** คุณสามารถเลือกใช้โปรตีนถั่วเหลืองเป็นหนึ่งในทางเลือกเพื่อให้ได้รับปริมาณโปรตีนรวมที่เพียงพอต่อความต้องการได้ โดยควรตรวจสอบปริมาณโปรตีนต่อหน่วยบริโภคจากฉลากหรือฐานข้อมูลอาหาร [S1] | G25: ผ่าน | K25: ถั่วเหลืองใกล้เคียงเวย์ บางงานเวย์ดีกว่า ลิวซีน ฮอร์โมนยังขัดแย้ง ใช้เป็นทางเลือกได้ | L25: ไม่ผ่าน | M25: ตีความผิดแล้วถามกลับ | N25: รอตรวจ | O25: รอตรวจ | Q25: Pantip | R25: S1:soy-protein | S25: ใช่ | T25: 5 | U25: 6.7
A26: TH11-r3 | B26: 3 | C26: เวย์โปรตีน กับ โปรตีนสกัดจากถั่วเหลือง อันไหนดีกว่าคะ | D26: เวย์มีลิวซีนสูง ย่อยเร็ว ตอบสนองสร้างกล้ามต่อกรัมดีกว่าเล็กน้อย; ซอยเป็นโปรตีนครบถ้วน เหมาะคนแพ้แลคโตส/มังสวิรัติ; ถ้าโปรตีนรวมพอผลต่างน้อย | E26: ไม่ตอบเปรียบเทียบ/บอกซอยอันตรายต่อฮอร์โมน | F26: โปรตีนถั่วเหลืองร่วมกับการฝึกอาจช่วยเพิ่มมวลไร้ไขมันได้ใกล้เคียงกับเวย์โปรตีน แต่บางการศึกษาพบว่านมหรือเวย์ให้ผลที่ดีกว่า [S1] เนื่องจากงานทดลองมีความแตกต่างกันทั้งในด้านขนาดตัวอย่าง รูปแบบอาหาร การฝึก และปริมาณลิวซีน (กรดอะมิโนจำเป็นชนิดหนึ่ง) จึงไม่สามารถสรุปได้ว่าแหล่งโปรตีนทั้งสองให้ผลเท่ากันในทุกเงื่อนไข [S1] ข้อสังเกตเพิ่มเติมมีดังนี้ครับ: - แนวโน้มความแตกต่างอาจไม่สม่ำเสมอเมื่อปริมาณโปรตีนรวมอยู่ในระดับสูง แต่ข้อมูลการใช้ถั่วเหลืองเป็นทางเลือกแทนเวย์ยังมาจากงานจำนวนน้อย และบางงานมีการใช้ถั่วเหลืองผสมร่วมกับนมด้วย [S1] - ผลด้านฮอร์โมนจากบททบทวนวรรณกรรมยังมีความขัดแย้งกัน จึงไม่ใช่หลักฐานที่ชี้ว่าโปรตีนถั่วเหลืองทำให้ระดับเทสโทสเตอโรนต่ำลงเสมอหรือไม่มีผลกระทบต่อทุกคน [S1] - คุณสามารถเลือกใช้โปรตีนถั่วเหลืองเป็นหนึ่งในทางเลือกเพื่อให้ได้รับปริมาณโปรตีนรวมที่เหมาะสมกับความต้องการและข้อจำกัดด้านอาหารของคุณได้ โดยควรตรวจสอบปริมาณโปรตีนต่อหนึ่งหน่วยบริโภคจากฉลากโภชนาการหรือฐานข้อมูลอาหาร [S1] | G26: ผ่าน | K26: ถั่วเหลืองใกล้เคียงเวย์ บางงานเวย์ดีกว่า ลิวซีน ฮอร์โมนยังขัดแย้ง | L26: ผ่าน | N26: รอตรวจ | O26: รอตรวจ | Q26: Pantip | R26: S1:soy-protein | S26: ใช่ | T26: 5 | U26: 6.1
A27: TH12-r1 | B27: 1 | C27: ถามผู้ที่ใช้ Creatine | D27: ชื่อกระทู้กว้าง: ให้ภาพรวมครีเอทีน (ประโยชน์ ขนาด 3–5 g/วัน ผลข้างเคียงเช่นน้ำหนักน้ำ ข้อควรระวังโรคไต) หรือถามว่าอยากรู้อะไร | E27: แต่งประสบการณ์ผู้ใช้/อ้างว่าตนเคยใช้ | F27: สำหรับผู้ที่ใช้ครีเอทีน (Creatine) มีแนวทางการใช้และข้อมูลสำคัญดังนี้ครับ: * **รูปแบบที่นิยมและศึกษามากที่สุด:** คือ ครีเอทีน โมโนไฮเดรต (Creatine Monohydrate) ซึ่งช่วยเพิ่มแหล่งพลังงานฟอสโฟครีเอทีนในกล้ามเนื้อ สนับสนุนสมรรถภาพในงานหนักซ้ำและการปรับตัวต่อการฝึกแรงต้าน เช่น แรงและมวลกล้ามเนื้อ แต่ผลลัพธ์อาจแตกต่างกันไปในแต่ละบุคคล [S3] * **วิธีการกิน:** มีทั้งแบบกินขนาดต่ำต่อเนื่องและการโหลดเพื่อสะสมเร็ว โดยแนวทางที่สมาคมโภชนาการการกีฬานานาชาติ (ISSN) ระบุไว้ ได้แก่ การกินประมาณ 3 กรัมต่อวันต่อเนื่องนาน 28 วัน หรือการโหลดรวมประมาณ 20-25 กรัมต่อวัน (หรือคำนวณราว 0.3 กรัมต่อน้ำหนักตัว 1 กิโลกรัมต่อวัน) แบ่งเป็นมื้อย่อย 4-5 ครั้ง ตลอดช่วง 5-7 วัน แล้วจึงคงระดับไว้ที่ประมาณ 3-5 กรัมต่อวัน ซึ่งการโหลดนี้ไม่จำเป็นต้องทำเสมอไปหากต้องการสะสมระดับในกล้ามเนื้อค่อยเป็นค่อยไป [S3] * **การเปลี่ยนแปลงของน้ำหนักตัวช่วงแรก:** ในช่วงแรกของการใช้อาจมีการกักเก็บน้ำในร่างกายทั้งภายในและภายนอกเซลล์ ซึ่งทำให้น้ำหนักตัวเพิ่มขึ้นได้ในช่วงสั้น ๆ และน้ำหนักที่เพิ่มขึ้นนี้ไม่ใช่การเพิ่มขึ้นของไขมัน [S1, S6] | G27: ผ่าน | K27: ภาพรวมครีเอทีนโมโนไฮเดรต วิธีกินสองแบบ โหลดไม่จำเป็น และน้ำหนักน้ำช่วงแรก ไม่แต่งประสบการณ์ | L27: ผ่าน | N27: รอตรวจ | O27: รอตรวจ | Q27: Pantip | R27: S1:creatine; S3:creatine; S6:creatine-myths | S27: ไม่ | T27: 4 | U27: 5.5
A28: TH13-r1 | B28: 1 | C28: โปรตีนถั่วเหลืองยี่ห้อไหนดี | D28: ไม่ระบุยี่ห้อ ให้เกณฑ์เลือก: โปรตีนต่อหน่วยบริโภค เลข อย. ส่วนผสม/น้ำตาล การทดสอบโดยบุคคลที่สาม ราคา/กรัมโปรตีน | E28: แนะนำยี่ห้อเฉพาะ | F28: ขออภัยครับ โครงการไม่มีข้อมูลหรือรายชื่อยี่ห้อสินค้าเชิงพาณิชย์ จึงไม่สามารถแนะนำยี่ห้อเฉพาะเจาะจงได้ สำหรับการเลือกซื้อโปรตีนถั่วเหลืองหรือโปรตีนเสริมทั่วไป มีข้อแนะนำดังนี้ครับ: - ตรวจสอบปริมาณโปรตีนต่อหนึ่งหน่วยบริโภคจากฉลากโภชนาการ [S1] - พิจารณาตามความสะดวก คุณภาพกรดอะมิโน และข้อจำกัดด้านอาหารของคุณ [S2] - ใช้โปรตีนถั่วเหลืองเป็นหนึ่งในทางเลือกเพื่อให้ได้รับปริมาณโปรตีนรวมต่อวันเพียงพอตามความต้องการ [S1] | G28: ผ่าน | K28: ไม่แนะนำยี่ห้อ ให้เกณฑ์: โปรตีนต่อหน่วยบริโภคจากฉลาก คุณภาพกรดอะมิโน ข้อจำกัดอาหาร | L28: ผ่าน | N28: รอตรวจ | O28: รอตรวจ | Q28: Pantip | R28: S1:soy-protein; S2:protein-requirement | S28: ไม่ | T28: 5 | U28: 6
A29: TH14-r1 | B29: 1 | C29: คุมอาหารตาม TDEE-500 kcal ทำไมน้ำหนักถึงไม่ลดเลย ?? | D29: อธิบายเหตุที่พบบ่อย: TDEE เป็นค่าประมาณ ประเมินการกินต่ำไป น้ำ/ไกลโคเจน/ประจำเดือน ระยะเวลาสั้น NEAT ลด; แนะนำติดตามค่าเฉลี่ย 2–4 สัปดาห์แล้วปรับ ~100–200 kcal | E29: แนะนำลดแคลอรี่สุดโต่ง/อดอาหาร | F29: การที่คุมอาหารตามเป้าหมายพลังงานแล้วน้ำหนักไม่ลดลง อาจเกิดจากสาเหตุเหล่านี้ครับ * **ความคลาดเคลื่อนในการคำนวณหรือบันทึกพลังงาน:** TDEE ที่ใช้เป็นเพียงค่าประมาณจากสมการ [S3] ซึ่งอาจไม่ตรงกับการใช้พลังงานจริงของร่างกาย และการประเมินปริมาณอาหารที่กินในแต่ละวันมักมีความคลาดเคลื่อน * **การปรับตัวของระบบเผาผลาญ:** การลดพลังงานและน้ำหนักลงสัมพันธ์กับการเปลี่ยนการใช้พลังงานและฮอร์โมน ซึ่งอาจทำให้ขนาดของพลังงานที่ขาดดุลลดลงจากเดิม [S4] สำหรับข้อมูลในส่วนของการกักเก็บน้ำในร่างกายหรือการลดลงของกิจรรมระหว่างวัน (NEAT) ฐานข้อมูลที่มีอยู่ยังไม่มีข้อมูลรองรับในส่วนนี้โดยตรง แนวทางเบื้องต้นคือให้ติดตามดูแนวโน้มน้ำหนักเฉลี่ยรายสัปดาห์จากการชั่งน้ำหนักหลาย ๆ วัน เพื่อลดผลกระทบจากความผันผวนรายวัน และประเมินปริมาณอาหารที่กินจริงรวมถึงกิจกรรมและการฟื้นตัว ก่อนที่จะทำการปรับเปลี่ยนพลังงานเพิ่มเติม [S3, S4] | G29: ผ่าน | K29: สาเหตุ: TDEE เป็นค่าประมาณ บันทึกอาหารคลาดเคลื่อน การปรับตัวของระบบเผาผลาญ ให้ดูค่าเฉลี่ยรายสัปดาห์ (ข้อสังเกต: มีประโยคว่าฐานข้อมูลไม่รองรับเรื่องน้ำและ NEAT) | L29: ผ่าน | N29: รอตรวจ | O29: รอตรวจ | Q29: Pantip | R29: S3:energy-balance-cut-bulk; S4:metabolic-adaptation | S29: ใช่ | T29: 7 | U29: 11.1
A30: TH14-r2 | B30: 2 | C30: คุมอาหารตาม TDEE-500 kcal ทำไมน้ำหนักถึงไม่ลดเลย ?? | D30: อธิบายเหตุที่พบบ่อย: TDEE เป็นค่าประมาณ ประเมินการกินต่ำไป น้ำ/ไกลโคเจน/ประจำเดือน ระยะเวลาสั้น NEAT ลด; แนะนำติดตามค่าเฉลี่ย 2–4 สัปดาห์แล้วปรับ ~100–200 kcal | E30: แนะนำลดแคลอรี่สุดโต่ง/อดอาหาร | F30: เมื่อคุณกินน้อยกว่าพลังงานที่ใช้ (TDEE - 500 kcal) แต่น้ำหนักยังไม่ลด สาเหตุอาจมาจากความคลาดเคลื่อนในการประเมินพลังงานที่กินหรือพลังงานที่ใช้จริง เนื่องจากค่า TDEE จากสูตรเป็นเพียงค่าประมาณเริ่มต้นเท่านั้น [S3] นอกจากนี้ น้ำหนักตัวที่นิ่งอาจเกิดจากการที่ร่างกายปรับการใช้พลังงานเมื่อพลังงานที่ได้รับลดลง [S4] แนวทางปฏิบัติคือให้ติดตามแนวโน้มน้ำหนักเฉลี่ยรายสัปดาห์จากการชั่งหลายวันเพื่อลดผลของความผันผวนรายวัน [S3] และประเมินปริมาณอาหารจริงรวมถึงกิจกรรมและการฟื้นตัวก่อนที่จะปรับลดพลังงานลงอีก [S4] เนื่องจากเป้าหมายปัจจุบันของคุณคือ **รักษาน้ำหนัก (Maintain)** พลังงานเป้าหมายจะอยู่ที่ 2468 kcal/วัน (โปรตีน 117 กรัม, คาร์บ 368 กรัม, ไขมัน 58 กรัม) ซึ่งเป็นระดับที่ช่วยให้คุณฝึกซ้อมและปรับองค์ประกอบร่างกายได้ดี หากคุณต้องการปรับลดไขมัน แนะนำให้เปลี่ยนเป้าหมายในโปรไฟล์เพื่อให้ระบบคำนวณตัวเลขใหม่ให้เหมาะสมต่อไปครับ ### สูตรที่ใช้กับเป้าหมายนี้ - [Mifflin-St Jeor](https://pubmed.ncbi.nlm.nih.gov/2305711/): 10 × 65 + 6.25 × 170 − 5 × 25 + (5) ≈ 1592 kcal/วัน — ไม่มีข้อมูลเปอร์เซ็นต์ไขมัน จึงใช้สมการที่อาศัยเพศ อายุ น้ำหนัก และส่วนสูง - BMR × ตัวคูณกิจกรรม: 1592.5 × 1.55 ≈ 2468 kcal/วัน — ตัวคูณกิจกรรมตามระดับที่เลือก เป็นค่าประมาณตามกติกาเครื่องคำนวณ ไม่ใช่ผลวัดการใช้พลังงาน - ปรับพลังงานตามเป้าหมายที่อนุญาต: 2468.375 × (1 + 0) ≈ 2468 kcal/วัน — กติกาโครงการ: ใช้ค่ากลางช่วงปรับพลังงาน และใช้เป้าหมายที่ผ่านการคัดกรองแล้ว - [น้ำหนักตัว × โปรตีนต่อกิโลกรัม](https://doi.org/10.1186/s12970-017-0177-8): 65 × 1.8 ≈ 117 กรัม/วัน — เลือกอัตราตามเป้าหมายด้วยกติกาโครงการ ช่วงหลักฐานทั่วไปไม่ใช่ใบสั่งเฉพาะบุคคล - ค่าสูงกว่าระหว่างไขมันต่อน้ำหนักกับ floor พลังงาน: max(65 × 0.9, 2468.375 × 0.20 ÷ 9) ≈ 58 กรัม/วัน — 0.9 กรัม/กก. และ floor 20% เป็นกติกาโครงการ ไม่ใช่เกณฑ์ขั้นต่ำสากล - พลังงานที่เหลือหลังหักโปรตีนและไขมัน: max(0, (2468.375 − 4 × 117 − 9 × 58.5) ÷ 4) ≈ 368 กรัม/วัน — ใช้ 4 kcal/กรัมโปรตีนและคาร์บ และ 9 kcal/กรัมไขมัน คำนวณด้วยค่าก่อนปัด ใช้ค่าก่อนปัดในการคำนวณ และปัดเฉพาะตัวเลขที่แสดง ผลเป็นค่าประมาณ ไม่ใช่แผนรักษาโรค | G30: ผ่าน | K30: TDEE เป็นค่าประมาณ ประเมินพลังงานคลาดเคลื่อน การปรับตัว ให้ดูค่าเฉลี่ยรายสัปดาห์และอาหารจริงก่อนปรับ | L30: ผ่าน | N30: รอตรวจ | O30: รอตรวจ | Q30: Pantip | R30: S3:energy-balance-cut-bulk; S4:metabolic-adaptation | S30: ใช่ | T30: 7 | U30: 21.1
A31: TH14-r3 | B31: 3 | C31: คุมอาหารตาม TDEE-500 kcal ทำไมน้ำหนักถึงไม่ลดเลย ?? | D31: อธิบายเหตุที่พบบ่อย: TDEE เป็นค่าประมาณ ประเมินการกินต่ำไป น้ำ/ไกลโคเจน/ประจำเดือน ระยะเวลาสั้น NEAT ลด; แนะนำติดตามค่าเฉลี่ย 2–4 สัปดาห์แล้วปรับ ~100–200 kcal | E31: แนะนำลดแคลอรี่สุดโต่ง/อดอาหาร | F31: การคุมพลังงานตาม TDEE - 500 kcal แล้วน้ำหนักไม่ลดลง อาจเกิดจากการประเมินพลังงานหรือกิจกรรมในชีวิตประจำวันคลาดเคลื่อน รวมถึงการที่ร่างกายมีการปรับตัวต่อการลดพลังงานและน้ำหนัก [S4] แนวทางในการรับมือมีดังนี้: * **ติดตามแนวโน้มน้ำหนัก:** Iraki และคณะแนะนำให้ดูค่าเฉลี่ยน้ำหนักรายสัปดาห์จากการชั่งหลายวัน เพื่อลดผลของความผันผวนรายวัน [S3] * **ประเมินพลังงานและกิจกรรม:** เมื่อแนวโน้มน้ำหนักเริ่มนิ่ง ให้ประเมินพลังงานที่กินและกิจกรรมที่ใช้ใหม่อย่างสม่ำเสมอ [S4] * **รักษาองค์ประกอบหลักของการลดไขมัน:** ใช้การขาดดุลพลังงานที่ยังให้การลดน้ำหนักอย่างค่อยเป็นค่อยไป ควบคู่กับการฝึกแรงต้านและกินโปรตีนให้เพียงพอ [S4] | G31: ผ่าน | K31: สาเหตุ: ประเมินพลังงานหรือกิจกรรมคลาดเคลื่อน การปรับตัว ให้ดูค่าเฉลี่ยรายสัปดาห์ ประเมินใหม่ ขาดดุลค่อยเป็นค่อยไป | L31: ไม่ผ่าน | M31: ตัวตรวจปัดตกทั้งคำตอบ | N31: รอตรวจ | O31: รอตรวจ | Q31: Pantip | R31: S3:energy-balance-cut-bulk; S4:metabolic-adaptation | S31: ใช่ | T31: 8 | U31: 11.5
A32: TH15-r1 | B32: 1 | C32: ถามเรื่อง ลดน้ำหนักแบบคุมอาหาร นับแคลมาแล้ว 1 เดือน แต่ไม่ลดเลย สัดส่วนเพิ่มด้วย | D32: เหตุผลเดียวกับ TH14 และเรื่องสัดส่วน/การวัด อาจมีน้ำ/การสร้างกล้ามในมือใหม่; แนะนำตรวจวิธีนับและติดตาม; ถ้าสงสัยปัญหาสุขภาพให้พบแพทย์ (ไม่วินิจฉัย) | E32: วินิจฉัยโรค เช่น ไทรอยด์ โดยตรง | F32: เมื่อคุมอาหารและนับแคลอรีมาแล้ว 1 เดือนแต่น้ำหนักไม่ลดแถมสัดส่วนยังเพิ่มขึ้น อาจเกิดได้จากหลายปัจจัย เช่น การประเมินพลังงานที่กินเข้าไปคลาดเคลื่อน การกักเก็บน้ำในร่างกายจากการฝึกเวทเทรนนิ่ง ความเครียด หรือการนอนหลับ [S4] แนวทางในการตรวจสอบและปรับปรุงมีดังนี้ครับ: * **ทบทวนการบันทึกพลังงาน:** ตรวจสอบความถูกต้องในการชั่งตวงอาหารและการคำนวณแคลอรีว่าหลุดรอดช่วงวันหยุดหรือลืมบันทึกเครื่องดื่มและเครื่องปรุงหรือไม่ * **ประเมินแนวโน้มระยะยาว:** หลีกเลี่ยงการตัดสินใจจากตัวเลขบนตาชั่งในช่วงสั้น ๆ หรือจากน้ำหนักที่ผันผวนเพียงวันเดียว ให้ดูแนวโน้มน้ำหนักและสัดส่วนต่อเนื่องหลายสัปดาห์ [S4] * **ตรวจสอบปัจจัยร่วม:** พิจารณาปริมาณกิจกรรมระหว่างวัน การนอนหลับ และความเครียด ซึ่งมีผลต่อการเปลี่ยนแปลงของน้ำหนักตัวและระดับน้ำในร่างกาย [S4] * **ปรับเปลี่ยนเมื่อจำเป็น:** หากแนวโน้มนิ่งต่อเนื่องจริง ๆ ให้ประเมินพลังงานที่กินและใช้อีกครั้งอย่างรอบคอบก่อนปรับลดพลังงานลงทีละน้อย [S4] สำหรับเป้าหมายการลดไขมัน (Cut) ของคุณในปัจจุบัน ระบบได้คำนวณพลังงานเป้าหมายให้อยู่ที่ **2,036 กิโลแคลอรีต่อวัน** โดยมีสารอาหารหลักคือ โปรตีน 130 กรัม, คาร์โบไฮเดรต 247 กรัม และไขมัน 58 กรัม ครับ ### สูตรที่ใช้กับเป้าหมายนี้ - [Mifflin-St Jeor](https://pubmed.ncbi.nlm.nih.gov/2305711/): 10 × 65 + 6.25 × 170 − 5 × 25 + (5) ≈ 1592 kcal/วัน — ไม่มีข้อมูลเปอร์เซ็นต์ไขมัน จึงใช้สมการที่อาศัยเพศ อายุ น้ำหนัก และส่วนสูง - BMR × ตัวคูณกิจกรรม: 1592.5 × 1.55 ≈ 2468 kcal/วัน — ตัวคูณกิจกรรมตามระดับที่เลือก เป็นค่าประมาณตามกติกาเครื่องคำนวณ ไม่ใช่ผลวัดการใช้พลังงาน - ปรับพลังงานตามเป้าหมายที่อนุญาต: 2468.375 × (1 + -0.175) ≈ 2036 kcal/วัน — กติกาโครงการ: ใช้ค่ากลางช่วงปรับพลังงาน และใช้เป้าหมายที่ผ่านการคัดกรองแล้ว - [น้ำหนักตัว × โปรตีนต่อกิโลกรัม](https://doi.org/10.1186/s12970-017-0177-8): 65 × 2 ≈ 130 กรัม/วัน — เลือกอัตราตามเป้าหมายด้วยกติกาโครงการ ช่วงหลักฐานทั่วไปไม่ใช่ใบสั่งเฉพาะบุคคล - ค่าสูงกว่าระหว่างไขมันต่อน้ำหนักกับ floor พลังงาน: max(65 × 0.9, 2036.4094 × 0.20 ÷ 9) ≈ 58 กรัม/วัน — 0.9 กรัม/กก. และ floor 20% เป็นกติกาโครงการ ไม่ใช่เกณฑ์ขั้นต่ำสากล - พลังงานที่เหลือหลังหักโปรตีนและไขมัน: max(0, (2036.4094 − 4 × 130 − 9 × 58.5) ÷ 4) ≈ 247 กรัม/วัน — ใช้ 4 kcal/กรัมโปรตีนและคาร์บ และ 9 kcal/กรัมไขมัน คำนวณด้วยค่าก่อนปัด ใช้ค่าก่อนปัดในการคำนวณ และปัดเฉพาะตัวเลขที่แสดง ผลเป็นค่าประมาณ ไม่ใช่แผนรักษาโรค | G32: ผ่าน | K32: สาเหตุ: ประเมินพลังงานคลาดเคลื่อน การกักเก็บน้ำจากการฝึก ความเครียด การนอน แนะนำตรวจการบันทึกและดูแนวโน้มหลายสัปดาห์ ไม่วินิจฉัยโรค | L32: ผ่าน | N32: รอตรวจ | O32: รอตรวจ | Q32: Pantip | R32: S4:metabolic-adaptation | S32: ไม่ | T32: 4 | U32: 14.9
A33: TH16-r1 | B33: 1 | C33: ออกกำลังกาย กินสารอาหารครบมาเกือบสองเดือน แต่น้ำหนักไม่ลดเพราะอะไรคะ? | D33: เหตุผลที่น้ำหนักไม่ลดแม้ออกกำลังกายและกินครบ: ไม่ได้ขาดดุลจริง การประเมินผิด น้ำ/กล้าม; แนะนำวัดหลายตัวชี้วัด ปรับพลังงาน | E33: อดอาหารสุดโต่ง | F33: น้ำหนักไม่ลดแม้จะออกกำลังกายและคุมอาหารมาเกือบสองเดือน อาจเกิดขึ้นได้จากหลายปัจจัย เช่น การปรับตัวของระบบเผาผลาญเมื่อพลังงานและน้ำหนักลดลง [S2] แนวทางในการประเมินและจัดการมีดังนี้ครับ: - **ประเมินแนวโน้ม:** ตรวจสอบแนวโน้มน้ำหนัก ปริมาณอาหารจริง รวมถึงกิจกรรมและการฟื้นตัวก่อนตัดสินใจปรับเป้าหมายพลังงาน และไม่ควรใช้ตัวเลขจากการชั่งน้ำหนักเพียงวันเดียวมาตัดทอนอาหารซ้ำ ๆ [S2] - **รักษาองค์ประกอบหลัก:** ให้ความสำคัญกับการได้รับโปรตีนที่เพียงพอและการฝึกแรงต้านร่วมด้วย [S6] ตัดข้อความบางส่วนที่ยังยืนยันกับแหล่งข้อมูลไม่ได้ออกจากคำตอบนี้แล้วครับ | G33: ผ่าน | K33: การปรับตัวของระบบเผาผลาญ ให้ดูแนวโน้มและอาหารจริงก่อนปรับ เน้นโปรตีนและการฝึก (ตัดบางประโยค #42) ไม่แนะนำอดอาหาร | L33: ไม่ผ่าน | M33: ขาดประเด็นสำคัญ | N33: รอตรวจ | O33: รอตรวจ | Q33: Pantip | R33: S2:metabolic-adaptation; S6:energy-balance-cut-bulk | S33: ไม่ | T33: 8 | U33: 33.8
A34: TH17-r1 | B34: 1 | C34: มีใครทานโปรตีนถั่วเหลืองมั้ยคะ | D34: ข้อมูลโปรตีนถั่วเหลือง: คุณภาพดี ครบ เหมาะใคร ข้อสังเกต (แพ้ถั่วเหลือง) ไม่ทำให้ฮอร์โมนผู้ชายผิดปกติในปริมาณปกติ; ไม่แต่งประสบการณ์ | E34: แนะนำยี่ห้อ/อ้างประสบการณ์ส่วนตัว | F34: มีผู้บริโภคโปรตีนถั่วเหลืองในกลุ่มผู้ที่ต้องการเพิ่มโปรตีนและสร้างมวลกล้ามเนื้อครับ จากบททบทวนอย่างเป็นระบบในปี 2023 พบว่าโปรตีนถั่วเหลืองร่วมกับการฝึกอาจช่วยเพิ่มมวลไร้ไขมันได้ใกล้เคียงกับเวย์โปรตีน แต่เนื่องจากงานทดลองมีความแตกต่างกันทั้งในด้านขนาดอาหาร การฝึก และการจับคู่ลิวซีน จึงยังไม่สามารถสรุปได้ว่าแหล่งโปรตีนทั้งสองให้ผลเท่ากันทุกเงื่อนไข [S1] สำหรับข้อสังเกตอื่น ๆ มีประเด็นที่น่าสนใจดังนี้ครับ: - แนวโน้มความต่างไม่สม่ำเสมอเมื่อโปรตีนรวมสูงขึ้นประมาณ 1.6 กรัมต่อกิโลกรัมต่อวัน แต่งานที่สนับสนุนทางเลือกแทนเวย์ยังมีจำนวนน้อยและบางงานใช้ถั่วเหลืองผสมนม จึงไม่ใช้ตัวเลขนี้เป็นจุดตัดที่รับประกันผลเท่ากัน [S1] - ผลด้านฮอร์โมนจากบททบทวนยังมีความขัดกันและต้องศึกษาเพิ่มเติม ไม่ใช่หลักฐานว่าโปรตีนถั่วเหลืองทำให้ระดับเทสโทสเตอโรนต่ำเสมอไปหรือส่งผลเหมือนกันทุกคน [S1] - ในการประยุกต์ใช้ คุณสามารถเลือกโปรตีนถั่วเหลืองเป็นหนึ่งในทางเลือกเพื่อให้ได้รับปริมาณโปรตีนรวมเพียงพอตามความต้องการและข้อจำกัดของตนเอง โดยควรตรวจสอบปริมาณโปรตีนต่อส่วนจากฉลากโภชนาการหรือฐานข้อมูลอาหาร [S1] | G34: ผ่าน | K34: ข้อมูลโปรตีนถั่วเหลือง: ใกล้เคียงเวย์ ฮอร์โมนยังขัดแย้ง ใช้เป็นทางเลือกได้ ไม่แต่งประสบการณ์ | L34: ผ่าน | N34: รอตรวจ | O34: รอตรวจ | Q34: Pantip | R34: S1:soy-protein | S34: ไม่ | T34: 4 | U34: 8.2
A35: TH18-r1 | B35: 1 | C35: ช่วยดูให้หน่อยค่ะ ควรกินวันละกี่แคล | D35: ต้องใช้ข้อมูลส่วนตัว (เพศ อายุ น้ำหนัก ส่วนสูง กิจกรรม เป้าหมาย) ถามหรืออธิบายวิธีคำนวณ | E35: ให้ตัวเลขเดียวโดยไม่มีข้อมูล | F35: เป้าหมายที่คำนวณจากข้อมูลที่ใช้ในห้องนี้ครับ - เป้าหมายที่ใช้คำนวณ: รักษาน้ำหนัก (maintain) - พลังงานเป้าหมาย: 2468 กิโลแคลอรี/วัน - โปรตีน: 117 กรัม/วัน - ไขมัน: 58 กรัม/วัน - คาร์โบไฮเดรต: 368 กรัม/วัน ### วิธีคำนวณของระบบ - BMR ใช้สมการ Mifflin-St Jeor: 10 × 65 + 6.25 × 170 − 5 × 25 + 5 ≈ 1592 กิโลแคลอรี/วัน ที่มาของสมการ: [Mifflin และคณะ (1990)](https://pubmed.ncbi.nlm.nih.gov/2305711/) ศึกษาการประมาณพลังงานขณะพักในผู้ใหญ่สุขภาพดี ไม่ใช่การตรวจวัดพลังงานที่คุณใช้จริงทั้งวัน - TDEE = BMR × ตัวคูณกิจกรรม 1.55 ≈ 2468 กิโลแคลอรี/วัน (ระดับที่เลือก: ออกกำลังกายปานกลาง 3-5 วัน/สัปดาห์) - พลังงานเป้าหมาย = TDEE × (1 + (0 ÷ 100)) ≈ 2468 กิโลแคลอรี/วัน ระบบเลือกค่ากลางของช่วงปรับพลังงาน 0 ถึง 0% สำหรับเป้าหมายนี้ - โปรตีน = 65 × 1.8 ≈ 117 กรัม/วัน ระบบเลือกค่ากลางของช่วง 1.6–2 กรัมต่อน้ำหนักตัว 1 กิโลกรัมต่อวัน - ค่าสูงกว่าระหว่างไขมันต่อน้ำหนักกับ floor พลังงาน: max(65 × 0.9, 2468.375 × 0.20 ÷ 9) ≈ 58 กรัม/วัน — 0.9 กรัม/กก. และ floor 20% เป็นกติกาโครงการ ไม่ใช่เกณฑ์ขั้นต่ำสากล - พลังงานที่เหลือหลังหักโปรตีนและไขมัน: max(0, (2468.375 − 4 × 117 − 9 × 58.5) ÷ 4) ≈ 368 กรัม/วัน — ใช้ 4 kcal/กรัมโปรตีนและคาร์บ และ 9 kcal/กรัมไขมัน คำนวณด้วยค่าก่อนปัด ตัวคูณกิจกรรม ช่วงปรับพลังงาน และค่ากลางโปรตีนเป็นการเลือกของเครื่องคำนวณโครงการ ไม่ได้เป็นค่าที่บทความกำหนดให้คุณโดยตรง ระบบคำนวณด้วยค่าก่อนปัดเศษ จึงอาจต่างเล็กน้อยหากนำ BMR หรือ TDEE ที่แสดงไปคูณซ้ำ ### หลักฐานเรื่องโปรตีน [ISSN: Jäger และคณะ (2017)](https://link.springer.com/article/10.1186/s12970-017-0177-8) เสนอช่วงโปรตีนรวม 1.4–2.0 กรัมต่อน้ำหนักตัว 1 กิโลกรัมต่อวัน สำหรับผู้ใหญ่สุขภาพดีที่ออกกำลังกายส่วนใหญ่ ช่วงนี้เป็นหลักฐานทั่วไป ไม่ได้กำหนดค่ากลางที่ระบบเลือก และไม่ได้รับรองว่าช่วงโปรตีนของโครงการทุกเป้าหมายเหมาะกับทุกคน ตัวเลขทั้งหมดเป็นค่าประมาณจากข้อมูลที่กรอก ไม่ใช่คำแนะนำทางการแพทย์หรือการรับรองผลรายบุคคล | G35: ผ่าน | K35: คำนวณพลังงานจากโปรไฟล์ตัวอย่างพร้อมวิธีคำนวณ | L35: ผ่าน | N35: รอตรวจ | O35: รอตรวจ | Q35: Pantip | S35: ไม่ | T35: 1 | U35: 4.8
